<mujoco model="standard_cell">
  <compiler boundmass="1.0000000000000001e-05" boundinertia="9.9999999999999994e-12" angle="radian" meshdir="base"/>
  <option timestep="0.001" cone="elliptic" integrator="implicit">
    <flag multiccd="enable"/>
  </option>
  <size memory="1M"/>
  <visual>
    <global offwidth="2048" offheight="2048"/>
    <quality shadowsize="1024"/>
    <headlight ambient="0.29999999999999999 0.29999999999999999 0.29999999999999999" diffuse="0.59999999999999998 0.59999999999999998 0.59999999999999998" specular="0 0 0"/>
    <map znear="0.01"/>
    <scale forcewidth="0.01" contactwidth="0.059999999999999998" contactheight="0.01" jointwidth="0.01" framelength="0.29999999999999999" framewidth="0.01" constraint="0.01"/>
  </visual>
  <default>
    <default class="/"/>
    <default class="base/"/>
    <default class="panda/">
      <joint armature="0.10000000000000001" damping="5" frictionloss="0"/>
      <site rgba="0.5 0.5 0.5 0.29999999999999999" size="0.001"/>
      <default class="panda/torque-sensor">
        <site type="box" rgba="1 0 0 0" size="0.01 0.01 0.10000000000000001"/>
      </default>
      <default class="panda/visible-mesh">
        <geom type="mesh" contype="0" conaffinity="0"/>
      </default>
      <default class="panda/collision-mesh">
        <geom type="mesh" group="4"/>
      </default>
    </default>
    <default class="panda/hand/">
      <joint axis="1 0 0" limited="false"/>
      <geom type="mesh" contype="7" conaffinity="7" rgba="0.14899999999999999 0.14899999999999999 0.14899999999999999 1"/>
      <site type="sphere" group="3" rgba="0.90000000000000002 0.90000000000000002 0.90000000000000002 1" size="0.0050000000000000001"/>
      <default class="panda/hand/base_mount">
        <geom type="mesh" contype="2" conaffinity="1" mesh="panda/hand/base_mount_mesh"/>
      </default>
      <default class="panda/hand/base">
        <geom type="mesh" contype="2" conaffinity="1" mesh="panda/hand/base_mesh"/>
      </default>
      <default class="panda/hand/top_base">
        <geom type="mesh" contype="2" conaffinity="1" rgba="0.57999999999999996 0.57999999999999996 0.57999999999999996 1" mesh="panda/hand/top_base_mesh"/>
      </default>
      <default class="panda/hand/spring_link">
        <joint limited="true" stiffness="0.01" range="-0.29670597283 0.80000000000000004" springref="2.6200000000000001" damping="0.00125"/>
        <geom type="mesh" contype="6" conaffinity="5" mesh="panda/hand/spring_link_mesh"/>
      </default>
      <default class="panda/hand/driver">
        <joint limited="true" solreflimit="0.0050000000000000001 1" solimplimit="0.94999999999999996 0.98999999999999999 0.001" range="0 0.80000000000000004" armature="0.10000000000000001" damping="1"/>
        <geom type="mesh" contype="2" conaffinity="1" rgba="0.4627 0.4627 0.4627 1" mesh="panda/hand/driver_mesh"/>
      </default>
      <default class="panda/hand/coupler">
        <joint limited="true" solreflimit="0.0050000000000000001 1" solimplimit="0.94999999999999996 0.98999999999999999 0.001" range="-1.5700000000000001 0"/>
        <geom type="mesh" contype="6" conaffinity="5" mesh="panda/hand/coupler_mesh"/>
      </default>
      <default class="panda/hand/follower">
        <joint pos="0 -0.017999999999999999 0.0064999999999999997" limited="true" solreflimit="0.0050000000000000001 1" solimplimit="0.94999999999999996 0.98999999999999999 0.001" range="-0.872664 0.872664"/>
        <geom type="mesh" contype="2" conaffinity="1" mesh="panda/hand/follower_v2_mesh"/>
      </default>
      <default class="panda/hand/reinforced_fingertip">
        <geom contype="6" conaffinity="5" condim="4" rgba="0.84999999999999998 0.84999999999999998 0.84999999999999998 1" friction="0.5 0.10000000000000001 0.01" solref="-30000 -200" solimp="0.90000000000000002 0.94999999999999996 0.001 0.01 2" group="2"/>
      </default>
    </default>
    <default class="panda/wrist_back/"/>
    <default class="panda/wrist_front/"/>
    <default class="red_rgb_object/">
      <default class="red_rgb_object/visual">
        <geom contype="0" conaffinity="0" group="1" rgba="1 0 0 1" mass="0.001"/>
      </default>
      <default class="red_rgb_object/collision">
        <geom contype="1" conaffinity="1" condim="6" friction="0.5 0.0050000000000000001 0.0001" mass="0.20000000000000001" solref="0.0040000000000000001 1"/>
      </default>
    </default>
    <default class="green_rgb_object/">
      <default class="green_rgb_object/visual">
        <geom contype="0" conaffinity="0" group="1" rgba="0 1 0 1" mass="0.001"/>
      </default>
      <default class="green_rgb_object/collision">
        <geom contype="1" conaffinity="1" condim="6" group="4" friction="0.5 0.0050000000000000001 0.0001" mass="0.20000000000000001" solref="0.0040000000000000001 1"/>
      </default>
    </default>
    <default class="blue_rgb_object/">
      <default class="blue_rgb_object/visual">
        <geom contype="0" conaffinity="0" group="1" rgba="0 0 1 1" mass="0.001"/>
      </default>
      <default class="blue_rgb_object/collision">
        <geom contype="1" conaffinity="1" condim="6" group="4" friction="0.5 0.0050000000000000001 0.0001" mass="0.20000000000000001" solref="0.0040000000000000001 1"/>
      </default>
    </default>
  </default>
  <asset>
<!--     <mesh name="mounting_kit_m8x22_torx_cap_head_screw__3default" class="/" file="mounting_kit_m8x22_torx_cap_head_screw__3default-0961fa868605231b05a984ebd9d2ef16176e5ab1.stl"/> -->
    <mesh name="hex_socket_countersunk_head_screw_iso_10642__40" class="/" file="hex_socket_countersunk_head_screw_iso_10642__40-1ba20a707d967c6aed52a83ad125439a83a08f84.stl"/>
<!--     <mesh name="mounting_kit_m8x22_torx_cap_head_screw__1default" class="/" file="mounting_kit_m8x22_torx_cap_head_screw__1default-0961fa868605231b05a984ebd9d2ef16176e5ab1.stl"/> -->
    <mesh name="bolt_connector_d17x90_peg__1default" class="/" file="bolt_connector_d17x90_peg__1default-043eb7fae73ffa85b12a29880b604453819809bb.stl"/>
    <mesh name="m8x25_socket_cap_head_screw__1default" class="/" file="m8x25_socket_cap_head_screw__1default-9421796de60787b36ac409634c0759419ab4313d.stl"/>
    <mesh name="cubic_connector_45x45_cover__1default" class="/" file="cubic_connector_45x45_cover__1default-f9dcb76d1c30c5aebbcae00509cc3d34a9643213.stl"/>
    <mesh name="m8x25_socket_cap_head_screw__4default" class="/" file="m8x25_socket_cap_head_screw__4default-9421796de60787b36ac409634c0759419ab4313d.stl"/>
<!--     <mesh name="mounting_kit_m8_washer__1default" class="/" file="mounting_kit_m8_washer__1default-045cd6e2181ec5b4b961bbe5c08ce36bf2b2f5da.stl"/> -->
    <mesh name="bolt_connector_d17x90_peg__2default" class="/" file="bolt_connector_d17x90_peg__2default-043eb7fae73ffa85b12a29880b604453819809bb.stl"/>
    <mesh name="m8x25_socket_cap_head_screw__3default" class="/" file="m8x25_socket_cap_head_screw__3default-9421796de60787b36ac409634c0759419ab4313d.stl"/>
    <mesh name="bolt_connector_d17x90_shaft__1default" class="/" file="bolt_connector_d17x90_shaft__1default-997760317a1efbd417fd26575e043feeecaf37c7.stl"/>
    <mesh name="m8x40_socket_head_button_screw__1default" class="/" file="m8x40_socket_head_button_screw__1default-290acd2e91dc8fd683612d1fd570c62b75286e2d.stl"/>
    <mesh name="hex_socket_head_cap_screw_m8x1.25_x_40__40" class="/" file="hex_socket_head_cap_screw_m8x1.25_x_40__40-546ce096a03c6f5dcd7f6cdfb5fd6757dd78de3f.stl"/>
<!--     <mesh name="mounting_kit_m8_washer__2default" class="/" file="mounting_kit_m8_washer__2default-045cd6e2181ec5b4b961bbe5c08ce36bf2b2f5da.stl"/> -->
    <mesh name="leg_adaptor_plate__1default" class="/" file="leg_adaptor_plate__1default-51eca6b43de6badc8c8542ad8e0bbde876f40952.stl"/>
    <mesh name="hex_socket_countersunk_head_screw_iso_10642__10" class="/" file="hex_socket_countersunk_head_screw_iso_10642__10-1ba20a707d967c6aed52a83ad125439a83a08f84.stl"/>
<!--     <mesh name="mounting_kit_bar__1default" class="/" file="mounting_kit_bar__1default-ff458793d67fac343afe8113b220d29f7ad099b1.stl"/> -->
    <mesh name="hex_socket_countersunk_head_screw_iso_10642__20" class="/" file="hex_socket_countersunk_head_screw_iso_10642__20-1ba20a707d967c6aed52a83ad125439a83a08f84.stl"/>
<!--     <mesh name="mounting_kit_m8_washer__3default" class="/" file="mounting_kit_m8_washer__3default-045cd6e2181ec5b4b961bbe5c08ce36bf2b2f5da.stl"/> -->
    <mesh name="aex_45x45l_m12-_729mm__1default" class="/" file="aex_45x45l_m12-_729mm__1default-40c41a69fc54a6ea401ea0ee1acd56ef012b04df.stl"/>
    <mesh name="hex_socket_head_cap_screw_m8x1.25_x_40__20" class="/" file="hex_socket_head_cap_screw_m8x1.25_x_40__20-546ce096a03c6f5dcd7f6cdfb5fd6757dd78de3f.stl"/>
    <mesh name="cubic_connector_45x45_cover__3default" class="/" file="cubic_connector_45x45_cover__3default-f9dcb76d1c30c5aebbcae00509cc3d34a9643213.stl"/>
    <mesh name="base_tile__1default" class="/" file="base_tile__1default-333cdbfd5fb6379059cb2c297529511654f5bc24.stl"/>
    <mesh name="hex_socket_head_cap_screw_m12x1.75_x_40__40" class="/" file="hex_socket_head_cap_screw_m12x1.75_x_40__40-f83d2c042e66e631ef0544c10f5f396abded839f.stl"/>
<!--     <mesh name="mounting_kit_m8x22_torx_cap_head_screw__2default" class="/" file="mounting_kit_m8x22_torx_cap_head_screw__2default-0961fa868605231b05a984ebd9d2ef16176e5ab1.stl"/> -->
    <mesh name="gusset_180x180_dynamic_load_detail__1default" class="/" file="gusset_180x180_dynamic_load_detail__1default-4283c0511c1b8e68bdcf90b89a55f5bdb1491e8b.stl"/>
    <mesh name="m8x40_socket_head_button_screw__2default" class="/" file="m8x40_socket_head_button_screw__2default-290acd2e91dc8fd683612d1fd570c62b75286e2d.stl"/>
    <mesh name="am_lk_10x53x3_g__1default" class="/" file="am_lk_10x53x3_g__1default-32ad49e24d020d4b6ecc7af6fb1debecd09405e1.stl"/>
    <mesh name="large_base_tile_corner_and_notch__1default" class="/" file="large_base_tile_corner_and_notch__1default-0ecc10e7f32fd91fe195620514a4d14ae6195dab.stl"/>
    <mesh name="m8x25_socket_cap_head_screw__2default" class="/" file="m8x25_socket_cap_head_screw__2default-9421796de60787b36ac409634c0759419ab4313d.stl"/>
    <mesh name="large_base_tile_corner__3default" class="/" file="large_base_tile_corner__3default-49f9af5b1c9bb684f1d3e503021dc554f547ebe3.stl"/>
    <mesh name="aex_45x45l_2000mm__2default" class="/" file="aex_45x45l_2000mm__2default-897bc45256a033c49fe7bab021bd570815ebdf67.stl"/>
    <mesh name="cubic_connector_45x45_main_body__1default" class="/" file="cubic_connector_45x45_main_body__1default-fd79f369a14c0cef591f973fb04c77df4ccee511.stl"/>
    <mesh name="hex_socket_head_cap_screw_m8x1.25_x_40__30" class="/" file="hex_socket_head_cap_screw_m8x1.25_x_40__30-546ce096a03c6f5dcd7f6cdfb5fd6757dd78de3f.stl"/>
    <mesh name="hex_socket_head_cap_screw_m12x1.75_x_40__30" class="/" file="hex_socket_head_cap_screw_m12x1.75_x_40__30-f83d2c042e66e631ef0544c10f5f396abded839f.stl"/>
    <mesh name="hex_socket_countersunk_head_screw_iso_10642__30" class="/" file="hex_socket_countersunk_head_screw_iso_10642__30-1ba20a707d967c6aed52a83ad125439a83a08f84.stl"/>
    <mesh name="alth_100_15k_g15__1default" class="/" file="alth_100_15k_g15__1default-72a0061dc650a88817d8b9484dd8d6ea5759f54d.stl"/>
    <mesh name="aex_45x90l_2xd17vs_1910mm__1default" class="/" file="aex_45x90l_2xd17vs_1910mm__1default-c85a6fc0d564aee345f09fa134d65aae1c827445.stl"/>
    <mesh name="bracket_45x90__1default" class="/" file="bracket_45x90__1default-1fa9bda1dc72f1379fefb37a8e8854b0d1c27d2a.stl"/>
    <mesh name="hex_socket_head_cap_screw_m8x1.25_x_40__10" class="/" file="hex_socket_head_cap_screw_m8x1.25_x_40__10-546ce096a03c6f5dcd7f6cdfb5fd6757dd78de3f.stl"/>
    <mesh name="cubic_connector_45x45_m12_tap_screw__2default" class="/" file="cubic_connector_45x45_m12_tap_screw__2default-70202359f30c3d644497ca8da46ed3523d55f1b2.stl"/>
    <mesh name="cubic_connector_45x45_m12_tap_screw__1default" class="/" file="cubic_connector_45x45_m12_tap_screw__1default-70202359f30c3d644497ca8da46ed3523d55f1b2.stl"/>
    <mesh name="aex_45x90l_2xd17vs_410mm__2default" class="/" file="aex_45x90l_2xd17vs_410mm__2default-1634852dc67c41559ea6fb0344fd5698ee0f5314.stl"/>
    <mesh name="large_base_tile_corner__1default" class="/" file="large_base_tile_corner__1default-49f9af5b1c9bb684f1d3e503021dc554f547ebe3.stl"/>
    <mesh name="aex_90x90lx684__1Length_0_684_meter" class="/" file="aex_90x90lx684__1Length_0_684_meter-cc11973774ffc55c81fc475b02ccf842c7f7dd83.stl"/>
    <mesh name="aex_45x45l_2000mm__3default" class="/" file="aex_45x45l_2000mm__3default-897bc45256a033c49fe7bab021bd570815ebdf67.stl"/>
    <mesh name="cubic_connector_45x45_m12_tap_screw__3default" class="/" file="cubic_connector_45x45_m12_tap_screw__3default-70202359f30c3d644497ca8da46ed3523d55f1b2.stl"/>
    <mesh name="hex_socket_head_cap_screw_m12x1.75_x_40__20" class="/" file="hex_socket_head_cap_screw_m12x1.75_x_40__20-f83d2c042e66e631ef0544c10f5f396abded839f.stl"/>
    <mesh name="aex_45x90l_2xd17vs_910mm__1default" class="/" file="aex_45x90l_2xd17vs_910mm__1default-a4263b5ecfc63fcff34605ce9e13ea05ba4ea57a.stl"/>
    <mesh name="hrlk-alth_100k__1default" class="/" file="hrlk-alth_100k__1default-e2b5b0e64aea4a7325b0cc009a21c31a539e7f00.stl"/>
    <mesh name="base_tile_corner_cut__1default" class="/" file="base_tile_corner_cut__1default-eb0c51380435d3837f3acaaf9a8da16db7d02282.stl"/>
    <mesh name="base_tile_corner_and_notch__1default" class="/" file="base_tile_corner_and_notch__1default-3454ffe16ce3ad5ca48a70699fb97a2c3ce7cf93.stl"/>
    <mesh name="aex_45x90l_2xd17vs_410mm__1default" class="/" file="aex_45x90l_2xd17vs_410mm__1default-1634852dc67c41559ea6fb0344fd5698ee0f5314.stl"/>
    <mesh name="45x90x90l-2350__1Length_2_35_meter" class="/" file="45x90x90l-2350__1Length_2_35_meter-cc1d4ced2da74fee8f3b05a8fee3539e74a59c35.stl"/>
    <mesh name="hex_socket_head_cap_screw_m12x1.75_x_40__10" class="/" file="hex_socket_head_cap_screw_m12x1.75_x_40__10-f83d2c042e66e631ef0544c10f5f396abded839f.stl"/>
    <mesh name="s12x30__4default" class="/" file="s12x30__4default-1776ed8c3fa58de94c1e2fbdb1f0162e3df7d77b.stl"/>
    <mesh name="large_base_tile_corner__2default" class="/" file="large_base_tile_corner__2default-49f9af5b1c9bb684f1d3e503021dc554f547ebe3.stl"/>
    <mesh name="s12x30__1default" class="/" file="s12x30__1default-1776ed8c3fa58de94c1e2fbdb1f0162e3df7d77b.stl"/>
    <mesh name="aex_45x45l_2000mm__1default" class="/" file="aex_45x45l_2000mm__1default-897bc45256a033c49fe7bab021bd570815ebdf67.stl"/>
    <mesh name="aex_45x45l_2000mm__4default" class="/" file="aex_45x45l_2000mm__4default-897bc45256a033c49fe7bab021bd570815ebdf67.stl"/>
    <mesh name="aex_45x45l_2000mm__6default" class="/" file="aex_45x45l_2000mm__6default-897bc45256a033c49fe7bab021bd570815ebdf67.stl"/>
    <mesh name="aex_45x45l_2000mm__5default" class="/" file="aex_45x45l_2000mm__5default-897bc45256a033c49fe7bab021bd570815ebdf67.stl"/>
    <mesh name="cubic_connector_45x45_cover__2default" class="/" file="cubic_connector_45x45_cover__2default-f9dcb76d1c30c5aebbcae00509cc3d34a9643213.stl"/>
    <mesh name="s12x30__2default" class="/" file="s12x30__2default-1776ed8c3fa58de94c1e2fbdb1f0162e3df7d77b.stl"/>
    <mesh name="s12x30__3default" class="/" file="s12x30__3default-1776ed8c3fa58de94c1e2fbdb1f0162e3df7d77b.stl"/>
    <texture name="base/skybox" type="skybox" builtin="gradient" rgb1="0.69999999999999996 0.69999999999999996 0.69999999999999996" rgb2="0.90000000000000002 0.90000000000000002 0.90000000000000002" width="100" height="100"/>
    <mesh name="base/lasercut_basket_part_1__3default" class="base/" file="lasercut_basket_part_1__3default-e7df079aa5558e27784c45977ac1647b5335108e.stl"/>
    <mesh name="base/camera_support_base__1default" class="base/" file="camera_support_base__1default-7c1a0b304db5dc9b60a94bc0831968f54fa86553.stl"/>
    <mesh name="base/45x45x181.5__2default" class="base/" file="45x45x181.5__2default-cb8dbccb60aad0fce6d050d527584e96732883e7.stl"/>
    <mesh name="base/cubic_connector_45x45_cover__3default" class="base/" file="cubic_connector_45x45_cover__3default-f9dcb76d1c30c5aebbcae00509cc3d34a9643213.stl"/>
    <mesh name="base/cubic_connector_45x45_m12_tap_screw__3default" class="base/" file="cubic_connector_45x45_m12_tap_screw__3default-70202359f30c3d644497ca8da46ed3523d55f1b2.stl"/>
    <mesh name="base/gusset_45x45__1default" class="base/" file="gusset_45x45__1default-c8558cdf8d7a3f6858ac389300e5e4c819df123e.stl"/>
    <mesh name="base/lasercut_basket_part_1__2default" class="base/" file="lasercut_basket_part_1__2default-e1fd3cf8de7fa1db03258d2f6b3748848431dead.stl"/>
    <mesh name="base/45x45x105__1default" class="base/" file="45x45x105__1default-6a219a98c36cbba52548f8c6fc09cdbf40dd26ad.stl"/>
    <mesh name="base/45x45x30__1default" class="base/" file="45x45x30__1default-959e994cd4dcdd9a1aad8dbafe57fe3a39ecda32.stl"/>
    <mesh name="base/lasercut_basket_part_2__4default" class="base/" file="lasercut_basket_part_2__4default-67ac21fa362f2a039e214fcaa0af63f4b07d6b0c.stl"/>
    <mesh name="base/cubic_connector_45x45_m12_tap_screw__2default" class="base/" file="cubic_connector_45x45_m12_tap_screw__2default-70202359f30c3d644497ca8da46ed3523d55f1b2.stl"/>
    <mesh name="base/basler_ace_aca1920-40gc__1default" class="base/" file="basler_ace_aca1920-40gc__1default-5643b5fc6fb90e606001858084a21b91b8c22028.stl"/>
    <mesh name="base/parametric_top__1default" class="base/" file="parametric_top__1default-26a28813bb85d9631f2dbbaa3eef94585eaa55a8.stl"/>
    <mesh name="base/45x45x800__1default" class="base/" file="45x45x800__1default-e63ce7f1ebb4cb5274caefdcd8259750412ba7ff.stl"/>
    <mesh name="base/45x45x193.5__2default" class="base/" file="45x45x193.5__2default-b5d3bd368ca0ee8a067722b7625ac7f440abb879.stl"/>
    <mesh name="base/lasercut_basket_part_4__2default" class="base/" file="lasercut_basket_part_4__2default-69bfd36b90eefc8e06dfe4ae91b05a447df1b3bc.stl"/>
    <mesh name="base/lasercut_basket_part_4__4default" class="base/" file="lasercut_basket_part_4__4default-69bfd36b90eefc8e06dfe4ae91b05a447df1b3bc.stl"/>
    <mesh name="base/cubic_connector_45x45_cover__2default" class="base/" file="cubic_connector_45x45_cover__2default-f9dcb76d1c30c5aebbcae00509cc3d34a9643213.stl"/>
    <mesh name="base/cubic_connector_45x45_main_body__1default" class="base/" file="cubic_connector_45x45_main_body__1default-fd79f369a14c0cef591f973fb04c77df4ccee511.stl"/>
    <mesh name="base/cubic_connector_45x45_cover__1default" class="base/" file="cubic_connector_45x45_cover__1default-f9dcb76d1c30c5aebbcae00509cc3d34a9643213.stl"/>
    <mesh name="base/gusset_45x45__2default" class="base/" file="gusset_45x45__2default-c8558cdf8d7a3f6858ac389300e5e4c819df123e.stl"/>
    <mesh name="base/lens_ts0814-mp_f1.4_f8mm_1inch__1default" class="base/" file="lens_ts0814-mp_f1.4_f8mm_1inch__1default-f2ffeb1945a16af02c457e37acc2de6ee6c8b3f2.stl"/>
    <mesh name="base/cubic_connector_45x45_m12_tap_screw__1default" class="base/" file="cubic_connector_45x45_m12_tap_screw__1default-70202359f30c3d644497ca8da46ed3523d55f1b2.stl"/>
    <mesh name="base/lasercut_basket_part_3__1default" class="base/" file="lasercut_basket_part_3__1default-e43553274e18bd850e3ddece45de8d00f275eb6c.stl"/>
    <mesh name="base/lasercut_basket_part_2__6default" class="base/" file="lasercut_basket_part_2__6default-833aa9c794e59bc0a8a15644ec6bac15ecef5d7e.stl"/>
    <mesh name="base/45x45x800__2default" class="base/" file="45x45x800__2default-e63ce7f1ebb4cb5274caefdcd8259750412ba7ff.stl"/>
    <mesh name="base/lasercut_basket_part_2__1default" class="base/" file="lasercut_basket_part_2__1default-e855c27891e63c945f35d64304438e6117082315.stl"/>
    <mesh name="base/gusset_45x45__4default" class="base/" file="gusset_45x45__4default-c8558cdf8d7a3f6858ac389300e5e4c819df123e.stl"/>
    <mesh name="base/lasercut_basket_part_1__4default" class="base/" file="lasercut_basket_part_1__4default-ca9532a13e4998272aa4f9207c61d46a7e2856aa.stl"/>
    <mesh name="base/lasercut_basket_part_1__1default" class="base/" file="lasercut_basket_part_1__1default-f73ee8580bb05ab1ed15347111365de78958f9db.stl"/>
    <mesh name="base/lasercut_basket_part_2__5default" class="base/" file="lasercut_basket_part_2__5default-0395f7a3873616f96e17277878a6c0001ca7b05b.stl"/>
    <mesh name="base/45x45x250__1default" class="base/" file="45x45x250__1default-297b6a12f85cb46bd2682b8add87e6e4aaf09cab.stl"/>
    <mesh name="base/45x45x800__4default" class="base/" file="45x45x800__4default-e63ce7f1ebb4cb5274caefdcd8259750412ba7ff.stl"/>
    <mesh name="base/lens_ts1214-mp_f1.4_f12.5mm_1inch__1default" class="base/" file="lens_ts1214-mp_f1.4_f12.5mm_1inch__1default-b45abb3d1f45aa74450b1f630dc34efbfc992a1c.stl"/>
    <mesh name="base/gusset_45x45__3default" class="base/" file="gusset_45x45__3default-c8558cdf8d7a3f6858ac389300e5e4c819df123e.stl"/>
    <mesh name="base/part_1__1default" class="base/" file="part_1__1default-5a302ceb8e487de8f737ca647a901096f90eebd8.stl"/>
    <mesh name="base/45x45x800__3default" class="base/" file="45x45x800__3default-e63ce7f1ebb4cb5274caefdcd8259750412ba7ff.stl"/>
    <mesh name="base/lasercut_basket_part_4__3default" class="base/" file="lasercut_basket_part_4__3default-69bfd36b90eefc8e06dfe4ae91b05a447df1b3bc.stl"/>
    <mesh name="base/lasercut_basket_part_4__1default" class="base/" file="lasercut_basket_part_4__1default-69bfd36b90eefc8e06dfe4ae91b05a447df1b3bc.stl"/>
    <mesh name="base/45x45x193.5__1default" class="base/" file="45x45x193.5__1default-b5d3bd368ca0ee8a067722b7625ac7f440abb879.stl"/>
    <mesh name="base/45x45x181.5__1default" class="base/" file="45x45x181.5__1default-cb8dbccb60aad0fce6d050d527584e96732883e7.stl"/>
    <mesh name="base/part_2__1default" class="base/" file="part_2__1default-e57d1a80fde2bc1e8987796e430c3706cdf6f1bb.stl"/>
    <mesh name="panda/link0" class="panda/" file="link0-3f633d19409870795516c6de40b4c7922f53c43d.stl"/>
    <mesh name="panda/link1" class="panda/" file="link1-53f934209b6019b996b6d9c714d0a9cf102f7fb2.stl"/>
    <mesh name="panda/link2" class="panda/" file="link2-8500c695b73e8ceeaa520c02db5684f02793b80f.stl"/>
    <mesh name="panda/link3" class="panda/" file="link3-0af960563df21dd3a3b0afac6e34f62bf10c71c4.stl"/>
    <mesh name="panda/link4" class="panda/" file="link4-97c9a53ee35f3939b3438a38005e78fd4c9f23cb.stl"/>
    <mesh name="panda/link5" class="panda/" file="link5-45f32b743a68e18d2c32d189c4bad39b4c3bb513.stl"/>
    <mesh name="panda/link6" class="panda/" file="link6-e9fa3ad660cf2a9b04e0ec55e8d56abf5891d531.stl"/>
    <mesh name="panda/link7" class="panda/" file="link7-5dcc7199c8e231447ebda37651ead64ebe3cf6ec.stl"/>
    <mesh name="panda/link1_submesh0" class="panda/" file="link1_submesh0-d48ecc8e50c31ff95e6847d4e2b1d1863261b9e1.stl"/>
    <mesh name="panda/link1_submesh1" class="panda/" file="link1_submesh1-2ba4d7e795d7bef243d552b6a5193731421ee38f.stl"/>
    <mesh name="panda/link1_submesh2" class="panda/" file="link1_submesh2-9063f48e055d0b19392c73489d6a037130ca7309.stl"/>
    <mesh name="panda/link1_submesh3" class="panda/" file="link1_submesh3-2425d9fabe03284efa426f322f5c987672cda219.stl"/>
    <mesh name="panda/link1_submesh4" class="panda/" file="link1_submesh4-d70fcc556c498b7bbc028b4cf452815111895071.stl"/>
    <mesh name="panda/link1_submesh5" class="panda/" file="link1_submesh5-01d63ca047e9da471c6ed4a339115a0749823b03.stl"/>
    <mesh name="panda/link1_submesh6" class="panda/" file="link1_submesh6-0896cf8d680da96af522a7f8a6b97574e8b0606e.stl"/>
    <mesh name="panda/link2_submesh0" class="panda/" file="link2_submesh0-a8febb9c86295cb9b4095a450f8ea81e91aeed9c.stl"/>
    <mesh name="panda/link2_submesh1" class="panda/" file="link2_submesh1-3a8a473a85607303f18d52a08be67c9cdae2ce91.stl"/>
    <mesh name="panda/link2_submesh2" class="panda/" file="link2_submesh2-766f789da0db1b69205311562f6ec19ec7b87d5b.stl"/>
    <mesh name="panda/link2_submesh3" class="panda/" file="link2_submesh3-fb34bc0436d987c33d2f77f10be2efb4ee1f1757.stl"/>
    <mesh name="panda/link2_submesh4" class="panda/" file="link2_submesh4-e18b998e9e346896f1af4c8658c10c0d13b2d419.stl"/>
    <mesh name="panda/link2_submesh5" class="panda/" file="link2_submesh5-c6d643094aada42bf3fe2e6bc6845cb353db453b.stl"/>
    <mesh name="panda/link2_submesh6" class="panda/" file="link2_submesh6-e68d939386823e9cbcd680c5173fedeb5f40000d.stl"/>
    <mesh name="panda/link2_submesh7" class="panda/" file="link2_submesh7-faf8172bb6df186ea307a86273d5946703101c53.stl"/>
    <mesh name="panda/link3_detail0" class="panda/" file="link3_detail0-f98a5aea809364d60e5039efdeec07dea90b27d9.stl"/>
    <mesh name="panda/link3_detail1" class="panda/" file="link3_detail1-1f6479d9382af56015742482f8e2845ae9020849.stl"/>
    <mesh name="panda/link3_jointcap0" class="panda/" file="link3_jointcap0-bdd480b11a8f0fb83dd0d97141624ce108513053.stl"/>
    <mesh name="panda/link3_jointcap1" class="panda/" file="link3_jointcap1-8b7d2ff06ac5e6b45abb8c792ae75dc58983ddc3.stl"/>
    <mesh name="panda/link3_jointcap2" class="panda/" file="link3_jointcap2-54db31a948b2de48fe56b24233a961d9a4b4fcd6.stl"/>
    <mesh name="panda/link3_jointcap3" class="panda/" file="link3_jointcap3-df53b7c419869cecfc945d7a59a914d26073b1bf.stl"/>
    <mesh name="panda/link3_main_submesh0" class="panda/" file="link3_main_submesh0-f385e1aa2ecbe15dd83c6b39b847c4f1a45efb69.stl"/>
    <mesh name="panda/link3_main_submesh1" class="panda/" file="link3_main_submesh1-ab550e254f38f8d75ffca3d26b51f8c1327e0861.stl"/>
    <mesh name="panda/link3_main_submesh2" class="panda/" file="link3_main_submesh2-715cdead403a5194eb599810d21fcd18cbfd0f3b.stl"/>
    <mesh name="panda/link3_main_submesh3" class="panda/" file="link3_main_submesh3-41f73ab4964f906a9560daa2d140bcc4dbe28466.stl"/>
    <mesh name="panda/link3_main_submesh4" class="panda/" file="link3_main_submesh4-d377089ad68c39346105bb636b7f9527193b9b6e.stl"/>
    <mesh name="panda/link3_main_submesh5" class="panda/" file="link3_main_submesh5-a528f495bbe56d73b164556b6be0e2246d87447b.stl"/>
    <mesh name="panda/link3_main_submesh6" class="panda/" file="link3_main_submesh6-e036b2e8e315aa4a3c35be681177c9632c1c2f63.stl"/>
    <mesh name="panda/link3_main_submesh7" class="panda/" file="link3_main_submesh7-74fb9aada9ccc0fb8765dc71f15d7295697613ee.stl"/>
    <mesh name="panda/link4_detail0" class="panda/" file="link4_detail0-babc55ddf61dcd86966dc734a8cedea79d214c6a.stl"/>
    <mesh name="panda/link4_detail1" class="panda/" file="link4_detail1-1dd33209526e2b39b74b635f203ba3cd90ebda39.stl"/>
    <mesh name="panda/link4_jointcap0" class="panda/" file="link4_jointcap0-98d2588a828f6869425ed3a6e1c36159a1921291.stl"/>
    <mesh name="panda/link4_jointcap1" class="panda/" file="link4_jointcap1-889154265c7f40d066055fe636ae84377639d8fe.stl"/>
    <mesh name="panda/link4_main_submesh0" class="panda/" file="link4_main_submesh0-c9159218bacd2026dbe82661bd511ed8dff7282c.stl"/>
    <mesh name="panda/link4_main_submesh1" class="panda/" file="link4_main_submesh1-76b761c8c08573d297b01c8573d591579aed0859.stl"/>
    <mesh name="panda/link4_main_submesh2" class="panda/" file="link4_main_submesh2-4a1cb889097bfc95e824c168f7b7e3486cbcf388.stl"/>
    <mesh name="panda/link4_main_submesh3" class="panda/" file="link4_main_submesh3-1212fadf6234cf135315b0761a5d458bdb444bbd.stl"/>
    <mesh name="panda/link4_main_submesh4" class="panda/" file="link4_main_submesh4-03e0200da141e982b9a4fd634b9636b82f24de86.stl"/>
    <mesh name="panda/link4_main_submesh5" class="panda/" file="link4_main_submesh5-c01ab4bf9c47734d032a79bb46bdbcb3f85bb841.stl"/>
    <mesh name="panda/link4_main_submesh6" class="panda/" file="link4_main_submesh6-7a0449003b4eb869ee846ab25585632806d37ba7.stl"/>
    <mesh name="panda/link4_main_submesh7" class="panda/" file="link4_main_submesh7-e8a9db38106fe95131693e1302818df6c771d768.stl"/>
    <mesh name="panda/link5_jointcap0" class="panda/" file="link5_jointcap0-b7aec7590bb1d3234f77e54fdecd619658e81776.stl"/>
    <mesh name="panda/link5_jointcap1" class="panda/" file="link5_jointcap1-1a3d9e7a80d0a5bd6e3621d46fe8e0d14e3736e1.stl"/>
    <mesh name="panda/link5_jointcap2" class="panda/" file="link5_jointcap2-e921aee6c03307879997796732de0c9fa1ed5f8a.stl"/>
    <mesh name="panda/link5_jointcap3" class="panda/" file="link5_jointcap3-6dfacb1a9de68e921473b8aef7fc51402d6bcd1e.stl"/>
    <mesh name="panda/link5_main_submesh0" class="panda/" file="link5_main_submesh0-a01791514ee7bd40e8421122467c390cad1d8464.stl"/>
    <mesh name="panda/link5_main_submesh1" class="panda/" file="link5_main_submesh1-dec4f04d7fab4c279b1c7e202973d380af37677b.stl"/>
    <mesh name="panda/link5_main_submesh2" class="panda/" file="link5_main_submesh2-fa572a7b5d762907d0de13dcaaf5143c4ea5a486.stl"/>
    <mesh name="panda/link5_main_submesh3" class="panda/" file="link5_main_submesh3-313d1ceb9e273bf658aa223319e51fc9e689323e.stl"/>
    <mesh name="panda/link5_main_submesh4" class="panda/" file="link5_main_submesh4-051272af6c6cf7ffe69b1dd1a21a04917d75d2ac.stl"/>
    <mesh name="panda/link5_main_submesh5" class="panda/" file="link5_main_submesh5-776bfd0373c34f5375df3d32b2b6eafdc32d4a11.stl"/>
    <mesh name="panda/link5_main_submesh6" class="panda/" file="link5_main_submesh6-6d3741df8284851a7ebe27d5d3176998e2553c0e.stl"/>
    <mesh name="panda/link5_main_submesh7" class="panda/" file="link5_main_submesh7-db95161ae220d5423897d527f45a5818628ebafa.stl"/>
    <mesh name="panda/link6_buttons0" class="panda/" file="link6_buttons0-cf45bc7c6a2d3cd4be5d725ec354ff04cf2f8724.stl"/>
    <mesh name="panda/link6_buttons1" class="panda/" file="link6_buttons1-956a275eba8695226fc6d30f76e3ba8b393f12da.stl"/>
    <mesh name="panda/link6_joint0" class="panda/" file="link6_joint0-e0a45142b100784225da96ead5c657d1b2f870f8.stl"/>
    <mesh name="panda/link6_joint1" class="panda/" file="link6_joint1-d628aea2da5c3b7bd970f1120155e612ab3259d0.stl"/>
    <mesh name="panda/link6_jointcap0" class="panda/" file="link6_jointcap0-9de4a4c8507359812349eb7e3179c922d581c35c.stl"/>
    <mesh name="panda/link6_jointcap1" class="panda/" file="link6_jointcap1-2c12ce304175718146b24868d14e03859c2dff56.stl"/>
    <mesh name="panda/link6_main_submesh0" class="panda/" file="link6_main_submesh0-6343afb2aedc8e9a2b964c58e3d355c33b006952.stl"/>
    <mesh name="panda/link6_main_submesh1" class="panda/" file="link6_main_submesh1-01c77d75454cbc01ed5be605063997968e906b2f.stl"/>
    <mesh name="panda/link6_main_submesh2" class="panda/" file="link6_main_submesh2-309e9f13f332663b67a78937c2c9057d5f178f72.stl"/>
    <mesh name="panda/link6_main_submesh3" class="panda/" file="link6_main_submesh3-2ed5fbba0fb0f571e4e37a6dd1af408dd231b5fc.stl"/>
    <mesh name="panda/link6_main_submesh4" class="panda/" file="link6_main_submesh4-c6320397d9d328e6669fb9456e813143e4ad3825.stl"/>
    <mesh name="panda/link6_main_submesh5" class="panda/" file="link6_main_submesh5-4d70a483d12e4615243870e24bb528304a3a7465.stl"/>
    <mesh name="panda/link6_main_submesh6" class="panda/" file="link6_main_submesh6-7f70e44ab41edfc859a0fe8eb2451a011de34b18.stl"/>
    <mesh name="panda/link6_main_submesh7" class="panda/" file="link6_main_submesh7-6e78b21310b5c5e94efccbbc7e37bb4c897da56a.stl"/>
    <mesh name="panda/link7_button0" class="panda/" file="link7_button0-1120dc1a719f28f239f96800b3477277fbfac826.stl"/>
    <mesh name="panda/link7_button1" class="panda/" file="link7_button1-9b760c3527900788c4d447b8d207e0a7b62be324.stl"/>
    <mesh name="panda/link7_handle0" class="panda/" file="link7_handle0-4af2979d486d9f88ea3fa0e27d6cdd43b21a6e15.stl"/>
    <mesh name="panda/link7_handle1" class="panda/" file="link7_handle1-cecec27751700be291bdc32ea36b86b93aa6ab6d.stl"/>
    <mesh name="panda/link7_main_submesh0" class="panda/" file="link7_main_submesh0-8b7c04141ab92f67686f463386cc25dcac79750c.stl"/>
    <mesh name="panda/link7_main_submesh1" class="panda/" file="link7_main_submesh1-94653e395a82b393336cc0625fa38398f0515068.stl"/>
    <mesh name="panda/link7_main_submesh2" class="panda/" file="link7_main_submesh2-78dd55c9a9a17154015e83eeaf23ead9bcb87ac5.stl"/>
    <mesh name="panda/link7_main_submesh3" class="panda/" file="link7_main_submesh3-c904fb842ab7fc5be42535d1646715b2211d04f0.stl"/>
    <material name="panda/joint_housing" class="panda/" rgba="0.25 0.25 0.25 1"/>
    <material name="panda/white_shell" class="panda/" rgba="1 1 1 1"/>
    <mesh name="panda/hand/base_mesh" class="panda/hand/" file="base-e5dacbcc3971bfdb549ff8c7d38ea873ca7f2933.stl" scale="0.001 0.001 0.001"/>
    <mesh name="panda/hand/driver_mesh" class="panda/hand/" file="driver-97efa43184c575b31ff1f3980641896f51492762.stl" scale="0.001 0.001 0.001"/>
    <mesh name="panda/hand/coupler_mesh" class="panda/hand/" file="coupler-0a4240dc94992944cca6ec9e270ff1658fa86c55.stl" scale="0.001 0.001 0.001"/>
    <mesh name="panda/hand/follower_v2_mesh" class="panda/hand/" file="follower_v2-7eb67c27fd4d1cf1e958842e8ad80d9c87d42285.stl"/>
    <mesh name="panda/hand/pad_mesh" class="panda/hand/" file="fingertip_v2-d5ba31c01f24f9ab45b58da6f0dcb0dbbe6e325b.stl"/>
    <mesh name="panda/hand/silicon_pad_mesh" class="panda/hand/" file="finger_pad_v2-f8993b2e5d2a136f22cb5557049879e951615f56.stl"/>
    <mesh name="panda/hand/fingertip_pad_v2_mesh" class="panda/hand/" file="fingertip_pad_v2-7494aedad64e22794b79f9f5edac7fe38fb2ac5c.stl"/>
    <mesh name="panda/hand/reinforced_fingertip_mesh" class="panda/hand/" file="reinforced_fingertip-c29b4a5d92e0e7f9f8191b8de02211a019a0a021.stl"/>
    <mesh name="panda/hand/spring_link_mesh" class="panda/hand/" file="spring_link-8f50234325193b84e9f86b7a63a24560a389c9bf.stl" scale="0.001 0.001 0.001"/>
    <mesh name="panda/hand/base_mount_mesh" class="panda/hand/" file="base_mount-22e57178defe77afb6bdd333bfae16607f1eb3dd.stl" scale="0.001 0.001 0.001"/>
    <mesh name="panda/wrist_back/camera_mount" class="panda/wrist_back/" file="camera_mount_v2-93590cc28cd6c55c574fd805fd2235010059c863.stl"/>
    <mesh name="panda/wrist_front/camera_mount" class="panda/wrist_front/" file="camera_mount_v2-93590cc28cd6c55c574fd805fd2235010059c863.stl"/>
    <mesh name="red_rgb_object/mesh_visual_red_rgb_object_00" class="red_rgb_object/" file="cbbe2184a4c7ca15fbe747d648486246e21e61c2.stl" scale="1 1 1"/>
    <mesh name="red_rgb_object/mesh_collision_red_rgb_object_00" class="red_rgb_object/" file="cbbe2184a4c7ca15fbe747d648486246e21e61c2.stl" scale=".9 .9 .9"/>
    <mesh name="green_rgb_object/mesh_visual_green_rgb_object_00" class="green_rgb_object/" file="b794feb2658282cf158501e5e8f0aceb213f0176.stl" scale="1 1 1"/>
    <mesh name="green_rgb_object/mesh_collision_green_rgb_object_00" class="green_rgb_object/" file="b794feb2658282cf158501e5e8f0aceb213f0176.stl" scale="1 1 1"/>
    <mesh name="blue_rgb_object/mesh_visual_blue_rgb_object_00" class="blue_rgb_object/" file="76c74f1a0292eda8bf64fb70a28cb8c2fafc8b49.stl" scale="1 1 1"/>
    <mesh name="blue_rgb_object/mesh_collision_blue_rgb_object_00" class="blue_rgb_object/" file="76c74f1a0292eda8bf64fb70a28cb8c2fafc8b49.stl" scale="1 1 1"/>
  </asset>
  <worldbody>
    <site name="BASKET" class="/" group="4" size="0.01" pos="0.6 0 0.0498"/>
    <body pos="0.6 0 0.0498" name="base/">
      <body name="base/rgb_basket" pos="0 0 0" quat="0.707 0 0 0.707">
        <geom name="base//unnamed_geom_0" class="base/" type="mesh" contype="0" conaffinity="0" rgba="0.49803900000000001 0.49803900000000001 0.49803900000000001 1" pos="0 0.12 -0.050099999999999999" mesh="base/lasercut_basket_part_1__3default"/>
        <geom name="base//unnamed_geom_1" class="base/" type="mesh" contype="0" conaffinity="0" rgba="0.34117599999999998 0.77647100000000002 0.74117599999999995 1" pos="0.42249999999999999 -0.42249999999999999 0.20549999999999999" quat="1.3267900000000001e-06 0 0 1" mesh="base/camera_support_base__1default"/>
        <geom name="base//unnamed_geom_2" class="base/" type="mesh" contype="0" conaffinity="0" rgba="0.64705900000000005 0.64705900000000005 0.64705900000000005 1" pos="0.42249999999999999 0.42249999999999999 0.1305" quat="1.3267900000000001e-06 1 0 0" mesh="base/45x45x181.5__2default"/>
        <geom name="base//unnamed_geom_3" class="base/" type="mesh" contype="0" conaffinity="0" rgba="0.89803900000000003 0.91764699999999999 0.92941200000000002 1" pos="-0.40000000000000002 -0.42249999999999999 0.153" quat="0.16280800000000001 0.68810700000000002 0.68811 -0.16280600000000001" mesh="base/cubic_connector_45x45_cover__3default"/>
        <geom name="base//unnamed_geom_4" class="base/" type="mesh" contype="0" conaffinity="0" rgba="0.50980400000000003 0.50980400000000003 0.58823499999999995 1" pos="0.42249999999999999 -0.40000000000000002 0.153" quat="0.66792300000000004 -1.01243e-07 0.74422999999999995 -1.01243e-07" mesh="base/cubic_connector_45x45_m12_tap_screw__3default"/>
        <geom name="base//unnamed_geom_5" class="base/" type="mesh" contype="0" conaffinity="0" rgba="0.50980400000000003 0.50980400000000003 0.58823499999999995 1" pos="-0.42249999999999999 -0.40000000000000002 0.17549999999999999" quat="9.3818399999999995e-07 -9.3818700000000004e-07 0.70710799999999996 -0.70710499999999998" mesh="base/gusset_45x45__1default"/>
        <geom name="base//unnamed_geom_6" class="base/" type="mesh" contype="0" conaffinity="0" rgba="0.49803900000000001 0.49803900000000001 0.49803900000000001 1" pos="0.12 0 -0.050099999999999999" quat="0.70710499999999998 0 0 -0.70710799999999996" mesh="base/lasercut_basket_part_1__2default"/>
        <geom name="base//unnamed_geom_7" class="base/" type="mesh" contype="0" conaffinity="0" rgba="0.91764699999999999 0.91764699999999999 0.91764699999999999 1" pos="-0.27250000000000002 0.55000000000000004 0.153" quat="0.499998 0.5 -0.5 0.50000199999999995" mesh="base/45x45x105__1default"/>
        <geom name="base//unnamed_geom_8" class="base/" type="mesh" contype="0" conaffinity="0" rgba="0.89803900000000003 0.91764699999999999 0.92941200000000002 1" pos="-0.42249999999999999 0.42249999999999999 0.1305" quat="0.36288199999999998 -0.36288300000000001 -0.60689199999999999 0.60689000000000004" mesh="base/cubic_connector_45x45_cover__3default"/>
        <geom name="base//unnamed_geom_9" class="base/" type="mesh" contype="0" conaffinity="0" rgba="0.231373 0.38039200000000001 0.70588200000000001 1" pos="0.42249999999999999 -0.42249999999999999 0.17549999999999999" quat="0.70710499999999998 0 0 -0.70710799999999996" mesh="base/45x45x30__1default"/>
        <geom name="base//unnamed_geom_10" class="base/" type="mesh" contype="0" conaffinity="0" rgba="0.231373 0.38039200000000001 0.70588200000000001 1" pos="-0.42249999999999999 -0.42249999999999999 0.17549999999999999" quat="1.3267900000000001e-06 0 0 1" mesh="base/45x45x30__1default"/>
        <geom name="base//unnamed_geom_11" class="base/" type="mesh" contype="0" conaffinity="0" rgba="0.64705900000000005 0.64705900000000005 0.64705900000000005 1" pos="0.12 0 -0.050099999999999999" quat="0.70710499999999998 0 0 -0.70710799999999996" mesh="base/lasercut_basket_part_2__4default"/>
        <geom name="base//unnamed_geom_12" class="base/" type="mesh" contype="0" conaffinity="0" rgba="0.50980400000000003 0.50980400000000003 0.58823499999999995 1" pos="-0.42249999999999999 0.42249999999999999 0.1305" quat="9.3818399999999995e-07 -9.3818700000000004e-07 -0.70710799999999996 0.70710499999999998" mesh="base/cubic_connector_45x45_m12_tap_screw__2default"/>
        <geom name="base//unnamed_geom_13" class="base/" type="mesh" contype="0" conaffinity="0" rgba="0.89803900000000003 0.91764699999999999 0.92941200000000002 1" pos="0.40637899999999999 -0.40637899999999999 0.25622200000000001" quat="0.90369100000000002 -0.079564300000000004 -0.19208500000000001 -0.37432100000000001" mesh="base/basler_ace_aca1920-40gc__1default"/>
        <geom name="base//unnamed_geom_14" class="base/" type="mesh" contype="0" conaffinity="0" rgba="0.49803900000000001 0.49803900000000001 0.49803900000000001 1" pos="-0.42249999999999999 -0.42249999999999999 0.21049999999999999" quat="9.3818399999999995e-07 0.70710499999999998 -0.70710799999999996 -9.3818700000000004e-07" mesh="base/parametric_top__1default"/>
        <geom name="base//unnamed_geom_15" class="base/" type="mesh" contype="0" conaffinity="0" rgba="0.64705900000000005 0.64705900000000005 0.64705900000000005 1" pos="0.40000000000000002 -0.42249999999999999 0.153" quat="9.3818399999999995e-07 -0.70710499999999998 9.3818700000000004e-07 0.70710799999999996" mesh="base/45x45x800__1default"/>
        <geom name="base//unnamed_geom_16" class="base/" type="mesh" contype="0" conaffinity="0" rgba="0.49803900000000001 0.49803900000000001 0.49803900000000001 1" pos="0 0.12 -0.050099999999999999" mesh="base/lasercut_basket_part_1__2default"/>
        <geom name="base//unnamed_geom_17" class="base/" type="mesh" contype="0" conaffinity="0" rgba="0.64705900000000005 0.64705900000000005 0.64705900000000005 1" pos="0.42249999999999999 -0.42249999999999999 -0.063" quat="0.70710499999999998 0 0 0.70710799999999996" mesh="base/45x45x193.5__2default"/>
        <geom name="base//unnamed_geom_18" class="base/" type="mesh" contype="0" conaffinity="0" rgba="0.49803900000000001 0.49803900000000001 0.49803900000000001 1" pos="0 0.12 -0.050099999999999999" mesh="base/lasercut_basket_part_4__2default"/>
        <geom name="base//unnamed_geom_19" class="base/" type="mesh" contype="0" conaffinity="0" rgba="0.49803900000000001 0.49803900000000001 0.49803900000000001 1" pos="-0.12 0 -0.050099999999999999" quat="0.70710499999999998 0 0 0.70710799999999996" mesh="base/lasercut_basket_part_4__4default"/>
        <geom name="base//unnamed_geom_20" class="base/" type="mesh" contype="0" conaffinity="0" rgba="0.49803900000000001 0.49803900000000001 0.49803900000000001 1" pos="0.12 0 -0.050099999999999999" quat="0.70710499999999998 0 0 -0.70710799999999996" mesh="base/lasercut_basket_part_1__3default"/>
        <geom name="base//unnamed_geom_21" class="base/" type="mesh" contype="0" conaffinity="0" rgba="0.34117599999999998 0.77647100000000002 0.74117599999999995 1" pos="-0.27550000000000002 0.57250000000000001 0.33250000000000002" mesh="base/camera_support_base__1default"/>
        <geom name="base//unnamed_geom_22" class="base/" type="mesh" contype="0" conaffinity="0" rgba="0.89803900000000003 0.91764699999999999 0.92941200000000002 1" pos="-0.40000000000000002 0.42249999999999999 0.153" quat="0.17254 0.68573200000000001 0.68573499999999998 -0.172538" mesh="base/cubic_connector_45x45_cover__2default"/>
        <geom name="base//unnamed_geom_23" class="base/" type="mesh" contype="0" conaffinity="0" rgba="0.89803900000000003 0.91764699999999999 0.92941200000000002 1" pos="-0.40637899999999999 -0.40637899999999999 0.25622200000000001" quat="0.37432300000000002 -0.19208500000000001 -0.079564800000000005 -0.90368999999999999" mesh="base/basler_ace_aca1920-40gc__1default"/>
        <geom name="base//unnamed_geom_24" class="base/" type="mesh" contype="0" conaffinity="0" rgba="0.50980400000000003 0.50980400000000003 0.58823499999999995 1" pos="0.42249999999999999 0.40000000000000002 0.153" quat="9.3818399999999995e-07 -0.70710499999999998 9.3818700000000004e-07 0.70710799999999996" mesh="base/cubic_connector_45x45_main_body__1default"/>
        <geom name="base//unnamed_geom_25" class="base/" type="mesh" contype="0" conaffinity="0" rgba="0.50980400000000003 0.50980400000000003 0.58823499999999995 1" pos="0.40000000000000002 -0.42249999999999999 0.153" quat="0.499998 -0.5 0.5 0.50000199999999995" mesh="base/cubic_connector_45x45_m12_tap_screw__2default"/>
        <geom name="base//unnamed_geom_26" class="base/" type="mesh" contype="0" conaffinity="0" rgba="0.89803900000000003 0.91764699999999999 0.92941200000000002 1" pos="-0.42249999999999999 0.40000000000000002 0.153" quat="1.2911499999999999e-06 0.97313300000000003 3.0548699999999999e-07 -0.230244" mesh="base/cubic_connector_45x45_cover__1default"/>
        <geom name="base//unnamed_geom_27" class="base/" type="mesh" contype="0" conaffinity="0" rgba="0.50980400000000003 0.50980400000000003 0.58823499999999995 1" pos="-0.40000000000000002 -0.42249999999999999 0.17549999999999999" quat="0.499998 -0.5 -0.50000199999999995 0.5" mesh="base/gusset_45x45__2default"/>
        <geom name="base//unnamed_geom_28" class="base/" type="mesh" contype="0" conaffinity="0" rgba="0.30196099999999998 0.30196099999999998 0.30196099999999998 1" pos="0.40637899999999999 -0.40637899999999999 0.25622200000000001" quat="0.71768299999999996 0.55490399999999995 -0.395123 -0.144537" mesh="base/lens_ts0814-mp_f1.4_f8mm_1inch__1default"/>
        <geom name="base//unnamed_geom_29" class="base/" type="mesh" contype="0" conaffinity="0" rgba="0.64705900000000005 0.64705900000000005 0.64705900000000005 1" pos="0 0.12 -0.050099999999999999" mesh="base/lasercut_basket_part_2__4default"/>
        <geom name="base//unnamed_geom_30" class="base/" type="mesh" contype="0" conaffinity="0" rgba="0.50980400000000003 0.50980400000000003 0.58823499999999995 1" pos="0.40000000000000002 0.42249999999999999 0.153" quat="0.47229500000000002 -0.52624899999999997 0.52625200000000005 0.47229199999999999" mesh="base/cubic_connector_45x45_m12_tap_screw__1default"/>
        <geom name="base//unnamed_geom_31" class="base/" type="mesh" contype="0" conaffinity="0" rgba="0.49803900000000001 0.49803900000000001 0.49803900000000001 1" pos="0 0.12 -0.0511" mesh="base/lasercut_basket_part_3__1default"/>
        <geom name="base//unnamed_geom_32" class="base/" type="mesh" contype="0" conaffinity="0" rgba="0.64705900000000005 0.64705900000000005 0.64705900000000005 1" pos="0 0.12 -0.050099999999999999" mesh="base/lasercut_basket_part_2__6default"/>
        <geom name="base//unnamed_geom_33" class="base/" type="mesh" contype="0" conaffinity="0" rgba="0.50980400000000003 0.50980400000000003 0.58823499999999995 1" pos="-0.40000000000000002 -0.42249999999999999 0.153" quat="0.47229500000000002 0.52624899999999997 0.52625200000000005 -0.47229199999999999" mesh="base/cubic_connector_45x45_m12_tap_screw__1default"/>
        <geom name="base//unnamed_geom_34" class="base/" type="mesh" contype="0" conaffinity="0" rgba="0.64705900000000005 0.64705900000000005 0.64705900000000005 1" pos="0.42249999999999999 -0.40000000000000002 0.153" quat="0.499998 -0.5 0.5 0.50000199999999995" mesh="base/45x45x800__2default"/>
        <geom name="base//unnamed_geom_35" class="base/" type="mesh" contype="0" conaffinity="0" rgba="0.50980400000000003 0.50980400000000003 0.58823499999999995 1" pos="-0.42249999999999999 0.40000000000000002 0.153" quat="9.8744099999999993e-07 0.74422999999999995 8.86197e-07 -0.66792300000000004" mesh="base/cubic_connector_45x45_m12_tap_screw__3default"/>
        <geom name="base//unnamed_geom_36" class="base/" type="mesh" contype="0" conaffinity="0" rgba="0.50980400000000003 0.50980400000000003 0.58823499999999995 1" pos="0.40000000000000002 -0.42249999999999999 0.153" quat="0.499998 -0.5 0.5 0.50000199999999995" mesh="base/cubic_connector_45x45_main_body__1default"/>
        <geom name="base//unnamed_geom_37" class="base/" type="mesh" contype="0" conaffinity="0" rgba="0.50980400000000003 0.50980400000000003 0.58823499999999995 1" pos="-0.25 0.44500000000000001 0.14749999999999999" quat="0.499998 0.5 -0.5 0.50000199999999995" mesh="base/gusset_45x45__2default"/>
        <geom name="base//unnamed_geom_38" class="base/" type="mesh" contype="0" conaffinity="0" rgba="0.64705900000000005 0.64705900000000005 0.64705900000000005 1" pos="0.12 0 -0.050099999999999999" quat="0.70710499999999998 0 0 -0.70710799999999996" mesh="base/lasercut_basket_part_2__1default"/>
        <geom name="base//unnamed_geom_39" class="base/" type="mesh" contype="0" conaffinity="0" rgba="0.64705900000000005 0.64705900000000005 0.64705900000000005 1" pos="0 0.12 -0.050099999999999999" mesh="base/lasercut_basket_part_2__1default"/>
        <geom name="base//unnamed_geom_40" class="base/" type="mesh" contype="0" conaffinity="0" rgba="0.89803900000000003 0.91764699999999999 0.92941200000000002 1" pos="0.42249999999999999 0.40000000000000002 0.153" quat="1.28669e-06 0.969773 3.2374699999999999e-07 -0.244007" mesh="base/cubic_connector_45x45_cover__1default"/>
        <geom name="base//unnamed_geom_41" class="base/" type="mesh" contype="0" conaffinity="0" rgba="0.50980400000000003 0.50980400000000003 0.58823499999999995 1" pos="-0.27250000000000002 0.55000000000000004 0.125" quat="9.3818399999999995e-07 9.3818700000000004e-07 0.70710799999999996 0.70710499999999998" mesh="base/gusset_45x45__4default"/>
        <geom name="base//unnamed_geom_42" class="base/" type="mesh" contype="0" conaffinity="0" rgba="0.49803900000000001 0.49803900000000001 0.49803900000000001 1" pos="0.12 0 -0.050099999999999999" quat="0.70710499999999998 0 0 -0.70710799999999996" mesh="base/lasercut_basket_part_1__4default"/>
        <geom name="base//unnamed_geom_43" class="base/" type="mesh" contype="0" conaffinity="0" rgba="0.50980400000000003 0.50980400000000003 0.58823499999999995 1" pos="0.40000000000000002 -0.42249999999999999 0.17549999999999999" quat="0.499998 -0.5 0.50000199999999995 -0.5" mesh="base/gusset_45x45__2default"/>
        <geom name="base//unnamed_geom_44" class="base/" type="mesh" contype="0" conaffinity="0" rgba="0.49803900000000001 0.49803900000000001 0.49803900000000001 1" pos="0 0.12 -0.050099999999999999" mesh="base/lasercut_basket_part_1__1default"/>
        <geom name="base//unnamed_geom_45" class="base/" type="mesh" contype="0" conaffinity="0" rgba="0.64705900000000005 0.64705900000000005 0.64705900000000005 1" pos="0.12 0 -0.050099999999999999" quat="0.70710499999999998 0 0 -0.70710799999999996" mesh="base/lasercut_basket_part_2__6default"/>
        <geom name="base//unnamed_geom_46" class="base/" type="mesh" contype="0" conaffinity="0" rgba="0.89803900000000003 0.91764699999999999 0.92941200000000002 1" pos="0.40000000000000002 0.42249999999999999 0.153" quat="0.16280800000000001 -0.68810700000000002 0.68811 0.16280600000000001" mesh="base/cubic_connector_45x45_cover__2default"/>
        <geom name="base//unnamed_geom_47" class="base/" type="mesh" contype="0" conaffinity="0" rgba="0.50980400000000003 0.50980400000000003 0.58823499999999995 1" pos="-0.29499999999999998 0.44500000000000001 0.1585" quat="0.499998 0.5 0.5 -0.50000199999999995" mesh="base/gusset_45x45__1default"/>
        <geom name="base//unnamed_geom_48" class="base/" type="mesh" contype="0" conaffinity="0" rgba="0.64705900000000005 0.64705900000000005 0.64705900000000005 1" pos="0 0.12 -0.050099999999999999" mesh="base/lasercut_basket_part_2__5default"/>
        <geom name="base//unnamed_geom_49" class="base/" type="mesh" contype="0" conaffinity="0" rgba="0.89803900000000003 0.91764699999999999 0.92941200000000002 1" pos="-0.42249999999999999 -0.40000000000000002 0.153" quat="0.244007 -9.6294300000000005e-07 0.969773 -9.6294300000000005e-07" mesh="base/cubic_connector_45x45_cover__2default"/>
        <geom name="base//unnamed_geom_50" class="base/" type="mesh" contype="0" conaffinity="0" rgba="0.64705900000000005 0.64705900000000005 0.64705900000000005 1" pos="-0.27550000000000002 0.57250000000000001 0.082500000000000004" quat="1.3267900000000001e-06 0 0 1" mesh="base/45x45x250__1default"/>
        <geom name="base//unnamed_geom_51" class="base/" type="mesh" contype="0" conaffinity="0" rgba="0.89803900000000003 0.91764699999999999 0.92941200000000002 1" pos="0.40000000000000002 -0.42249999999999999 0.153" quat="0.17254 -0.68573200000000001 0.68573499999999998 0.172538" mesh="base/cubic_connector_45x45_cover__3default"/>
        <geom name="base//unnamed_geom_52" class="base/" type="mesh" contype="0" conaffinity="0" rgba="0.50980400000000003 0.50980400000000003 0.58823499999999995 1" pos="-0.42249999999999999 -0.40000000000000002 0.153" quat="0.70710499999999998 0 0.70710799999999996 0" mesh="base/cubic_connector_45x45_m12_tap_screw__3default"/>
        <geom name="base//unnamed_geom_53" class="base/" type="mesh" contype="0" conaffinity="0" rgba="0.50980400000000003 0.50980400000000003 0.58823499999999995 1" pos="0.42249999999999999 0.42249999999999999 0.1305" quat="0.499998 -0.5 -0.50000199999999995 0.5" mesh="base/cubic_connector_45x45_m12_tap_screw__3default"/>
        <geom name="base//unnamed_geom_54" class="base/" type="mesh" contype="0" conaffinity="0" rgba="0.50980400000000003 0.50980400000000003 0.58823499999999995 1" pos="0.42249999999999999 -0.40000000000000002 0.17549999999999999" quat="9.3818399999999995e-07 -9.3818700000000004e-07 0.70710799999999996 -0.70710499999999998" mesh="base/gusset_45x45__1default"/>
        <geom name="base//unnamed_geom_55" class="base/" type="mesh" contype="0" conaffinity="0" rgba="0.34117599999999998 0.77647100000000002 0.74117599999999995 1" pos="-0.42249999999999999 -0.42249999999999999 0.20549999999999999" quat="0.70710499999999998 0 0 0.70710799999999996" mesh="base/camera_support_base__1default"/>
        <geom name="base//unnamed_geom_56" class="base/" type="mesh" contype="0" conaffinity="0" rgba="0.64705900000000005 0.64705900000000005 0.64705900000000005 1" pos="-0.42249999999999999 0.40000000000000002 0.153" quat="0.499998 0.5 0.5 -0.50000199999999995" mesh="base/45x45x800__4default"/>
        <geom name="base//unnamed_geom_57" class="base/" type="mesh" contype="0" conaffinity="0" rgba="0.91764699999999999 0.91764699999999999 0.91764699999999999 1" pos="-0.27550000000000002 0.57250000000000001 0.33750000000000002" quat="1.75154e-12 -1.3267900000000001e-06 -1 1.3267900000000001e-06" mesh="base/parametric_top__1default"/>
        <geom name="base//unnamed_geom_58" class="base/" type="mesh" contype="0" conaffinity="0" rgba="0.49803900000000001 0.49803900000000001 0.49803900000000001 1" pos="0 0.12 -0.050099999999999999" mesh="base/lasercut_basket_part_1__4default"/>
        <geom name="base//unnamed_geom_59" class="base/" type="mesh" contype="0" conaffinity="0" rgba="0.89803900000000003 0.91764699999999999 0.92941200000000002 1" pos="0.42249999999999999 0.42249999999999999 0.1305" quat="0.68573200000000001 -0.68573499999999998 -0.172539 0.172539" mesh="base/cubic_connector_45x45_cover__3default"/>
        <geom name="base//unnamed_geom_60" class="base/" type="mesh" contype="0" conaffinity="0" rgba="0.49803900000000001 0.49803900000000001 0.49803900000000001 1" pos="0.42249999999999999 -0.42249999999999999 0.21049999999999999" quat="1.3267900000000001e-06 1 0 0" mesh="base/parametric_top__1default"/>
        <geom name="base//unnamed_geom_61" class="base/" type="mesh" contype="0" conaffinity="0" rgba="0.89803900000000003 0.91764699999999999 0.92941200000000002 1" pos="0.42249999999999999 -0.40000000000000002 0.153" quat="0.230244 -9.8566099999999992e-07 0.97313300000000003 -9.8566099999999992e-07" mesh="base/cubic_connector_45x45_cover__2default"/>
        <geom name="base//unnamed_geom_62" class="base/" type="mesh" contype="0" conaffinity="0" rgba="0.30196099999999998 0.30196099999999998 0.30196099999999998 1" pos="-0.27400600000000003 0.56929600000000002 0.39799200000000001" quat="0.27945199999999998 -0.50313799999999997 -0.80357599999999996 -0.15174199999999999" mesh="base/lens_ts1214-mp_f1.4_f12.5mm_1inch__1default"/>
        <geom name="base//unnamed_geom_63" class="base/" type="mesh" contype="0" conaffinity="0" rgba="0.50980400000000003 0.50980400000000003 0.58823499999999995 1" pos="-0.27250000000000002 0.55000000000000004 0.18099999999999999" quat="0.70710499999999998 -0.70710799999999996 0 0" mesh="base/gusset_45x45__3default"/>
        <geom name="base//unnamed_geom_64" class="base/" type="mesh" contype="0" conaffinity="0" rgba="0.50980400000000003 0.50980400000000003 0.58823499999999995 1" pos="-0.42249999999999999 -0.42249999999999999 0.1305" quat="0.499998 -0.5 0.50000199999999995 -0.5" mesh="base/cubic_connector_45x45_m12_tap_screw__2default"/>
        <geom name="base//unnamed_geom_65" class="base/" type="mesh" contype="0" conaffinity="0" rgba="0.89803900000000003 0.91764699999999999 0.92941200000000002 1" pos="0.42249999999999999 -0.42249999999999999 0.1305" quat="0.60688799999999998 -0.60689000000000004 0.36288500000000001 -0.36288399999999998" mesh="base/cubic_connector_45x45_cover__1default"/>
        <geom name="base//unnamed_geom_66" class="base/" type="mesh" contype="0" conaffinity="0" rgba="0.34902 0.376471 0.40000000000000002 1" pos="0.42249999999999999 -0.42249999999999999 0.17549999999999999" quat="0.70710499999999998 0 0 -0.70710799999999996" mesh="base/part_1__1default"/>
        <geom name="base//unnamed_geom_67" class="base/" type="mesh" contype="0" conaffinity="0" rgba="0.50980400000000003 0.50980400000000003 0.58823499999999995 1" pos="0.42249999999999999 -0.42249999999999999 0.1305" quat="0.70710499999999998 -0.70710799999999996 0 0" mesh="base/cubic_connector_45x45_m12_tap_screw__1default"/>
        <geom name="base//unnamed_geom_68" class="base/" type="mesh" contype="0" conaffinity="0" rgba="0.89803900000000003 0.91764699999999999 0.92941200000000002 1" pos="0.40616200000000002 -0.40615600000000002 0.25608300000000001" quat="0.90340600000000004 -0.079418799999999998 -0.19214600000000001 -0.37500600000000001" mesh="base/basler_ace_aca1920-40gc__1default"/>
        <geom name="base//unnamed_geom_69" class="base/" type="mesh" contype="0" conaffinity="0" rgba="0.30196099999999998 0.30196099999999998 0.30196099999999998 1" pos="0.40616200000000002 -0.40615600000000002 0.25608300000000001" quat="0.90340600000000004 -0.079418799999999998 -0.19214600000000001 -0.37500600000000001" mesh="base/lens_ts0814-mp_f1.4_f8mm_1inch__1default"/>
        <geom name="base//unnamed_geom_70" class="base/" type="mesh" contype="0" conaffinity="0" rgba="0.50980400000000003 0.50980400000000003 0.58823499999999995 1" pos="-0.42249999999999999 -0.40000000000000002 0.153" quat="0.70710499999999998 0 0.70710799999999996 0" mesh="base/cubic_connector_45x45_main_body__1default"/>
        <geom name="base//unnamed_geom_71" class="base/" type="mesh" contype="0" conaffinity="0" rgba="0.50980400000000003 0.50980400000000003 0.58823499999999995 1" pos="-0.40000000000000002 0.42249999999999999 0.153" quat="0.499998 0.5 0.5 -0.50000199999999995" mesh="base/cubic_connector_45x45_main_body__1default"/>
        <geom name="base//unnamed_geom_72" class="base/" type="mesh" contype="0" conaffinity="0" rgba="0.64705900000000005 0.64705900000000005 0.64705900000000005 1" pos="0.40000000000000002 0.42249999999999999 0.153" quat="9.3818399999999995e-07 -0.70710499999999998 9.3818700000000004e-07 0.70710799999999996" mesh="base/45x45x800__3default"/>
        <geom name="base//unnamed_geom_73" class="base/" type="mesh" contype="0" conaffinity="0" rgba="0.49803900000000001 0.49803900000000001 0.49803900000000001 1" pos="0.12 0 -0.050099999999999999" quat="0.70710499999999998 0 0 -0.70710799999999996" mesh="base/lasercut_basket_part_1__1default"/>
        <geom name="base//unnamed_geom_74" class="base/" type="mesh" contype="0" conaffinity="0" rgba="0.49803900000000001 0.49803900000000001 0.49803900000000001 1" pos="0.12 0 -0.050099999999999999" quat="0.70710499999999998 0 0 -0.70710799999999996" mesh="base/lasercut_basket_part_4__3default"/>
        <geom name="base//unnamed_geom_75" class="base/" type="mesh" contype="0" conaffinity="0" rgba="0.89803900000000003 0.91764699999999999 0.92941200000000002 1" pos="-0.42249999999999999 -0.42249999999999999 0.1305" quat="0.172539 -0.17254 0.68573499999999998 -0.68573200000000001" mesh="base/cubic_connector_45x45_cover__1default"/>
        <geom name="base//unnamed_geom_76" class="base/" type="mesh" contype="0" conaffinity="0" rgba="0.89803900000000003 0.91764699999999999 0.92941200000000002 1" pos="-0.27400600000000003 0.56929600000000002 0.39799200000000001" quat="0.50953300000000001 0.26761200000000002 -0.170488 0.79980799999999996" mesh="base/basler_ace_aca1920-40gc__1default"/>
        <geom name="base//unnamed_geom_77" class="base/" type="mesh" contype="0" conaffinity="0" rgba="0.50980400000000003 0.50980400000000003 0.58823499999999995 1" pos="0.42249999999999999 0.40000000000000002 0.153" quat="9.3818399999999995e-07 -0.70710499999999998 9.3818700000000004e-07 0.70710799999999996" mesh="base/cubic_connector_45x45_m12_tap_screw__2default"/>
        <geom name="base//unnamed_geom_78" class="base/" type="mesh" contype="0" conaffinity="0" rgba="0.49803900000000001 0.49803900000000001 0.49803900000000001 1" pos="0 -0.12 -0.050099999999999999" quat="1.3267900000000001e-06 0 0 1" mesh="base/lasercut_basket_part_4__1default"/>
        <geom name="base//unnamed_geom_79" class="base/" type="mesh" contype="0" conaffinity="0" rgba="0.64705900000000005 0.64705900000000005 0.64705900000000005 1" pos="-0.42249999999999999 -0.42249999999999999 -0.063" quat="0.70710499999999998 0 0 0.70710799999999996" mesh="base/45x45x193.5__1default"/>
        <geom name="base//unnamed_geom_80" class="base/" type="mesh" contype="0" conaffinity="0" rgba="0.64705900000000005 0.64705900000000005 0.64705900000000005 1" pos="-0.42249999999999999 0.42249999999999999 0.1305" quat="1.3267900000000001e-06 1 0 0" mesh="base/45x45x181.5__1default"/>
        <geom name="base//unnamed_geom_81" class="base/" type="mesh" contype="0" conaffinity="0" rgba="0.64705900000000005 0.64705900000000005 0.64705900000000005 1" pos="0.12 0 -0.050099999999999999" quat="0.70710499999999998 0 0 -0.70710799999999996" mesh="base/lasercut_basket_part_2__5default"/>
        <geom name="base//unnamed_geom_82" class="base/" type="mesh" contype="0" conaffinity="0" rgba="0.50980400000000003 0.50980400000000003 0.58823499999999995 1" pos="-0.40000000000000002 0.42249999999999999 0.153" quat="0.499998 0.5 0.5 -0.50000199999999995" mesh="base/cubic_connector_45x45_m12_tap_screw__1default"/>
        <geom name="base//unnamed_geom_83" class="base/" type="mesh" contype="0" conaffinity="0" rgba="0.30196099999999998 0.30196099999999998 0.30196099999999998 1" pos="-0.40637899999999999 -0.40637899999999999 0.25622200000000001" quat="-0.048034500000000001 -0.41798000000000002 0.81785099999999999 -0.392563" mesh="base/lens_ts0814-mp_f1.4_f8mm_1inch__1default"/>
        <geom name="base//unnamed_geom_84" class="base/" type="mesh" contype="0" conaffinity="0" rgba="0.61568599999999996 0.81176499999999996 0.92941200000000002 1" pos="0.42259999999999998 -0.42259999999999998 0.17549999999999999" quat="0.70710499999999998 0 0 -0.70710799999999996" mesh="base/part_2__1default"/>
        <body name="base/camera_ref" pos="0 0.59999999999999998 0" quat="0.707 0 0 -0.707">
          <camera name="base/basket_front_left" class="base/" fovy="35" pos="0.96999999999999997 -0.375 0.23499999999999999" quat="0.78149999999999997 0.48999999999999999 0.20499999999999999 0.32719999999999999"/>
          <camera name="base/basket_front_right" class="base/" fovy="35" pos="0.96999999999999997 0.375 0.23499999999999999" quat="0.32719999999999999 0.20499999999999999 0.48999999999999999 0.78149999999999997"/>
          <camera name="base/basket_back_left" class="base/" fovy="30" pos="0.059999999999999998 -0.26000000000000001 0.39000000000000001" quat="0.754 0.373 -0.25 -0.47999999999999998"/>
        </body>
      </body>
      <body name="base/collision_basket" pos="0 0 0" quat="0.707 0 0 0.707">
        <geom name="base/basket_front_left_camera_strut_CollisionGeom" class="base/" type="capsule" contype="0" conaffinity="0" group="5" size="0.059999999999999998" rgba="1 1 1 0.29999999999999999" fromto="0.41999999999999998 -0.41999999999999998 0.14999999999999999 0.41999999999999998 -0.41999999999999998 0.25"/>
        <geom name="base/basket_front_left_camera_CollisionGeom" class="base/" type="capsule" contype="0" conaffinity="0" group="5" size="0.040000000000000001" rgba="1 1 1 0.29999999999999999" fromto="0.42999999999999999 -0.42999999999999999 0.28000000000000003 0.35999999999999999 -0.35999999999999999 0.23999999999999999"/>
        <geom name="base/basket_front_right_camera_strut_CollisionGeom" class="base/" type="capsule" contype="0" conaffinity="0" group="5" size="0.059999999999999998" rgba="1 1 1 0.29999999999999999" fromto="-0.41999999999999998 -0.41999999999999998 0.14999999999999999 -0.41999999999999998 -0.41999999999999998 0.25"/>
        <geom name="base/basket_front_right_camera_CollisionGeom" class="base/" type="capsule" contype="0" conaffinity="0" group="5" size="0.040000000000000001" rgba="1 1 1 0.29999999999999999" fromto="-0.42999999999999999 -0.42999999999999999 0.28000000000000003 -0.35999999999999999 -0.35999999999999999 0.23999999999999999"/>
        <geom name="base/basket_back_camera_vertical_strut_CollisionGeom" class="base/" type="capsule" contype="0" conaffinity="0" group="5" size="0.059999999999999998" rgba="1 1 1 0.29999999999999999" fromto="-0.28000000000000003 0.56999999999999995 0.10000000000000001 -0.28000000000000003 0.56999999999999995 0.34999999999999998"/>
        <geom name="base/basket_back_camera_horizontal_strut_CollisionGeom" class="base/" type="capsule" contype="0" conaffinity="0" group="5" size="0.059999999999999998" rgba="1 1 1 0.29999999999999999" fromto="-0.28000000000000003 0.56999999999999995 0.14999999999999999 -0.28000000000000003 0.42999999999999999 0.14999999999999999"/>
        <geom name="base/basket_back_camera_CollisionGeom" class="base/" type="capsule" contype="0" conaffinity="0" group="5" size="0.040000000000000001" rgba="1 1 1 0.29999999999999999" fromto="-0.28499999999999998 0.59999999999999998 0.41999999999999998 -0.255 0.53000000000000003 0.35999999999999999"/>
        <geom name="base/basket_back_strut_CollisionGeom" class="base/" type="capsule" contype="0" conaffinity="0" group="5" size="0.050000000000000003" rgba="1 1 1 0.29999999999999999" fromto="0.40000000000000002 0.41999999999999998 0.14999999999999999 -0.40000000000000002 0.41999999999999998 0.14999999999999999"/>
        <geom name="base/basket_front_strut_CollisionGeom" class="base/" type="capsule" contype="0" conaffinity="0" group="5" size="0.050000000000000003" rgba="1 1 1 0.29999999999999999" fromto="0.40000000000000002 -0.41999999999999998 0.14999999999999999 -0.40000000000000002 -0.41999999999999998 0.14999999999999999"/>
        <geom name="base/basket_right_strut_CollisionGeom" class="base/" type="capsule" contype="0" conaffinity="0" group="5" size="0.050000000000000003" rgba="1 1 1 0.29999999999999999" fromto="-0.41999999999999998 0.40000000000000002 0.14999999999999999 -0.41999999999999998 -0.40000000000000002 0.14999999999999999"/>
        <geom name="base/basket_left_strut_CollisionGeom" class="base/" type="capsule" contype="0" conaffinity="0" group="5" size="0.050000000000000003" rgba="1 1 1 0.29999999999999999" fromto="0.41999999999999998 0.40000000000000002 0.14999999999999999 0.41999999999999998 -0.40000000000000002 0.14999999999999999"/>
        <geom name="base/basket_base_surface_CollisionGeom" class="base/" type="box" contype="1" conaffinity="1" group="5" size="0.25 0.25 0.02" rgba="1 1 0 0.29999999999999999" pos="0 0 -0.02"/>
        <geom name="base/basket_sloped_side_surfaces_CollisionGeom1" class="base/" type="box" contype="1" conaffinity="1" group="5" size="0.20000000000000001 0.40000000000000002 0.0050000000000000001" rgba="1 1 0 0.29999999999999999" pos="-0.28000000000000003 0 0.070000000000000007" axisangle="0 1 0 0.44506000000000001"/>
        <geom name="base/basket_sloped_side_surfaces_CollisionGeom2" class="base/" type="box" contype="1" conaffinity="1" group="5" size="0.20000000000000001 0.40000000000000002 0.0050000000000000001" rgba="1 1 0 0.29999999999999999" pos="0.28000000000000003 0 0.070000000000000007" axisangle="0 1 0 2.6965300000000001"/>
        <geom name="base/basket_sloped_side_surfaces_CollisionGeom3" class="base/" type="box" contype="1" conaffinity="1" group="5" size="0.40000000000000002 0.20000000000000001 0.0050000000000000001" rgba="1 1 0 0.29999999999999999" pos="0 -0.28000000000000003 0.070000000000000007" axisangle="1 0 0 2.6965300000000001"/>
        <geom name="base/basket_sloped_side_surfaces_CollisionGeom4" class="base/" type="box" contype="1" conaffinity="1" group="5" size="0.40000000000000002 0.20000000000000001 0.0050000000000000001" rgba="1 1 0 0.29999999999999999" pos="0 0.28000000000000003 0.070000000000000007" axisangle="1 0 0 0.44506000000000001"/>
      </body>
    </body>
    <site name="//unnamed_site_1" class="/" pos="0.048 0 0"/>
    <body pos="0.048 0 0" name="panda/">
      <site name="panda/base_site" class="panda/" pos="0 0 0"/>
      <geom name="panda//unnamed_geom_0" class="panda/collision-mesh" group="0" material="panda/white_shell" mesh="panda/link0"/>
      <body gravcomp="1" name="panda/panda_link1" pos="0 0 0.33300000000000002">
        <inertial pos="0 0 0" mass="2.3399999999999999" diaginertia="0.29999999999999999 0.29999999999999999 0.29999999999999999"/>
        <site name="panda/j1_site" class="panda/torque-sensor"/>
        <joint name="panda/panda_joint1" class="panda/" axis="0 0 1" limited="true" range="-2.8973 2.8973" /> damping="45"
        <geom name="panda//unnamed_geom_1" class="panda/collision-mesh" mesh="panda/link1"/>
        <geom name="panda//unnamed_geom_2" class="panda/visible-mesh" material="panda/white_shell" mesh="panda/link1_submesh0"/>
        <geom name="panda//unnamed_geom_3" class="panda/visible-mesh" material="panda/white_shell" mesh="panda/link1_submesh1"/>
        <geom name="panda//unnamed_geom_4" class="panda/visible-mesh" material="panda/white_shell" mesh="panda/link1_submesh2"/>
        <geom name="panda//unnamed_geom_5" class="panda/visible-mesh" material="panda/white_shell" mesh="panda/link1_submesh3"/>
        <geom name="panda//unnamed_geom_6" class="panda/visible-mesh" material="panda/white_shell" mesh="panda/link1_submesh4"/>
        <geom name="panda//unnamed_geom_7" class="panda/visible-mesh" material="panda/white_shell" mesh="panda/link1_submesh5"/>
        <geom name="panda//unnamed_geom_8" class="panda/visible-mesh" material="panda/white_shell" mesh="panda/link1_submesh6"/>
        <body gravcomp="1" name="panda/panda_link2" quat="0.70710700000000004 -0.70710700000000004 0 0">
          <inertial pos="0 0 0" mass="2.3599999999999999" diaginertia="0.29999999999999999 0.29999999999999999 0.29999999999999999"/>
          <site name="panda/j2_site" class="panda/torque-sensor"/>
          <joint name="panda/panda_joint2" class="panda/" axis="0 0 1" limited="true" range="-1.7627999999999999 1.7627999999999999" /> damping="45"
          <geom name="panda//unnamed_geom_9" class="panda/collision-mesh" mesh="panda/link2"/>
          <geom name="panda//unnamed_geom_10" class="panda/visible-mesh" material="panda/white_shell" mesh="panda/link2_submesh0"/>
          <geom name="panda//unnamed_geom_11" class="panda/visible-mesh" material="panda/white_shell" mesh="panda/link2_submesh1"/>
          <geom name="panda//unnamed_geom_12" class="panda/visible-mesh" material="panda/white_shell" mesh="panda/link2_submesh2"/>
          <geom name="panda//unnamed_geom_13" class="panda/visible-mesh" material="panda/white_shell" mesh="panda/link2_submesh3"/>
          <geom name="panda//unnamed_geom_14" class="panda/visible-mesh" material="panda/white_shell" mesh="panda/link2_submesh4"/>
          <geom name="panda//unnamed_geom_15" class="panda/visible-mesh" material="panda/white_shell" mesh="panda/link2_submesh5"/>
          <geom name="panda//unnamed_geom_16" class="panda/visible-mesh" material="panda/white_shell" mesh="panda/link2_submesh6"/>
          <geom name="panda//unnamed_geom_17" class="panda/visible-mesh" material="panda/white_shell" mesh="panda/link2_submesh7"/>
          <body gravcomp="1" name="panda/panda_link3" pos="0 -0.316 0" quat="0.70710700000000004 0.70710700000000004 0 0">
            <inertial pos="0 0 0" mass="2.3799999999999999" diaginertia="0.29999999999999999 0.29999999999999999 0.29999999999999999"/>
            <site name="panda/j3_site" class="panda/torque-sensor"/>
            <joint name="panda/panda_joint3" class="panda/" axis="0 0 1" limited="true" range="-2.8973 2.8973" /> damping="35"
            <geom name="panda//unnamed_geom_18" class="panda/collision-mesh" mesh="panda/link3"/>
            <geom name="panda//unnamed_geom_19" class="panda/visible-mesh" material="panda/white_shell" mesh="panda/link3_detail0"/>
            <geom name="panda//unnamed_geom_20" class="panda/visible-mesh" material="panda/white_shell" mesh="panda/link3_detail1"/>
            <geom name="panda//unnamed_geom_21" class="panda/visible-mesh" material="panda/joint_housing" mesh="panda/link3_jointcap0"/>
            <geom name="panda//unnamed_geom_22" class="panda/visible-mesh" material="panda/joint_housing" mesh="panda/link3_jointcap1"/>
            <geom name="panda//unnamed_geom_23" class="panda/visible-mesh" material="panda/joint_housing" mesh="panda/link3_jointcap2"/>
            <geom name="panda//unnamed_geom_24" class="panda/visible-mesh" material="panda/joint_housing" mesh="panda/link3_jointcap3"/>
            <geom name="panda//unnamed_geom_25" class="panda/visible-mesh" material="panda/white_shell" mesh="panda/link3_main_submesh0"/>
            <geom name="panda//unnamed_geom_26" class="panda/visible-mesh" material="panda/white_shell" mesh="panda/link3_main_submesh1"/>
            <geom name="panda//unnamed_geom_27" class="panda/visible-mesh" material="panda/white_shell" mesh="panda/link3_main_submesh2"/>
            <geom name="panda//unnamed_geom_28" class="panda/visible-mesh" material="panda/white_shell" mesh="panda/link3_main_submesh3"/>
            <geom name="panda//unnamed_geom_29" class="panda/visible-mesh" material="panda/white_shell" mesh="panda/link3_main_submesh4"/>
            <geom name="panda//unnamed_geom_30" class="panda/visible-mesh" material="panda/white_shell" mesh="panda/link3_main_submesh5"/>
            <geom name="panda//unnamed_geom_31" class="panda/visible-mesh" material="panda/white_shell" mesh="panda/link3_main_submesh6"/>
            <geom name="panda//unnamed_geom_32" class="panda/visible-mesh" material="panda/white_shell" mesh="panda/link3_main_submesh7"/>
            <body gravcomp="1" name="panda/panda_link4" pos="0.082500000000000004 0 0" quat="0.70710700000000004 0.70710700000000004 0 0">
              <inertial pos="0 0 0" mass="2.4300000000000002" diaginertia="0.29999999999999999 0.29999999999999999 0.29999999999999999"/>
              <site name="panda/j4_site" class="panda/torque-sensor"/>
              <joint name="panda/panda_joint4" class="panda/" axis="0 0 1" limited="true" range="-3.0718000000000001 -0.4" /> damping="35"
              <geom name="panda//unnamed_geom_33" class="panda/collision-mesh" mesh="panda/link4"/>
              <geom name="panda//unnamed_geom_34" class="panda/visible-mesh" material="panda/white_shell" mesh="panda/link4_detail0"/>
              <geom name="panda//unnamed_geom_35" class="panda/visible-mesh" material="panda/white_shell" mesh="panda/link4_detail1"/>
              <geom name="panda//unnamed_geom_36" class="panda/visible-mesh" material="panda/joint_housing" mesh="panda/link4_jointcap0"/>
              <geom name="panda//unnamed_geom_37" class="panda/visible-mesh" material="panda/joint_housing" mesh="panda/link4_jointcap1"/>
              <geom name="panda//unnamed_geom_38" class="panda/visible-mesh" material="panda/white_shell" mesh="panda/link4_main_submesh0"/>
              <geom name="panda//unnamed_geom_39" class="panda/visible-mesh" material="panda/white_shell" mesh="panda/link4_main_submesh1"/>
              <geom name="panda//unnamed_geom_40" class="panda/visible-mesh" material="panda/white_shell" mesh="panda/link4_main_submesh2"/>
              <geom name="panda//unnamed_geom_41" class="panda/visible-mesh" material="panda/white_shell" mesh="panda/link4_main_submesh3"/>
              <geom name="panda//unnamed_geom_42" class="panda/visible-mesh" material="panda/white_shell" mesh="panda/link4_main_submesh4"/>
              <geom name="panda//unnamed_geom_43" class="panda/visible-mesh" material="panda/white_shell" mesh="panda/link4_main_submesh5"/>
              <geom name="panda//unnamed_geom_44" class="panda/visible-mesh" material="panda/white_shell" mesh="panda/link4_main_submesh6"/>
              <geom name="panda//unnamed_geom_45" class="panda/visible-mesh" material="panda/white_shell" mesh="panda/link4_main_submesh7"/>
              <body gravcomp="1" name="panda/panda_link5" pos="-0.082500000000000004 0.38400000000000001 0" quat="0.70710700000000004 -0.70710700000000004 0 0">
                <inertial pos="0 0 0" mass="3.5" diaginertia="0.29999999999999999 0.29999999999999999 0.29999999999999999"/>
                <site name="panda/j5_site" class="panda/torque-sensor"/>
                <joint name="panda/panda_joint5" class="panda/" axis="0 0 1" limited="true" range="-2.8973 2.8973" /> damping="20"
                <geom name="panda//unnamed_geom_46" class="panda/collision-mesh" mesh="panda/link5"/>
                <geom name="panda//unnamed_geom_47" class="panda/visible-mesh" material="panda/joint_housing" mesh="panda/link5_jointcap0"/>
                <geom name="panda//unnamed_geom_48" class="panda/visible-mesh" material="panda/joint_housing" mesh="panda/link5_jointcap1"/>
                <geom name="panda//unnamed_geom_49" class="panda/visible-mesh" material="panda/joint_housing" mesh="panda/link5_jointcap2"/>
                <geom name="panda//unnamed_geom_50" class="panda/visible-mesh" material="panda/joint_housing" mesh="panda/link5_jointcap3"/>
                <geom name="panda//unnamed_geom_51" class="panda/visible-mesh" material="panda/white_shell" mesh="panda/link5_main_submesh0"/>
                <geom name="panda//unnamed_geom_52" class="panda/visible-mesh" material="panda/white_shell" mesh="panda/link5_main_submesh1"/>
                <geom name="panda//unnamed_geom_53" class="panda/visible-mesh" material="panda/white_shell" mesh="panda/link5_main_submesh2"/>
                <geom name="panda//unnamed_geom_54" class="panda/visible-mesh" material="panda/white_shell" mesh="panda/link5_main_submesh3"/>
                <geom name="panda//unnamed_geom_55" class="panda/visible-mesh" material="panda/white_shell" mesh="panda/link5_main_submesh4"/>
                <geom name="panda//unnamed_geom_56" class="panda/visible-mesh" material="panda/white_shell" mesh="panda/link5_main_submesh5"/>
                <geom name="panda//unnamed_geom_57" class="panda/visible-mesh" material="panda/white_shell" mesh="panda/link5_main_submesh6"/>
                <geom name="panda//unnamed_geom_58" class="panda/visible-mesh" material="panda/white_shell" mesh="panda/link5_main_submesh7"/>
                <body gravcomp="1" name="panda/panda_link6" quat="0.70710700000000004 0.70710700000000004 0 0">
                  <inertial pos="0 0 0" mass="1.47" diaginertia="0.29999999999999999 0.29999999999999999 0.29999999999999999"/>
                  <site name="panda/j6_site" class="panda/torque-sensor"/>
                  <joint name="panda/panda_joint6" class="panda/" axis="0 0 1" limited="false" range="-0.017500000000000002 3.7524999999999999" /> damping="20"
                  <geom name="panda//unnamed_geom_59" class="panda/collision-mesh" mesh="panda/link6"/>
                  <geom name="panda//unnamed_geom_60" class="panda/visible-mesh" material="panda/joint_housing" mesh="panda/link6_buttons0"/>
                  <geom name="panda//unnamed_geom_61" class="panda/visible-mesh" material="panda/joint_housing" mesh="panda/link6_buttons1"/>
                  <geom name="panda//unnamed_geom_62" class="panda/visible-mesh" material="panda/white_shell" mesh="panda/link6_joint0"/>
                  <geom name="panda//unnamed_geom_63" class="panda/visible-mesh" material="panda/white_shell" mesh="panda/link6_joint1"/>
                  <geom name="panda//unnamed_geom_64" class="panda/visible-mesh" material="panda/joint_housing" mesh="panda/link6_jointcap0"/>
                  <geom name="panda//unnamed_geom_65" class="panda/visible-mesh" material="panda/joint_housing" mesh="panda/link6_jointcap1"/>
                  <geom name="panda//unnamed_geom_66" class="panda/visible-mesh" material="panda/white_shell" mesh="panda/link6_main_submesh0"/>
                  <geom name="panda//unnamed_geom_67" class="panda/visible-mesh" material="panda/white_shell" mesh="panda/link6_main_submesh1"/>
                  <geom name="panda//unnamed_geom_68" class="panda/visible-mesh" material="panda/white_shell" mesh="panda/link6_main_submesh2"/>
                  <geom name="panda//unnamed_geom_69" class="panda/visible-mesh" material="panda/white_shell" mesh="panda/link6_main_submesh3"/>
                  <geom name="panda//unnamed_geom_70" class="panda/visible-mesh" material="panda/white_shell" mesh="panda/link6_main_submesh4"/>
                  <geom name="panda//unnamed_geom_71" class="panda/visible-mesh" material="panda/white_shell" mesh="panda/link6_main_submesh5"/>
                  <geom name="panda//unnamed_geom_72" class="panda/visible-mesh" material="panda/white_shell" mesh="panda/link6_main_submesh6"/>
                  <geom name="panda//unnamed_geom_73" class="panda/visible-mesh" material="panda/white_shell" mesh="panda/link6_main_submesh7"/>
                  <body gravcomp="1" name="panda/panda_link7" pos="0.087999999999999995 0 0" quat="0.70710700000000004 0.70710700000000004 0 0">
                    <inertial pos="0 0 0" mass="0.45000000000000001" diaginertia="0.29999999999999999 0.29999999999999999 0.29999999999999999"/>
                    <site name="panda/wrist_site" class="panda/" rgba="1 0 0 1" size="0.001" pos="0 0 0.107"/>
                    <body pos="0 0 0.107" name="panda/hand/">
                      <body gravcomp="1" name="panda/hand/base_mount" pos="0 0 0.0070000000000000001" quat="0.70699999999999996 0 0 -0.70699999999999996">
                        <geom name="panda/hand/base_mount_geom" class="panda/hand/base_mount"/>
                        <body gravcomp="1" name="panda/hand/base" pos="0 0 0.0038" quat="0.70699999999999996 0 0 -0.70699999999999996">
                          <inertial pos="0 -2.7039400000000001e-05 0.035467499999999999" quat="1 -0.00152849 0 0" mass="0.77744100000000005" diaginertia="0.00026028500000000002 0.000225381 0.00015270799999999999"/>
                          <geom name="panda/hand/base_geom" class="panda/hand/base"/>
                          <site name="panda/hand/base_top_site" class="panda/hand/" pos="0 0 0.087999999999999995"/>
                          <site name="panda/hand/pinch_site" class="panda/hand/" pos="0 0 0.145"/>
                          <body gravcomp="1" name="panda/hand/right_driver" pos="0 0.030601099999999999 0.054904000000000001">
                            <inertial pos="2.96931e-12 0.017754700000000002 0.00107314" quat="0.68130100000000005 0.73200299999999996 0 0" mass="0.0089956299999999993" diaginertia="1.72352e-06 1.6090599999999999e-06 3.22006e-07"/>
                            <joint name="panda/hand/right_driver_joint" class="panda/hand/driver"/>
                            <geom name="panda/hand/right_driver_geom" class="panda/hand/driver"/>
                            <body gravcomp="1" name="panda/hand/right_coupler" pos="0 0.0315 -0.0041000000000000003">
                              <inertial pos="0 0.0030120899999999998 0.023217499999999999" quat="0.70563600000000004 -0.045590400000000003 0.045590400000000003 0.70563600000000004" mass="0.0140974" diaginertia="4.1620600000000001e-06 3.5221600000000001e-06 8.8813100000000003e-07"/>
                              <joint name="panda/hand/right_coupler_joint" class="panda/hand/coupler"/>
                              <geom name="panda/hand/right_coupler_geom" class="panda/hand/coupler"/>
                              <geom name="panda/hand/right_coupler_CollisionGeom" class="panda/hand/" type="capsule" contype="0" conaffinity="0" group="5" size="0.014999999999999999" rgba="1 1 1 0.29999999999999999" fromto="0 0 0 0 0.0050000000000000001 0.044999999999999998"/>
                            </body>
                            <geom name="panda/hand/right_driver_CollisionGeom" class="panda/hand/" type="capsule" contype="0" conaffinity="0" group="5" size="0.014999999999999999" rgba="1 1 1 0.29999999999999999" fromto="0 0 0 0 0.027 0.0018"/>
                          </body>
                          <body gravcomp="1" name="panda/hand/right_spring_link" pos="0 0.0132 0.060900000000000003">
                            <inertial pos="-8.6500500000000008e-09 0.018162399999999999 0.021265800000000001" quat="0.66340299999999996 -0.24473700000000001 0.24473700000000001 0.66340299999999996" mass="0.022164199999999998" diaginertia="8.9685299999999993e-06 6.7173299999999996e-06 2.6393100000000001e-06"/>
                            <joint name="panda/hand/right_spring_link_joint" class="panda/hand/spring_link"/>
                            <geom name="panda/hand/right_spring_link_geom" class="panda/hand/spring_link"/>
                            <body gravcomp="1" name="panda/hand/right_follower" pos="0 0.055 0.037499999999999999">
                              <inertial pos="0 -0.011046 0.012478599999999999" quat="1 0.16639999999999999 0 0" mass="0.012522200000000001" diaginertia="2.6741500000000001e-06 2.4559000000000001e-06 6.0203100000000003e-07"/>
                              <joint name="panda/hand/right_follower_joint" class="panda/hand/follower"/>
                              <geom name="panda/hand/right_follower_geom" class="panda/hand/follower"/>
                              <body gravcomp="1" name="panda/hand/right_pad" pos="0 -0.011401 0.013015000000000001" quat="0 0 0 1">
                                <geom name="panda/hand/reinforced_right_fingertip_geom" class="panda/hand/reinforced_fingertip" type="mesh" rgba="1 1 1 1" mesh="panda/hand/reinforced_fingertip_mesh"/>
                                <geom name="panda/hand/right_pad_CollisionGeom" class="panda/hand/" type="box" contype="0" conaffinity="0" group="5" size="0.012 0.01 0.019" rgba="1 1 1 0.29999999999999999" pos="0 0.0040000000000000001 0.019"/>
                                <geom name="panda/hand/right_collision_box1" class="panda/hand/reinforced_fingertip" type="box" size="0.0070000000000000001 0.0021575000000000001 0.0050000000000000001" group="4" pos="0 0.0117 0.029999999999999999"/>
                                <geom name="panda/hand/right_collision_box2" class="panda/hand/reinforced_fingertip" type="box" size="0.0070000000000000001 0.0021575000000000001 0.0050000000000000001" group="4" pos="0 0.0117 0.014999999999999999"/>
                                <site name="touch_right" type="box" size="0.008 0.0022 0.0175" pos="0 0.0117 0.025" group="4"/>
                              </body>
                              <geom name="panda/hand/right_follower_CollisionGeom" class="panda/hand/" type="sphere" contype="0" conaffinity="0" group="5" size="0.014999999999999999" rgba="1 1 1 0.29999999999999999" pos="0 -0.01 0.0050000000000000001"/>
                            </body>
                            <geom name="panda/hand/right_spring_link_CollisionGeom" class="panda/hand/" type="capsule" contype="0" conaffinity="0" group="5" size="0.02" rgba="1 1 1 0.29999999999999999" fromto="0 0 0 0 0.031 0.035999999999999997"/>
                          </body>
                          <body gravcomp="1" name="panda/hand/left_driver" pos="0 -0.030601099999999999 0.054904000000000001" quat="0 0 0 1">
                            <inertial pos="0 0.017754700000000002 0.00107314" quat="0.68130100000000005 0.73200299999999996 0 0" mass="0.0089956299999999993" diaginertia="1.72352e-06 1.6090599999999999e-06 3.22006e-07"/>
                            <joint name="panda/hand/left_driver_joint" class="panda/hand/driver"/>
                            <geom name="panda/hand/left_driver_geom" class="panda/hand/driver"/>
                            <body gravcomp="1" name="panda/hand/left_coupler" pos="0 0.0315 -0.0041000000000000003">
                              <inertial pos="0 0.0030120899999999998 0.023217499999999999" quat="0.70563600000000004 -0.045590400000000003 0.045590400000000003 0.70563600000000004" mass="0.0140974" diaginertia="4.1620600000000001e-06 3.5221600000000001e-06 8.8813100000000003e-07"/>
                              <joint name="panda/hand/left_coupler_joint" class="panda/hand/coupler"/>
                              <geom name="panda/hand/left_coupler_geom" class="panda/hand/coupler"/>
                              <geom name="panda/hand/left_coupler_CollisionGeom" class="panda/hand/" type="capsule" contype="0" conaffinity="0" group="5" size="0.014999999999999999" rgba="1 1 1 0.29999999999999999" fromto="0 0 0 0 0.0050000000000000001 0.044999999999999998"/>
                            </body>
                            <geom name="panda/hand/left_driver_CollisionGeom" class="panda/hand/" type="capsule" contype="0" conaffinity="0" group="5" size="0.014999999999999999" rgba="1 1 1 0.29999999999999999" fromto="0 0 0 0 0.027 0.0018"/>
                          </body>
                          <body gravcomp="1" name="panda/hand/left_spring_link" pos="0 -0.0132 0.060900000000000003" quat="0 0 0 1">
                            <inertial pos="-8.6500500000000008e-09 0.018162399999999999 0.021265800000000001" quat="0.66340299999999996 -0.24473700000000001 0.24473700000000001 0.66340299999999996" mass="0.022164199999999998" diaginertia="8.9685299999999993e-06 6.7173299999999996e-06 2.6393100000000001e-06"/>
                            <joint name="panda/hand/left_spring_link_joint" class="panda/hand/spring_link"/>;
                            <geom name="panda/hand/left_spring_link_geom" class="panda/hand/spring_link"/>
                            <body gravcomp="1" name="panda/hand/left_follower" pos="0 0.055 0.037499999999999999">
                              <inertial pos="0 -0.011046 0.012478599999999999" quat="1 0.16639999999999999 0 0" mass="0.012522200000000001" diaginertia="2.6741500000000001e-06 2.4559000000000001e-06 6.0203100000000003e-07"/>
                              <joint name="panda/hand/left_follower_joint" class="panda/hand/follower"/>
                              <geom name="panda/hand/left_follower_geom" class="panda/hand/follower"/>
                              <body gravcomp="1" name="panda/hand/left_pad" pos="0 -0.011401 0.013015000000000001" quat="0 0 0 1">
                                <geom name="panda/hand/reinforced_left_fingertip_geom" class="panda/hand/reinforced_fingertip" type="mesh" rgba="1 1 1 1" mesh="panda/hand/reinforced_fingertip_mesh"/>
                                <geom name="panda/hand/left_pad_CollisionGeom" class="panda/hand/" type="box" contype="0" conaffinity="0" group="5" size="0.012 0.01 0.019" rgba="1 1 1 0.29999999999999999" pos="0 0.0040000000000000001 0.019"/>
                                <geom name="panda/hand/left_collision_box1" class="panda/hand/reinforced_fingertip" type="box" size="0.0070000000000000001 0.0021575000000000001 0.0050000000000000001" group="4" pos="0 0.0117 0.029999999999999999"/>
                                <geom name="panda/hand/left_collision_box2" class="panda/hand/reinforced_fingertip" type="box" size="0.0070000000000000001 0.0021575000000000001 0.0050000000000000001" group="4" pos="0 0.0117 0.014999999999999999"/>
                                <site name="touch_left" type="box" size="0.008 0.0022 0.0175" pos="0 0.0117 0.025" group="4"/>
                              </body>
                              <geom name="panda/hand/left_follower_CollisionGeom" class="panda/hand/" type="sphere" contype="0" conaffinity="0" group="5" size="0.014999999999999999" rgba="1 1 1 0.29999999999999999" pos="0 -0.01 0.0050000000000000001"/>
                            </body>
                            <geom name="panda/hand/left_spring_link_CollisionGeom" class="panda/hand/" type="capsule" contype="0" conaffinity="0" group="5" size="0.02" rgba="1 1 1 0.29999999999999999" fromto="0 0 0 0 0.031 0.035999999999999997"/>
                          </body>
                          <site name="eeff" class="panda/hand/" type="sphere" pos="0 0 0.145"/>
                          <geom name="panda/hand/base_CollisionGeom_1" class="panda/hand/" type="cylinder" contype="0" conaffinity="0" group="5" size="0.040000000000000001 0.024" rgba="1 1 1 0.29999999999999999" pos="0 0 0.01"/>
                          <geom name="panda/hand/base_CollisionGeom_2" class="panda/hand/" type="sphere" contype="0" conaffinity="0" group="5" size="0.044999999999999998" rgba="1 1 1 0.29999999999999999" pos="0 0 0.050000000000000003"/>
                        </body>
                      </body>
                    </body>
<!--                     <body pos="0 0 0.107" name="panda/wrist_back/">
                      <body gravcomp="1" name="panda/wrist_back/prop_root" pos="0 0 0" euler="0 0 1.5707963267948966">
                        <inertial pos="0 0 0" mass="0.0001" diaginertia="0 0 0"/>
                        <body gravcomp="1" name="panda/wrist_back/camera_mount" pos="0 0 0.0070000000000000001">
                          <inertial pos="0 0 0" mass="0.001" diaginertia="0.001 0.001 0.001"/>
                          <geom name="panda/wrist_back//unnamed_geom_0" class="panda/wrist_back/" type="mesh" group="1" rgba="0.20000000000000001 0.20000000000000001 0.20000000000000001 1" mesh="panda/wrist_back/camera_mount"/>
                        </body>
                        <body gravcomp="1" name="panda/wrist_back/camera_root" pos="0 0.082600000000000007 0.051999999999999998" euler="-2.7576202181510405 0 3.1415926535897931">
                          <camera name="panda/wrist_back/camera_elem" class="panda/wrist_back/" fovy="45" pos="0 -0.032000000000000001 0" euler="0 0 0"/>
                        </body>
                      </body>
                    </body>
                    <body pos="0 0 0.107" name="panda/wrist_front/">
                      <body gravcomp="1" name="panda/wrist_front/prop_root" pos="0 0 0" euler="0 0 4.7123889803846897">
                        <inertial pos="0 0 0" mass="0.0001" diaginertia="0 0 0"/>
                        <body gravcomp="1" name="panda/wrist_front/camera_mount" pos="0 0 0.0070000000000000001">
                          <inertial pos="0 0 0" mass="0.001" diaginertia="0.001 0.001 0.001"/>
                          <geom name="panda/wrist_front//unnamed_geom_0" class="panda/wrist_front/" type="mesh" group="1" rgba="0.20000000000000001 0.20000000000000001 0.20000000000000001 1" mesh="panda/wrist_front/camera_mount"/>
                        </body>
                        <body gravcomp="1" name="panda/wrist_front/camera_root" pos="0 0.082600000000000007 0.051999999999999998" euler="-2.7576202181510405 0 3.1415926535897931">
                          <camera name="panda/wrist_front/camera_elem" class="panda/wrist_front/" fovy="45" pos="0 -0.032000000000000001 0" euler="0 0 0"/>
                        </body>
                      </body>
                    </body> -->
                    <site name="panda/j7_site" class="panda/torque-sensor"/>
                    <joint name="panda/panda_joint7" class="panda/" axis="0 0 1" limited="false" range="-2.8973 2.8973" damping="5"/> damping="20"
                    <geom name="panda//unnamed_geom_74" class="panda/collision-mesh" mesh="panda/link7"/>
                    <geom name="panda//unnamed_geom_75" class="panda/visible-mesh" material="panda/joint_housing" mesh="panda/link7_button0"/>
                    <geom name="panda//unnamed_geom_76" class="panda/visible-mesh" material="panda/joint_housing" mesh="panda/link7_button1"/>
                    <geom name="panda//unnamed_geom_77" class="panda/visible-mesh" material="panda/white_shell" mesh="panda/link7_handle0"/>
                    <geom name="panda//unnamed_geom_78" class="panda/visible-mesh" material="panda/white_shell" mesh="panda/link7_handle1"/>
                    <geom name="panda//unnamed_geom_79" class="panda/visible-mesh" material="panda/white_shell" mesh="panda/link7_main_submesh0"/>
                    <geom name="panda//unnamed_geom_80" class="panda/visible-mesh" material="panda/white_shell" mesh="panda/link7_main_submesh1"/>
                    <geom name="panda//unnamed_geom_81" class="panda/visible-mesh" material="panda/white_shell" mesh="panda/link7_main_submesh2"/>
                    <geom name="panda//unnamed_geom_82" class="panda/visible-mesh" material="panda/white_shell" mesh="panda/link7_main_submesh3"/>
                    <geom name="panda/panda_link7_CollisionGeom_1" class="panda/" type="cylinder" contype="0" conaffinity="0" group="5" size="0.070000000000000007" rgba="1 1 1 0.29999999999999999" fromto="0.016 0.016 0.050000000000000003 0.016 0.016 0.108"/>
                  </body>
                  <geom name="panda/panda_link6_CollisionGeom_1" class="panda/" type="capsule" contype="0" conaffinity="0" group="5" size="0.065000000000000002" rgba="1 1 1 0.29999999999999999" fromto="0 0 0.01 0.080000000000000002 0.029999999999999999 0"/>
                  <geom name="panda/panda_link6_CollisionGeom_2" class="panda/" type="cylinder" contype="0" conaffinity="0" group="5" size="0.050000000000000003" rgba="1 1 1 0.29999999999999999" fromto="0.089999999999999997 -0.053999999999999999 0.0030000000000000001 0.089999999999999997 0 0.0030000000000000001"/>
                </body>
                <geom name="panda/panda_link5_CollisionGeom_1" class="panda/" type="cylinder" contype="0" conaffinity="0" group="5" size="0.059999999999999998" rgba="1 1 1 0.29999999999999999" fromto="0 0 -0.26200000000000001 0 0 -0.16"/>
                <geom name="panda/panda_link5_CollisionGeom_2" class="panda/" type="capsule" contype="0" conaffinity="0" group="5" size="0.050000000000000003" rgba="1 1 1 0.29999999999999999" fromto="0 0.040000000000000001 -0.22 0 0.10000000000000001 0"/>
                <geom name="panda/panda_link5_CollisionGeom_3" class="panda/" type="cylinder" contype="0" conaffinity="0" group="5" size="0.056000000000000001" rgba="1 1 1 0.29999999999999999" fromto="0 0.014 0 0 0.124 0"/>
              </body>
              <geom name="panda/panda_link4_CollisionGeom_1" class="panda/" type="cylinder" contype="0" conaffinity="0" group="5" size="0.059999999999999998" rgba="1 1 1 0.29999999999999999" fromto="0 0 -0.002 0 0 0.070000000000000007"/>
              <geom name="panda/panda_link4_CollisionGeom_2" class="panda/" type="capsule" contype="0" conaffinity="0" group="5" size="0.059999999999999998" rgba="1 1 1 0.29999999999999999" fromto="0 0 0.059999999999999998 -0.080000000000000002 0.059999999999999998 0"/>
              <geom name="panda/panda_link4_CollisionGeom_3" class="panda/" type="cylinder" contype="0" conaffinity="0" group="5" size="0.059999999999999998" rgba="1 1 1 0.29999999999999999" fromto="-0.080000000000000002 0.059999999999999998 0 -0.080000000000000002 0.127 0"/>
            </body>
            <geom name="panda/panda_link3_CollisionGeom_1" class="panda/" type="cylinder" contype="0" conaffinity="0" group="5" size="0.059999999999999998" rgba="1 1 1 0.29999999999999999" fromto="0 0 -0.123 0 0 -0.040000000000000001"/>
            <geom name="panda/panda_link3_CollisionGeom_2" class="panda/" type="capsule" contype="0" conaffinity="0" group="5" size="0.059999999999999998" rgba="1 1 1 0.29999999999999999" fromto="0 0 -0.070000000000000007 0.085000000000000006 0.058000000000000003 0"/>
            <geom name="panda/panda_link3_CollisionGeom_3" class="panda/" type="cylinder" contype="0" conaffinity="0" group="5" size="0.059999999999999998" rgba="1 1 1 0.29999999999999999" fromto="0.080000000000000002 0 0 0.080000000000000002 0.070000000000000007 0"/>
          </body>
          <geom name="panda/panda_link2_CollisionGeom_1" class="panda/" type="cylinder" contype="0" conaffinity="0" group="5" size="0.059999999999999998" rgba="1 1 1 0.29999999999999999" fromto="0 0 0 0 0 0.10000000000000001"/>
          <geom name="panda/panda_link2_CollisionGeom_2" class="panda/" type="capsule" contype="0" conaffinity="0" group="5" size="0.059999999999999998" rgba="1 1 1 0.29999999999999999" fromto="0 0 0.080000000000000002 0 -0.12 0.0050000000000000001"/>
          <geom name="panda/panda_link2_CollisionGeom_3" class="panda/" type="cylinder" contype="0" conaffinity="0" group="5" size="0.059999999999999998" rgba="1 1 1 0.29999999999999999" fromto="0 -0.12 0 0 -0.19500000000000001 0"/>
        </body>
        <geom name="panda/panda_link1_CollisionGeom_1" class="panda/" type="cylinder" contype="0" conaffinity="0" group="5" size="0.059999999999999998" rgba="1 1 1 0.29999999999999999" fromto="0 0 -0.193 0 0 -0.13"/>
        <geom name="panda/panda_link1_CollisionGeom_2" class="panda/" type="capsule" contype="0" conaffinity="0" group="5" size="0.059999999999999998" rgba="1 1 1 0.29999999999999999" fromto="0 0 -0.13 0 -0.080000000000000002 0"/>
        <geom name="panda/panda_link1_CollisionGeom_3" class="panda/" type="cylinder" contype="0" conaffinity="0" group="5" size="0.059999999999999998" rgba="1 1 1 0.29999999999999999" fromto="0 -0.080000000000000002 0 0 0 0"/>
      </body>
      <geom name="panda/worldbody_CollisionGeom" class="panda/" type="cylinder" contype="0" conaffinity="0" group="5" size="0.12" rgba="1 1 1 0.29999999999999999" fromto="-0.040000000000000001 0 0 -0.040000000000000001 0 0.14000000000000001"/>
    </body>
  </worldbody>
  <equality>
    <connect name="panda/hand//unnamed_equality_0" class="panda/hand/" solref="0.0050000000000000001 1" solimp="0.94999999999999996 0.98999999999999999 0.001" body1="panda/hand/right_follower" body2="panda/hand/right_coupler" anchor="0 0 0"/>
    <connect name="panda/hand//unnamed_equality_1" class="panda/hand/" solref="0.0050000000000000001 1" solimp="0.94999999999999996 0.98999999999999999 0.001" body1="panda/hand/left_follower" body2="panda/hand/left_coupler" anchor="0 0 0"/>
    <joint name="panda/hand//unnamed_equality_2" class="panda/hand/" solref="0.0050000000000000001 1" solimp="0.94999999999999996 0.98999999999999999 0.001" joint1="panda/hand/right_driver_joint" joint2="panda/hand/left_driver_joint" polycoef="0 1 0 0 0"/>
  </equality>
  <tendon>
    <fixed name="panda/hand/split" class="panda/hand/">
      <joint joint="panda/hand/right_driver_joint" coef="0.5"/>
      <joint joint="panda/hand/left_driver_joint" coef="0.5"/>
    </fixed>
  </tendon>
  <actuator>
    <general  name="x" site="eeff" refsite="BASKET" ctrlrange="-.3 .3" ctrllimited="true" gainprm="1000" biasprm="0 -1000 -200" biastype="affine" gear="1 0 0 0 0 0"/>
    <general  name="y" site="eeff" refsite="BASKET" ctrlrange="-.3 .3" ctrllimited="true" gainprm="1000" biasprm="0 -1000 -200" biastype="affine" gear="0 1 0 0 0 0"/>
    <general  name="z" site="eeff" refsite="BASKET" ctrlrange="-.5 .3" ctrllimited="true" gainprm="1000" biasprm="450 -1000 -200" biastype="affine" gear="0 0 1 0 0 0"/>
    <general name="rx" site="eeff" refsite="world" ctrlrange="-.5 .5" ctrllimited="true" gainprm="100" biasprm="0 -100 -20" biastype="affine"  gear="0 0 0 1 0 0"/>
    <general name="ry" site="eeff" refsite="world" ctrlrange="-.5 .5" ctrllimited="true" gainprm="100" biasprm="0 -100 -20" biastype="affine"  gear="0 0 0 0 1 0"/>
    <general  name="rz" joint="panda/panda_joint7" ctrlrange="-1 1" ctrllimited="true" gainprm="10"/>
    <position name="fingers" ctrllimited="true" forcelimited="true" ctrlrange="0 1" forcerange="-5 5" kp="40" tendon="panda/hand/split"/>
  </actuator>
</mujoco>
