<mujoco model="iiwa14">
  <worldbody>
    <body name="base_right" pos="-0.6 0 0" childclass="iiwa">
      <inertial mass="5" pos="-0.1 0 0.07" diaginertia="0.05 0.06 0.03"/>
      <geom class="visual" mesh="link_0"/>
      <geom class="collision" size="0.12" pos="0 0 0.03"/>
      <geom class="collision" size="0.08" pos="-0.08 0 0.103"/>
      <geom class="collision" size="0.08" pos="-0.08 0 0.04"/>
      <geom class="collision" size="0.1" pos="0 0 0.14"/>
      <body name="link1_right" pos="0 0 0.1575">
        <inertial mass="5.76" pos="0 -0.03 0.12" diaginertia="0.0333 0.033 0.0123"/>
        <joint name="joint1_right" class="joint1_free"/>
        <geom class="visual" mesh="link_1"/>
        <geom class="collision" size="0.08" pos="0 0 -0.0005"/>
        <geom class="collision" size="0.075" pos="0.01 -0.025 0.0425"/>
        <geom class="collision" size="0.075" pos="-0.01 -0.025 0.0425"/>
        <geom class="collision" size="0.07" pos="0.01 -0.045 0.1025"/>
        <geom class="collision" size="0.07" pos="-0.01 -0.045 0.1025"/>
        <body name="link2_right" pos="0 0 0.2025" quat="0 0 1 1">
          <inertial mass="6.35" pos="0.0003 0.059 0.042" diaginertia="0.0305 0.0304 0.011" quat="0 0 1 1"/>
          <joint name="joint2_right" class="joint2"/>
          <geom class="visual" material="orange" mesh="link_2_orange"/>
          <geom class="visual" mesh="link_2_grey"/>
          <geom class="collision" size="0.095" pos="0 0 -0.01"/>
          <geom class="collision" size="0.09" pos="0 0 0.045"/>
          <geom class="collision" size="0.07" pos="-0.01 0.04 0.054"/>
          <geom class="collision" size="0.065" pos="-0.01 0.09 0.04"/>
          <geom class="collision" size="0.065" pos="-0.01 0.13 0.02"/>
          <geom class="collision" size="0.07" pos="0.01 0.04 0.054"/>
          <geom class="collision" size="0.065" pos="0.01 0.09 0.04"/>
          <geom class="collision" size="0.065" pos="0.01 0.13 0.02"/>
          <geom class="collision" size="0.075" pos="0 0.18 0"/>
          <body name="link3_right" pos="0 0.2045 0" quat="0 0 1 1">
            <inertial mass="3.5" pos="0 0.03 0.13" diaginertia="0.025 0.0238 0.0076"/>
            <joint name="joint3_right" class="joint1"/>
            <geom class="visual" mesh="link_3"/>
            <geom class="visual" material="light_gray" mesh="band"/>
            <geom class="visual" material="black" mesh="kuka"/>
            <geom class="collision" size="0.075" pos="0 0 0.0355"/>
            <geom class="collision" size="0.06" pos="0.01 0.023 0.0855"/>
            <geom class="collision" size="0.055" pos="0.01 0.048 0.1255"/>
            <geom class="collision" size="0.06" pos="0.01 0.056 0.1755"/>
            <geom class="collision" size="0.06" pos="-0.01 0.023 0.0855"/>
            <geom class="collision" size="0.055" pos="-0.01 0.048 0.1255"/>
            <geom class="collision" size="0.06" pos="-0.01 0.056 0.1755"/>
            <geom class="collision" size="0.075" pos="0 0.045 0.2155"/>
            <geom class="collision" size="0.075" pos="0 0 0.2155"/>
            <body name="link4_right" pos="0 0 0.2155" quat="1 1 0 0">
              <inertial mass="3.5" pos="0 0.067 0.034" diaginertia="0.017 0.0164 0.006" quat="1 1 0 0"/>
              <joint name="joint4_right" class="joint2"/>
              <geom class="visual" material="orange" mesh="link_4_orange"/>
              <geom class="visual" mesh="link_4_grey"/>
              <geom class="collision" size="0.078" pos="0 0.01 0.046"/>
              <geom class="collision" size="0.06" pos="0.01 0.06 0.052"/>
              <geom class="collision" size="0.065" pos="0.01 0.12 0.034"/>
              <geom class="collision" size="0.06" pos="-0.01 0.06 0.052"/>
              <geom class="collision" size="0.065" pos="-0.01 0.12 0.034"/>
              <geom class="collision" size="0.075" pos="0 0.184 0"/>
              <body name="link5_right" pos="0 0.1845 0" quat="0 0 1 1">
                <inertial mass="3.5" pos="0.0001 0.021 0.076" diaginertia="0.01 0.0087 0.00449"/>
                <joint name="joint5_right" class="joint1"/>
                <geom class="visual" mesh="link_5"/>
                <geom class="visual" material="light_gray" mesh="band"/>
                <geom class="visual" material="black" mesh="kuka"/>
                <geom class="collision" size="0.075" pos="0 0 0.0335"/>
                <geom class="collision" size="0.05" pos="-0.012 0.031 0.0755"/>
                <geom class="collision" size="0.05" pos="0.012 0.031 0.0755"/>
                <geom class="collision" size="0.04" pos="-0.012 0.06 0.1155"/>
                <geom class="collision" size="0.04" pos="0.012 0.06 0.1155"/>
                <geom class="collision" size="0.04" pos="-0.01 0.065 0.1655"/>
                <geom class="collision" size="0.04" pos="0.01 0.065 0.1655"/>
                <geom class="collision" size="0.035" pos="-0.012 0.065 0.1855"/>
                <geom class="collision" size="0.035" pos="0.012 0.065 0.1855"/>
                <body name="link6_right" pos="0 0 0.2155" quat="1 1 0 0">
                  <inertial mass="1.8" pos="0 0.0006 0.0004" diaginertia="0.0049 0.0047 0.0036" quat="1 1 0 0"/>
                  <joint name="joint6_right" class="joint2"/>
                  <geom class="visual" material="orange" mesh="link_6_orange"/>
                  <geom class="visual" mesh="link_6_grey"/>
                  <geom class="collision" size="0.055" pos="0 0 -0.059"/>
                  <geom class="collision" size="0.065" pos="0 -0.03 0.011"/>
                  <geom class="collision" size="0.08"/>
                  <body name="link7_right" pos="0 0.081 0" quat="0 0 1 1">
                    <inertial mass="1.2" pos="0 0 0.02" diaginertia="0.001 0.001 0.001"/>
                    <joint name="joint7_right" class="joint3"/>
                    <geom class="visual" mesh="link_7"/>
                    <geom class="collision" size="0.06" pos="0 0 0.001"/>
                    <site pos="0 0 0.045" name="attachment_site_right"/>
                  </body>
                </body>
              </body>
            </body>
          </body>
        </body>
      </body>
    </body>
  </worldbody>

  <contact>
    <exclude body1="base_right" body2="link1_right"/>
  </contact>

  <actuator>
    <general name="actuator1_right" joint="joint1_right" class="joint1"/>
    <general name="actuator2_right" joint="joint2_right" class="joint2"/>
    <general name="actuator3_right" joint="joint3_right" class="joint1"/>
    <general name="actuator4_right" joint="joint4_right" class="joint2"/>
    <general name="actuator5_right" joint="joint5_right" class="joint1"/>
    <general name="actuator6_right" joint="joint6_right" class="joint2"/>
    <general name="actuator7_right" joint="joint7_right" class="joint3"/>
  </actuator>
</mujoco>
