<mujoco model="aloha">
  <include file="../../common.xml"/>

  <size memory="1M"/>

  <asset>
    <texture name="groundplane" type="2d" builtin="flat" rgb1="0.20000000000000001 0.29999999999999999 0.40000000000000002" rgb2="0.10000000000000001 0.20000000000000001 0.29999999999999999" mark="edge" markrgb="0.50000000000000004 0.50000000000000004 0.50000000000000004" width="200" height="200"/>
    <material name="groundplane" texture="groundplane" texrepeat="2 2" texuniform="true" reflectance="0.20000000000000001"/>
  </asset>

  <custom>
    <numeric name="agent_planner" data="0" />
    <numeric name="agent_horizon" data="0.4" />
    <numeric name="agent_timestep" data="0.01" />
    <numeric name="agent_sample_width" data="0.0025" />
    <numeric name="agent_policy_width" data="0.0035" />
    <numeric name="sampling_exploration" data="0.05 0.3" />
    <numeric name="sampling_trajectories" data="120"/>
    <numeric name="sampling_spline_points" data="4" />
    <numeric name="sampling_representation" data="1" />
    <numeric name="sampling_sliding_plan" data="1" />
  </custom>

  <statistic extent=".5" center="0.1 0 0.15" meansize="0.03"/>


  <option timestep="0.01"/>

  <visual>
    <quality shadowsize="8192"/>
    <global azimuth="80" elevation="-10" realtime="0.33"/>
  </visual>

  <!-- since the included reorientation_cube brings its own sensors, the residuals must be specified first -->
  <sensor>
    <user name="Reach L" dim="3" user="1 .1 0 .5 .05 4"/>
    <user name="Reach R" dim="3" user="1 .1 0 .5 .05 4"/>
    <user name="Grasp L" dim="1" user="-1 .05 0 .5"/>
    <user name="Grasp R" dim="1" user="-1 .05 0 .5"/>
    <user name="Bring" dim="18"  user="2 1 0 5 0.01"/>
    <framepos name="left/gripper" objtype="body" objname="cross" reftype="site" refname="left/gripper"/>
    <framepos name="right/gripper" objtype="body" objname="cross" reftype="site" refname="right/gripper"/>
    <framepos name="object_pos" objtype="xbody" objname="cross"/>
    <framepos name="target_pos" objtype="xbody" objname="target_pos"/>
    <framepos name="trace0" objtype="body" objname="cross"/>
    <framepos name="trace1" objtype="site" objname="left/gripper"/>
    <framepos name="trace2" objtype="site" objname="right/gripper"/>
  </sensor>

  <include file="../aloha_cartesian.xml"/>
  <include file="../../common_assets/reorientation_cross.xml"/>

  <default>
    <default class="target">
      <geom group="1" contype="0" conaffinity="0"/>
    </default>
  </default>

  <worldbody>
    <light pos="0 -0.1 0.5" dir="0 0.2 -1" diffuse="0.7 0.7 0.7" specular="0.3 0.3 0.3"
        directional="true" castshadow="true"/>
    <geom name="floor" pos="0 0 -0.75" size="0 0 0.05" type="plane" material="groundplane"/>
    <body name="table" pos="0 0 -0.75">
      <geom name="table" pos="0 0 0.6509" size="0.61 0.37 0.1" type="box" class="collision"/>
      <geom name="table_visual" pos="0 0 0.6509" size="0.61 0.37 0.1" type="box" rgba="0.4 0.4 0.4 1" conaffinity="0" contype="0"/>
    </body>
    <body mocap="true" name="target_pos">
      <geom class="target" size="0.02" rgba="1 0.4 0.4 1"/>
    </body>
    <body name="target_orient" pos="0.1 -.2 0.1" gravcomp="1">
      <joint name="target_orient" type="ball" damping="0.001"/>
      <geom class="target" type="capsule" size=".015" fromto="-.02 0 0 .06 0 0" mass=".04" rgba="1 .2 .2 1"/>
      <geom class="target" type="capsule" size=".015" fromto="0 -.02 0 0 .06 0" mass=".04" rgba=".2 1 .2 1"/>
      <geom class="target" type="capsule" size=".015" fromto="0 0 -.02 0 0 .06" mass=".04" rgba=".2 .2 1 1"/>
    </body>
  </worldbody>
  <keyframe>
    <key name="home" qpos="
    0 -0.96 1.16 0 -0.3 0 0.02 0.02
    0 -0.96 1.16 0 -0.3 0 0.02 0.02
    0 0 0.3 1 1 1 1
    1 0 0 0
    "
    mpos="0 0 0.25"
    act= "-0.1 0 0 0 0 0 0.03 0.1 0 0 0 0 0 0.03"
    ctrl="-0.1 0 0 0 0 0 0.03 0.1 0 0 0 0 0 0.03"/>
  </keyframe>

  <default>
    <default class="grasp">
      <geom type="sphere" size="0.0006" rgba="1 0 0 1" condim="6" friction="1 5e-3 5e-4" solref=".01 1" margin=".01" gap=".01" group="3"/>
    </default>
  </default>
</mujoco>
