<mujocoinclude>
<!-- =================================================
    Copyright 2019 Vikash Kumar 
    Model   :: study table (MuJoCoV2.0)
    Author  :: Vikash Kumar (vikashplus@gmail.com), Michael Wu (michael50wu@gmail.com)
    Details :: https://github.com/vikashplus/furniture_sim
    License :: Under Apache License, Version 2.0 (the "License"); you may not use this file except in compliance with the License. You may obtain a copy of the License at http://www.apache.org/licenses/LICENSE-2.0 Unless required by applicable law or agreed to in writing, software distributed under the License is distributed on an "AS IS" BASIS, WITHOUT WARRANTIES OR CONDITIONS OF ANY KIND, either express or implied. See the License for the specific language governing permissions and limitations under the License.
====================================================== -©vk©-->

    <!-- studyTable_Main -©vk©-->
    <body name="studyTable_Main" pos="0 0 0"  childclass="body_studyTable" >
        <geom class="viz_stl_Wood_studyTable" type="mesh" mesh="studyTable_Main" euler="-1.57 0 3.14"/>
        <geom type="box" size=".6 .275 .025" pos="0 0 0.735" rgba="0.8 0.9 0.7 1.0" mass="40" />
        <geom type="box" size="0.17 0.26 .05" pos="0.42 0 0.66" rgba="0.8 0.9 0.7 1.0" />
        <geom type="box" size="0.17 0.26 .05" pos="-0.42 0 0.66" rgba="0.8 0.9 0.7 1.0" />
        <geom type="box" size="0.025 0.025 0.305" pos="-0.565 0.235 0.305" rgba="0.8 0.9 0.7 1.0" />
        <geom type="box" size="0.025 0.025 0.305" pos="-0.565 -0.235 0.305" rgba="0.8 0.9 0.7 1.0" />
        <geom type="box" size="0.025 0.025 0.305" pos="0.565 0.235 0.305" rgba="0.8 0.9 0.7 1.0" />
        <geom type="box" size="0.025 0.025 0.305" pos="0.565 -0.235 0.305" rgba="0.8 0.9 0.7 1.0" />
        <geom type="box" size="0.6 0.01 0.175" pos="0 0.265 0.935" rgba="0.8 0.9 0.7 1.0" />
        <geom type="box" size="0.6 0.11 0.01" pos="0 0.165 1.1" rgba="0.8 0.9 0.7 1.0" />
        <geom type="box" size="0.01 0.11 0.175" pos="0.59 .165 .935" rgba="0.8 0.9 0.7 1.0" />
        <geom type="box" size="0.01 0.11 0.175" pos="-0.59 .165 .935" rgba="0.8 0.9 0.7 1.0" />
        <geom type="box" size="0.01 0.11 0.175" pos="0 .165 .935" rgba="0.8 0.9 0.7 1.0"/>
    </body>

     <!-- StudyTable_Drawer -©vk©-->
    <body name="studyTable_Drawer" pos="0 0 0.655" childclass="drawer_studyTable" >
        <geom class="viz_stl_Wood_studyTable" type="mesh" mesh="studyTable_Drawer_Wood" euler="-1.57 0 3.14"/>
        <geom class="viz_stl_Metal_studyTable" type="mesh" mesh="studyTable_Drawer_Handle" euler="-1.57 0 3.14"/>
        <geom type="box" size=".24 .26 .01" pos="0 0 -0.04" rgba="0.8 0.9 0.7 1.0" mass="2" />
        <geom type="box" size=".24 .01 .05" pos="0 .25 0" rgba="0.8 0.9 0.7 1.0" />
        <geom type="box" size=".24 .01 .05" pos="0 -.25 0" rgba="0.8 0.9 0.7 1.0" />
        <geom type="box" size=".01 .26 .05" pos="-.23 0 0" rgba="0.8 0.9 0.7 1.0" />
        <geom type="box" size=".01 .26 .05" pos=".23 0 0" rgba="0.8 0.9 0.7 1.0" />
        <geom type="capsule" size=".014 .045" pos=".08203 -.315 .01" euler="1.57 0 0" rgba="0.8 0.9 0.7 1.0" />
        <geom type="capsule" size=".014 .045" pos="-.08203 -.315 .01" euler="1.57 0 0" rgba="0.8 0.9 0.7 1.0" />
        <geom type="capsule" size=".014 .08" pos="0 -.36 .01" euler="0 1.57 0" rgba="0.8 0.9 0.7 1.0" />
        <joint name="studyTable_Drawer_Joint" type="slide" pos="0 0 0" axis="0 1 0" limited="true" range="-0.48 0" />
    </body>

    <!-- StudyTable_Slide -©vk©-->
    <body name="studyTable_Slide" pos="-0.3 0.04 0.935" childclass="drawer_studyTable" >
        <geom class="viz_stl_Wood_studyTable" type="mesh" mesh="studyTable_Slide_Wood" euler="-1.57 0 3.14"/>
        <geom class="viz_stl_Metal_studyTable" type="mesh" mesh="studyTable_Slide_Handle" euler="-1.57 0 3.14"/>
        <geom type="box" size=".3 .01 .175" pos="0 0 0" rgba="0.8 0.9 0.7 1.0" mass="1" />
        <geom type="capsule" size=".014 .042" pos="0 -.065 .08302" euler="1.57 0 0" rgba="0.8 0.9 0.7 1.0" />
        <geom type="capsule" size=".014 .042" pos="0 -.065 -.08302" euler="1.57 0 0" rgba="0.8 0.9 0.7 1.0" />
        <geom type="capsule" size=".014 .08" pos="0 -.11 0" euler="0 0 0" rgba="0.8 0.9 0.7 1.0" />
        <site name='slide_handle' type='sphere' size='.01' pos='0 -.11 0'/>
        <joint name="studyTable_Slide_Joint" type="slide" pos="0 0 0" axis="1 0 0" limited="true" range="0 .6" />
    </body>

</mujocoinclude>
