<mujocoinclude>
    <asset>
        <material name="wooden_cover"  texuniform="false"  texture="wooden_cover"/>
        <texture type="2d" name="wooden_cover" file="../assets/dark-wood.png"/>

        <material name="metal_cover"  texuniform="false"  texture="metal_cover"/>
        <texture type="2d" name="metal_cover" file="../assets/metal.png"/>
    </asset>
    <worldbody>
        <body name="door" pos="0.8 0 0">
            <joint name="door_hinge" pos="-0.05 -0.5 1" axis="0 0 1" limited="true" range="0 1.4" stiffness="50"/>
            <geom name="door_body" type="box" rgba="0.8 0.8 0.83 1" pos="0 0 1" size="0.07 0.48 0.99" material="wooden_cover" density="600" class="visual"/>
            <geom type="box" pos="0 0 1" size="0.07 0.48 0.99" class="collision"/>

            <body name="door_hatch" pos="0 0.4 1.2" gravcomp='1'>
                <joint name="door_hatch_hinge" pos="0 0 0" axis="1 0 0" limited="true" range="0 2" stiffness="2" />
                <geom name="door_hatch_axis_in" pos="-0.12 0 0" size="0.05 0.05" zaxis="1 0 0" type="cylinder" material="metal_cover" class="visual"/>
                <geom name="door_hatch_axis_out" pos="0.12 0 0" size="0.05 0.05" zaxis="1 0 0" type="cylinder" material="metal_cover" class="visual"/>
                <geom name="door_hatch_inside" pos="-0.141 -0.1 0" size="0.02 0.1" zaxis="0 1 0" type="cylinder" material="metal_cover" class="visual"/>
                <geom name="door_hatch_outside" pos="0.141 -0.1 0" size="0.02 0.1" zaxis="0 1 0" type="cylinder" material="metal_cover" class="visual"/>
                <geom name="door_lock" pos="0.15 0.07 0" size="0.01 0.07" zaxis="0 1 0" type="cylinder" material="metal_cover" class="visual"/>
                <geom name="door_lock_internal" pos="-0.15 0.07 0" size="0.01 0.07" zaxis="0 1 0" type="cylinder" material="metal_cover" class="visual"/>


                <geom type="cylinder" pos="-0.12 0 0" size="0.05 0.05" zaxis="1 0 0" class="collision"/>
                <geom type="cylinder" pos="0.12 0 0" size="0.05 0.05" zaxis="1 0 0" class="collision"/>
                <geom type="cylinder" pos="-0.141 -0.1 0" size="0.02 0.1" zaxis="0 1 0" class="collision"/>
                <geom type="cylinder" pos="0.141 -0.1 0" size="0.02 0.1" zaxis="0 1 0" class="collision"/>
                <geom type="cylinder" pos="0.15 0.07 0" size="0.01 0.07" zaxis="0 1 0" class="collision"/>
                <geom type="cylinder" pos="-0.15 0.07 0" size="0.01 0.07" zaxis="0 1 0" class="collision"/>
            </body>
        </body>
        <body name="door_wall_connects" pos="0.8 0 0">
            <geom name="wall_door_connect_a" type="box" pos="0 0.66 1" size="0.12 0.14 1" rgba="0.5 0.5 0.5 0.3" class="visual"/>
            <geom name="wall_door_connect_b" type="box" pos="0 -0.66 1" size="0.12 0.14 1" rgba="0.5 0.5 0.5 0.3" class="visual"/>
            <geom name="ceiling_door_connect" type="box" pos="0 0 2.19" size="0.12 0.82 0.19" rgba="0.5 0.5 0.5 0.3" class="visual"/>

            <geom type="box" pos="0 0.66 1" size="0.12 0.14 1" class="collision"/>
            <geom type="box" pos="0 -0.66 1" size="0.12 0.14 1" class="collision"/>
            <geom type="box" pos="0 0 2.19" size="0.12 0.82 0.19" class="collision"/>

            <geom name="left_wall"   type="box" pos="-1.31 -0.7 1.19" size="1.19 0.12 1.19" rgba="0.8 0.8 0.83 0.3" class="visual"/>
            <geom name="right_wall"  type="box" pos="-1.31 0.7 1.19"  size="1.19 0.12 1.19" rgba="0.8 0.8 0.83 0.3" class="visual"/>
            <geom name="behind_wall" type="box" pos="-2.35 0 1.19"    size="0.15 0.58 1.19" rgba="0.8 0.8 0.83 0.3" class="visual"/>

            <geom type="box" pos="-1.31 -0.7 1.19" size="1.19 0.12 1.19" class="collision"/>
            <geom type="box" pos="-1.31 0.7 1.19"  size="1.19 0.12 1.19" class="collision"/>
            <geom type="box" pos="-2.35 0 1.19"    size="0.15 0.58 1.19" class="collision"/>
        </body>
    </worldbody>
</mujocoinclude>
