<mujoco model="leap_hand">
  <!-- 
    This model was generated with the following steps:
      - Downloaded leap_hand_right.urdf from https://github.com/dexsuite/dex-urdf
      - Fixed urdf inertias using Drake's `fix_inertia` tool
      - Converted urdf to mjcf
          - added <mujoco><compiler assetdir="./meshes/" discardvisual="false"/></mujoco> tags to urdf
          - opened urdf in mujoco and clicked "save xml"
      - Set options like cone="elliptic", frictionloss="0.05", etc from the old xml
      - Changed visual goems to group 2 and collision geoms to group 3 (was 0 and 1)
      - Add visual geoms for the fingertips
      - Set colors (black for everything except the fingertips
      - Add position actuators for all joints
      - Add sensors to make traces of the fingertips
      - Change the initial orientation of the palm
  -->

  <compiler angle="radian" meshdir="./meshes/" />
  <option cone="elliptic" impratio="10" />
  <asset>
    <material name="black" rgba="0.2 0.2 0.2 1" />
    <material name="white" rgba="0.9 0.9 0.9 1" />
    <mesh name="leap_mount" file="leap_mount.obj" />
    <mesh name="palm_lower" file="palm_lower.obj" />
    <mesh name="mcp_joint" file="mcp_joint.obj" />
    <mesh name="pip" file="pip.obj" />
    <mesh name="dip" file="dip.obj" />
    <mesh name="fingertip" file="fingertip.obj" />
    <mesh name="white_tip" file="white_tip.obj" />
    <mesh name="thumb_pip" file="thumb_pip.obj" />
    <mesh name="thumb_dip" file="thumb_dip.obj" />
    <mesh name="thumb_fingertip" file="thumb_fingertip.obj" />
    <mesh name="white_tip_thumb" file="white_tip_thumb.obj" />
  </asset>
  <default>
    <position kp="0.25" kv="0.005" />
    <joint damping="0.01" />
    <default class="visual">
      <geom group="2" type="mesh" contype="0" conaffinity="0" density="0" material="black" />
    </default>
    <default class="collision">
      <geom group="3" type="box" mass="0" />
    </default>

    <default class="mcp_joint">
      <joint pos="0 0 0" axis="0 0 -1"
        limited="true" range="-0.314 2.23" />
      <position ctrlrange="-0.314 2.23" />
    </default>
    <default class="pip">
      <joint pos="0 0 0" axis="0 0 -1"
        limited="true" range="-1.047 1.047" />
      <position ctrlrange="-1.047 1.047" />
    </default>
    <default class="dip">
      <joint pos="0 0 0" axis="0 0 -1"
        limited="true" range="-0.506 1.885" />
      <position ctrlrange="-0.506 1.885" />
    </default>
    <default class="fingertip">
      <joint pos="0 0 0" axis="0 0 -1"
        limited="true" range="-0.366 2.042" />
      <position ctrlrange="-0.366 2.042" />
    </default>
    <default class="thumb_base_pip">
      <joint pos="0 0 0" axis="0 0 -1"
        limited="true" range="-0.349 2.094" />
      <position ctrlrange="-0.349 2.094" />
    </default>
    <default class="thumb_pip">
      <joint pos="0 0 0" axis="0 0 -1"
        limited="true" range="-0.349 2.094" />
      <position ctrlrange="-0.349 2.094" />
    </default>
    <default class="thumb_dip">
      <joint pos="0 0 0" axis="0 0 -1"
        limited="true" range="-0.47 2.443" />
      <position ctrlrange="-0.47 2.443" />
    </default>
    <default class="thumb_fingertip">
      <joint pos="0 0 0" axis="0 0 -1"
        limited="true" range="-1.34 1.88" />
      <position ctrlrange="-1.34 1.88" />
    </default>
  </default>

  <!-- Some collision filtering -->
  <contact>
    <exclude body1="palm" body2="mcp_joint" />
    <exclude body1="palm" body2="mcp_joint_2" />
    <exclude body1="palm" body2="mcp_joint_3" />
    <exclude body1="palm" body2="pip" />
    <exclude body1="palm" body2="pip_2" />
    <exclude body1="palm" body2="pip_3" />
    <exclude body1="palm" body2="pip_4" />
    <exclude body1="palm" body2="thumb_pip" />
    <exclude body1="palm" body2="dip" />
    <exclude body1="palm" body2="dip_2" />
    <exclude body1="palm" body2="dip_3" />
    <exclude body1="palm" body2="thumb_dip" />
    <exclude body1="mcp_joint" body2="mcp_joint_2" />
    <exclude body1="mcp_joint" body2="mcp_joint_3" />
    <exclude body1="mcp_joint_2" body2="mcp_joint_3" />
    <exclude body1="pip_4" body2="mcp_joint" />
    <exclude body1="pip_4" body2="mcp_joint_2" />
    <exclude body1="pip_4" body2="mcp_joint_3" />
  </contact>

  <worldbody>
    <body name="mount" pos="0 0 0.00635" quat="1 0 0 0">
      <geom pos="0 0 0" quat="1 0 0 0" class="visual"
          mesh="leap_mount" />

      <!-- WARNING: palm position NOT exact!!! -->
      <body name="palm" pos="0.032 0.007 -0.0335" quat="0 1 0 0.7">
        <inertial pos="0.01 0 0.04" quat="0.707109 0 -0.707105 0" mass="0.237"
          diaginertia="0.00029351 0.00019217 0.00040716" />

        <!-- N.B. visualize the grasp site by removing the group tag-->
        <site name="grasp_site" pos="0.07 0.0 0.1" group="4" />

        <geom pos="0.0346999 0.06375 0.0779998" quat="0.707109 0 -0.707105 0" class="visual"
          mesh="palm_lower" />
        <geom size="0.011 0.013 0.017" pos="0.0109999 0.046 0.0889999" quat="0.707109 0 -0.707105 0"
          class="collision" />
        <geom size="0.011 0.013 0.017" pos="0.0109999 0.001 0.0889999" quat="0.707109 0 -0.707105 0"
          class="collision" />
        <geom size="0.011 0.013 0.017" pos="0.0109999 -0.044 0.0889999" quat="0.707109 0 -0.707105 0"
          class="collision" />
        <geom size="0.029 0.01 0.023" pos="0.0114996 -0.04 0.0319999"
          quat="0.699342 0.104515 -0.699338 -0.104515" class="collision" />
        <geom size="0.005 0.06 0.01" pos="0.0239998 0.003 0.0659998" quat="0.923805 0 -0.382864 0"
          class="collision" />
        <geom size="0.012 0.058 0.023" pos="0.0114997 0.005 0.0499999" quat="0.707109 0 -0.707105 0"
          class="collision" />
        <geom size="0.022 0.026 0.023" pos="0.0114995 -0.015 0.0199999" quat="0.707109 0 -0.707105 0"
          class="collision" />

        <!-- UNNEEDED GEOMS -->
        <!-- <geom size="0.01 0.06 0.015" pos="0.00299981 0.003 0.068" quat="0.707109 0 -0.707105 0"
          class="collision"/> -->
        <!-- <geom size="0.002 0.018 0.017" pos="0.00599938 0.029 -3.79588e-08"
          quat="0.707109 0 -0.707105 0"
          class="collision" /> -->
        <!-- <geom size="0.022 0.028 0.002" pos="-0.0100005 0.035 0.0200001" quat="0.707109 0 -0.707105 0"
          class="collision" /> -->

        <body name="mcp_joint" pos="0.0187 0.061 0.0909999" quat="0.707109 0.707105 0 0">
          <inertial pos="-0.022516 0.033882 0.016359" quat="0.388092 0.677951 -0.247713 0.573067"
            mass="0.044" diaginertia="1.74972e-05 1.61504e-05 7.21342e-06" />
          <joint name="1" pos="0 0 0" axis="0 0 -1" range="-0.314 2.23" />
          <geom pos="0.0084 0.0077 0.01465" type="mesh" class="visual"
            mesh="mcp_joint" />
          <geom size="0.01 0.008 0.017" pos="0 0.013 0.0147" class="collision" />
          <geom size="0.014 0.02 0.01" pos="-0.027 0.042 0.015" class="collision" />
          <!-- <geom size="0.017 0.003 0.01" pos="-0.0262 0.02 0.0146" class="collision" /> -->
          <!-- <geom size="0.01 0.012 0.004" pos="-0.0295 0.035 0.029" class="collision" /> -->
          <!-- <geom size="0.007 0.01 0.002" pos="0 0.005 0.03" class="collision" /> -->
          <!-- <geom size="0.007 0.01 0.002" pos="0 0.005 -0.001" class="collision" /> -->
          <body name="pip" pos="-0.0122 0.0381 0.0145" quat="0.500003 -0.5 -0.499997 0.5">
            <inertial pos="0.0075 -0.0002 -0.011" quat="0 0.707107 0 0.707107" mass="0.032"
              diaginertia="4.8853e-06 4.3733e-06 3.0933e-06" />
            <joint name="0" pos="0 0 0" axis="0 0 -1" range="-1.047 1.047" />
            <geom pos="0.0096 0.0002 0.0007" quat="0.500003 -0.5 -0.5 -0.499997" type="mesh"
              class="visual" mesh="pip" />
            <geom size="0.017 0.013 0.011" pos="0.0075 -0.0002 -0.011" class="collision" />
            <body name="dip" pos="0.015 0.0143 -0.013" quat="0.500003 0.5 -0.5 0.499997">
              <inertial pos="0.0054215 -0.029148 0.015" quat="0.687228 0.687228 0.166487 0.166487"
                mass="0.037" diaginertia="8.28004e-06 8.1598e-06 5.39516e-06" />
              <joint name="2" pos="0 0 0" axis="0 0 -1" range="-0.506 1.885" />
              <geom pos="0.0211 -0.0084 0.0097" quat="2.67949e-08 -1 0 0" type="mesh"
                class="visual" mesh="dip" />
              <geom size="0.01 0.008 0.017" pos="0 -0.015 0.0145" class="collision" />
              <geom size="0.017 0.011 0.013" pos="0.0075 -0.035 0.015" class="collision" />
              <!-- <geom size="0.008 0.003 0.013" pos="0 -0.02 0.015" class="collision" /> -->
              <!-- <geom size="0.007 0.01 0.002" pos="0 -0.0045 0.03" class="collision" />
              <geom size="0.007 0.01 0.002" pos="0 -0.0045 0" class="collision" /> -->
              <body name="fingertip" pos="0 -0.0361 0.0002">
                <inertial pos="-0.0008794 -0.027019 0.014594"
                  quat="0.702905 0.710643 -0.0212937 -0.0214203" mass="0.016"
                  diaginertia="3.71863e-06 3.02396e-06 1.6518e-06" />
                <joint name="3" pos="0 0 0" axis="0 0 -1" range="-0.366 2.042" />
                <geom pos="0.0132 -0.0061 0.0144" quat="2.67949e-08 1 0 0" type="mesh"
                  class="visual" mesh="fingertip" />
                <geom size="0.01 0.005 0.017" pos="0 -0.012 0.0145" class="collision" />
                <!-- <geom size="0.007 0.011 0.002" pos="0 -0.006 0.03" class="collision" />
                <geom size="0.007 0.011 0.002" pos="0 -0.006 -0.001" class="collision" /> -->
                <geom type="mesh" mesh="white_tip" class="collision" />
                <geom type="mesh" mesh="white_tip" class="visual" material="white" />
              </body>
            </body>
          </body>
        </body>
        <body name="mcp_joint_2" pos="0.0187 0.0156 0.0908999" quat="0.707109 0.707105 0 0">
          <inertial pos="-0.022516 0.033882 0.016359" quat="0.388092 0.677951 -0.247713 0.573067"
            mass="0.044" diaginertia="1.74972e-05 1.61504e-05 7.21342e-06" />
          <joint name="5" pos="0 0 0" axis="0 0 -1" range="-0.314 2.23" />
          <geom pos="0.0084 0.0077 0.01465" type="mesh" class="visual"
            mesh="mcp_joint" />
          <geom size="0.01 0.008 0.017" pos="0 0.013 0.0147" class="collision" />
          <geom size="0.014 0.02 0.01" pos="-0.027 0.042 0.015" class="collision" />
          <!-- <geom size="0.01 0.003 0.017" pos="0 0.018 0.0147" class="collision" />
          <geom size="0.014 0.02 0.01" pos="-0.027 0.042 0.015" class="collision" />
          <geom size="0.017 0.003 0.01" pos="-0.0262 0.02 0.0146" class="collision" />
          <geom size="0.01 0.012 0.004" pos="-0.0295 0.035 0.029" class="collision" />
          <geom size="0.007 0.01 0.002" pos="0 0.005 0.03" class="collision" />
          <geom size="0.007 0.01 0.002" pos="0 0.005 -0.001" class="collision" /> -->
          <body name="pip_2" pos="-0.0122 0.0381 0.0145" quat="0.500003 -0.5 -0.499997 0.5">
            <inertial pos="0.0075 -0.0002 -0.011" quat="0 0.707107 0 0.707107" mass="0.032"
              diaginertia="4.8853e-06 4.3733e-06 3.0933e-06" />
            <joint name="4" pos="0 0 0" axis="0 0 -1" range="-1.047 1.047" />
          <geom pos="0.0096 0.0003 0.0007" quat="0.500003 -0.5 -0.5 -0.499997" type="mesh"
            class="visual" mesh="pip" />
          <geom size="0.017 0.013 0.011" pos="0.0075 -0.0002 -0.011" class="collision" />
          <body name="dip_2" pos="0.015 0.0143 -0.013" quat="0.500003 0.5 -0.5 0.499997">
            <inertial pos="0.0054215 -0.029148 0.015" quat="0.687228 0.687228 0.166487 0.166487"
              mass="0.037" diaginertia="8.28004e-06 8.1598e-06 5.39516e-06" />
            <joint name="6" pos="0 0 0" axis="0 0 -1" range="-0.506 1.885" />
            <geom pos="0.0211 -0.0084 0.0097" quat="1.32679e-06 -1 0 0" type="mesh"
              class="visual" mesh="dip" />
            <geom size="0.01 0.008 0.017" pos="0 -0.015 0.0145" class="collision" />
            <geom size="0.017 0.011 0.013" pos="0.0075 -0.035 0.015" class="collision" />
            <!-- <geom size="0.008 0.003 0.013" pos="0 -0.02 0.015" class="collision" />
            <geom size="0.01 0.002 0.017" pos="0 -0.016 0.015" class="collision" />
            <geom size="0.007 0.01 0.002" pos="0 -0.0045 0.03" class="collision" />
            <geom size="0.007 0.01 0.002" pos="0 -0.0045 0" class="collision" />
            <geom size="0.017 0.011 0.013" pos="0.0075 -0.035 0.015" class="collision" /> -->
            <body name="fingertip_2" pos="0 -0.0361 0.0002">
              <inertial pos="-0.0008794 -0.027019 0.014594"
                quat="0.702905 0.710643 -0.0212937 -0.0214203" mass="0.016"
                diaginertia="3.71863e-06 3.02396e-06 1.6518e-06" />
              <joint name="7" pos="0 0 0" axis="0 0 -1" range="-0.366 2.042" />
              <geom pos="0.0132 -0.0061 0.0145" quat="1.32679e-06 1 0 0" type="mesh"
                class="visual" mesh="fingertip" />
              <geom size="0.01 0.005 0.017" pos="0 -0.012 0.0145" class="collision" />
              <!-- <geom size="0.007 0.011 0.002" pos="0 -0.006 0.03" class="collision" />
              <geom size="0.007 0.011 0.002" pos="0 -0.006 -0.001" class="collision" /> -->
              <geom type="mesh" mesh="white_tip" class="collision" />
              <geom type="mesh" mesh="white_tip" class="visual" material="white" />
            </body>
          </body>
        </body>
      </body>
      <body name="mcp_joint_3" pos="0.0187 -0.0298 0.0909099" quat="0.707109 0.707105 0 0">
        <inertial pos="-0.022516 0.033882 0.016359" quat="0.388092 0.677951 -0.247713 0.573067"
          mass="0.044" diaginertia="1.74972e-05 1.61504e-05 7.21342e-06" />
        <joint name="9" pos="0 0 0" axis="0 0 -1" range="-0.314 2.23" />
        <geom pos="0.0084 0.0077 0.01465" type="mesh" class="visual"
          mesh="mcp_joint" />
        <geom size="0.01 0.008 0.017" pos="0 0.013 0.0147" class="collision" />
        <geom size="0.014 0.02 0.01" pos="-0.027 0.042 0.015" class="collision" />
        <!-- <geom size="0.01 0.003 0.017" pos="0 0.018 0.0147" class="collision" />
        <geom size="0.014 0.02 0.01" pos="-0.027 0.042 0.015" class="collision" />
        <geom size="0.017 0.003 0.01" pos="-0.0262 0.02 0.0146" class="collision" />
        <geom size="0.01 0.012 0.004" pos="-0.0295 0.035 0.029" class="collision" />
        <geom size="0.007 0.01 0.002" pos="0 0.005 0.03" class="collision" />
        <geom size="0.007 0.01 0.002" pos="0 0.005 -0.001" class="collision" /> -->
        <body name="pip_3" pos="-0.0122 0.0381 0.0145" quat="0.500003 -0.5 -0.499997 0.5">
          <inertial pos="0.0075 -0.0002 -0.011" quat="0 0.707107 0 0.707107" mass="0.032"
            diaginertia="4.8853e-06 4.3733e-06 3.0933e-06" />
          <joint name="8" pos="0 0 0" axis="0 0 -1" range="-1.047 1.047" />
          <geom pos="0.0096 0.0003 0.0007" quat="0.500003 -0.5 -0.5 -0.499997" type="mesh"
            class="visual" mesh="pip" />
          <geom size="0.017 0.013 0.011" pos="0.0075 -0.0002 -0.011" class="collision" />
          <body name="dip_3" pos="0.015 0.0143 -0.013" quat="0.500003 0.5 -0.5 0.499997">
            <inertial pos="0.0054215 -0.029148 0.015" quat="0.687228 0.687228 0.166487 0.166487"
              mass="0.037" diaginertia="8.28004e-06 8.1598e-06 5.39516e-06" />
            <joint name="10" pos="0 0 0" axis="0 0 -1" range="-0.506 1.885" />
            <geom pos="0.0211 -0.0084 0.0097" quat="1.32679e-06 -1 0 0" type="mesh"
              class="visual" mesh="dip" />
            <geom size="0.01 0.008 0.017" pos="0 -0.015 0.0145" class="collision" />
            <geom size="0.017 0.011 0.013" pos="0.0075 -0.035 0.015" class="collision" />
            <!-- <geom size="0.008 0.003 0.013" pos="0 -0.02 0.015" class="collision" />
            <geom size="0.01 0.002 0.017" pos="0 -0.016 0.015" class="collision" />
            <geom size="0.007 0.01 0.002" pos="0 -0.0045 0.03" class="collision" />
            <geom size="0.007 0.01 0.002" pos="0 -0.0045 0" class="collision" />
            <geom size="0.017 0.011 0.013" pos="0.0075 -0.035 0.015" class="collision" /> -->
            <body name="fingertip_3" pos="0 -0.03609 0.0002">
              <inertial pos="-0.0008794 -0.027019 0.014594"
                quat="0.702905 0.710643 -0.0212937 -0.0214203" mass="0.016"
                diaginertia="3.71863e-06 3.02396e-06 1.6518e-06" />
              <joint name="11" pos="0 0 0" axis="0 0 -1" range="-0.366 2.042" />
              <geom pos="0.0132 -0.0061 0.0145" quat="1.32679e-06 1 0 0" type="mesh"
                class="visual" mesh="fingertip" />
              <geom size="0.01 0.005 0.017" pos="0 -0.012 0.0145" class="collision" />
              <!-- <geom size="0.007 0.011 0.002" pos="0 -0.006 0.03" class="collision" />
              <geom size="0.007 0.011 0.002" pos="0 -0.006 -0.001" class="collision" /> -->
              <geom type="mesh" mesh="white_tip" class="collision" />
              <geom type="mesh" mesh="white_tip" class="visual" material="white" />
            </body>
          </body>
        </body>
      </body>
      <body name="pip_4" pos="0.0215996 0.0368 0.0286999">
        <inertial pos="0.0075 -0.0002 -0.011" quat="0 0.707107 0 0.707107" mass="0.032"
          diaginertia="4.8853e-06 4.3733e-06 3.0933e-06" />
        <joint name="12" pos="0 0 0" axis="0 0 -1" range="-0.349 2.094" />
        <geom pos="-0.0053 0.0003 0.00078" quat="0.500003 -0.5 -0.5 -0.499997" type="mesh"
          class="visual" mesh="pip" />
        <geom size="0.017 0.013 0.011" pos="-0.0075 -0.0002 -0.011" class="collision" />
        <body name="thumb_pip" pos="0 0.0143 -0.013" quat="0.500003 0.5 -0.5 0.499997">
          <inertial pos="0 0 -0.0070806" quat="0.707107 0.707107 0 0" mass="0.003"
            diaginertia="6.1932e-07 5.351e-07 2.1516e-07" />
          <joint name="13" pos="0 0 0" axis="0 0 -1" range="-0.47 2.443" />
          <geom pos="0.01196 0 -0.0158" quat="0.707109 0.707105 0 0" type="mesh"
            class="visual" mesh="thumb_pip" />
          <geom size="0.009 0.0165 0.009" pos="0 0 -0.009" class="collision" />

          <!-- UNNEEDED GEOMS -->
          <!-- <geom size="0.009 0.0165 0.002" pos="0 0 -0.0015" class="collision" />
          <geom size="0.007 0.002 0.01" pos="0 -0.015 -0.013" class="collision" />
          <geom size="0.007 0.002 0.01" pos="0 0.015 -0.013" class="collision" /> -->
          <body name="thumb_dip" pos="0 0.0145 -0.017" quat="0.707109 -0.707105 0 0">
            <inertial pos="-0.0020593 0.015912 -0.013733"
              quat="0.698518 0.697382 -0.104933 0.121324"
              mass="0.038" diaginertia="9.87104e-06 9.32653e-06 4.36203e-06" />
            <joint name="14" pos="0 0 0" axis="0 0 -1" range="-1.2 1.9" />
            <geom pos="0.0439 0.0579 -0.0086" type="mesh" class="visual"
              mesh="thumb_dip" />
            <geom size="0.01 0.02 0.012" pos="0 0.0105 -0.014" class="collision" />
            <geom size="0.01 0.01 0.016" pos="0 0.041 -0.015" class="collision" />

            <!-- UNNEEDED GEOMS -->
            <!-- <geom size="0.005 0.012 0.009" pos="-0.0135 0.0175 -0.011656" class="collision" /> -->
            <!-- <geom size="0.01 0.002 0.016" pos="0 0.031 -0.015" class="collision" />
            <geom size="0.007 0.01 0.002" pos="0 0.042 0.001" class="collision" />
            <geom size="0.007 0.01 0.002" pos="0 0.042 -0.029" class="collision" /> -->
            <body name="thumb_fingertip" pos="0 0.0466 0.0002" quat="1.32679e-06 0 0 1">
              <inertial pos="0.00096191 -0.024203 -0.014419"
                quat="0.35287 0.311272 -0.632839 0.614904" mass="0.049"
                diaginertia="2.08591e-05 2.0402e-05 4.71335e-06" />
              <joint name="15" pos="0 0 0" axis="0 0 -1" range="-1.34 1.88" />
              <geom pos="0.0625 0.0784 0.0489" type="mesh" class="visual"
                mesh="thumb_fingertip" />
              <geom size="0.01 0.018 0.012" pos="0 -0.0085 -0.015" class="collision" />
              <geom size="0.01 0.002 0.015" pos="0 -0.029 -0.014" class="collision" />
              <geom type="mesh" mesh="white_tip_thumb" class="collision" />
              <geom type="mesh" mesh="white_tip_thumb" class="visual" material="white" />

              <!-- UNNEEDED GEOMS -->
              <!-- <geom size="0.004 0.012 0.009" pos="0.015 -0.0175 -0.0115" class="collision" /> -->
            </body>
          </body>
        </body>
      </body>
    </body>
    </body>
  </worldbody>

  <actuator>
    <position name="1" joint="1" class="mcp_joint" />
    <position name="0" joint="0" class="pip" />
    <position name="2" joint="2" class="dip" />
    <position name="3" joint="3" class="fingertip" />
    <position name="5" joint="5" class="mcp_joint" />
    <position name="4" joint="4" class="pip" />
    <position name="6" joint="6" class="dip" />
    <position name="7" joint="7" class="fingertip" />
    <position name="9" joint="9" class="mcp_joint" />
    <position name="8" joint="8" class="pip" />
    <position name="10" joint="10" class="dip" />
    <position name="11" joint="11" class="fingertip" />
    <position name="12" joint="12" class="thumb_base_pip" />
    <position name="13" joint="13" class="thumb_pip" />
    <position name="14" joint="14" class="thumb_dip" />
    <position name="15" joint="15" class="thumb_fingertip" />
  </actuator>

  <sensor>
    <framepos name="trace1" objtype="body" objname="fingertip" />
    <framepos name="trace2" objtype="body" objname="fingertip_2" />
    <framepos name="trace3" objtype="body" objname="fingertip_3" />
    <framepos name="trace4" objtype="body" objname="thumb_fingertip" />
  </sensor>
</mujoco>