<mujoco model="swimmer">
  <option timestep="0.01" integrator="implicit" density="1000">
    <flag contact="disable"/>
  </option>

  <default>
    <default class="swimmer">
      <joint type="hinge" pos="0 -.05 0" axis="0 0 1" limited="true" solreflimit=".05 .3"
             solimplimit="0 .8 .1" armature="1e-6" range="-90 90" stiffness=".001"/>
      <default class="inertial">
        <geom type="box" size=".001 .05 .01" material="self" mass=".01" group="3"/>
      </default>
      <default class="visual">
        <geom type="capsule" size=".01" fromto="0 -.05 0 0 .05 0" mass="0" material="self"/>
      </default>
      <site size=".01" rgba="0 0 0 0"/>
    </default>
    <default class="free">
      <joint limited="false" stiffness="0" armature="0"/>
    </default>
    <general gainprm="2e-3" ctrllimited="true" ctrlrange="-1 1" dyntype="filter" dynprm="0.6"/>
  </default>

  <worldbody>
    <geom name="ground" type="plane" size="2 2 0.01" material="blue_grid"/>
    <body name="head" pos="0 0 .05" childclass="swimmer">
      <light name="light_1" diffuse=".8 .8 .8" pos="0 0 1.5"/>
      <geom name="head" type="ellipsoid" size=".02 .04 .017" pos="0 -.022 0" mass="0" material="self"/>
      <geom name="nose" type="sphere" pos="0 -.06 0" size=".004" mass="0" material="effector" euler="180 0 0"/>
      <geom name="eyes" type="capsule" fromto="-.006 -.054 .005 .006 -.054 .005" size=".004" mass="0" material="eye"/>
      <camera name="tracking1" pos="0.0 -0.2 0.5" xyaxes="1 0 0 0 1 1" mode="trackcom" fovy="60"/>
      <camera name="tracking2" pos="-0.9 0.5 0.15" xyaxes="0 -1 0 .3 0 1" mode="trackcom" fovy="60"/>
      <camera name="eyes" pos="0 -.058 .005" xyaxes="-1 0 0 0 0 1"/>
      <joint name="rootx" class="free" type="slide" axis="1 0 0" pos="0 -.05 0"/>
      <joint name="rooty" class="free" type="slide" axis="0 1 0" pos="0 -.05 0"/>
      <joint name="rootz" class="free" type="hinge" axis="0 0 1" pos="0 -.05 0"/>
      <geom name="inertial" class="inertial"/>
      <geom name="visual" class="visual"/>
      <site name="head"/>
      <body name="segment_0" pos="0 .1 0">
        <geom class="visual" name="visual_0"/>
        <geom class="inertial" name="inertial_0"/>
        <site name="site_0"/>
        <joint name="joint_0"/>
        <body name="segment_1" pos="0 .1 0">
          <geom class="visual" name="visual_1"/>
          <geom class="inertial" name="inertial_1"/>
          <site name="site_1"/>
          <joint name="joint_1"/>
          <body name="segment_2" pos="0 .1 0">
            <geom class="visual" name="visual_2"/>
            <geom class="inertial" name="inertial_2"/>
            <site name="site_2"/>
            <joint name="joint_2"/>
            <body name="segment_3" pos="0 .1 0">
              <geom class="visual" name="visual_3"/>
              <geom class="inertial" name="inertial_3"/>
              <site name="site_3"/>
              <joint name="joint_3"/>
              <body name="segment_4" pos="0 .1 0">
                <geom class="visual" name="visual_4"/>
                <geom class="inertial" name="inertial_4"/>
                <site name="site_4"/>
                <joint name="joint_4"/>
              </body>
            </body>
          </body>
        </body>
      </body>
    </body>
  </worldbody>

  <actuator>
    <general name="0" joint="joint_0"/>
    <general name="1" joint="joint_1"/>
    <general name="2" joint="joint_2"/>
    <general name="3" joint="joint_3"/>
    <general name="4" joint="joint_4"/>
  </actuator>

</mujoco>
