<mujoco model="left_shadow_hand">
  

    <!-- <body name="lh_forearm" childclass="left_hand" quat="1 -1 1 -1"> -->
      <!-- <site name="lh_forearm_touch" class="left_hand" pos="0 0 0.08" zaxis="0 1 0"/> -->
      <!-- <inertial mass="3" pos="0 0 0.09" diaginertia="0.0138 0.0138 0.00744"/> -->
      <!-- <geom class="left_plastic_visual" mesh="left_forearm_0" material="gray"/> -->
      <!-- <geom class="left_plastic_visual" mesh="left_forearm_1"/> -->
      <!-- <include file="../shadow_hand_submodel/left_forearm_collision_collision_0.xml"/> -->
      <!-- <geom class="left_plastic_collision" size="0.03 0.03 0.03" pos="0 -0.01 0.181" quat="0.924909 0 0.380188 0" -->
        <!-- type="box"/> -->
      <!-- <body name="lh_wrist" pos="0 -0.01 0.21301"> -->
      <body name="lh_wrist" pos="0 -0.01 0.15301" quat="1 0 0 1">
        <inertial mass="0.1" pos="0 0 0.029" quat="0.5 0.5 0.5 0.5" diaginertia="6.4e-05 4.38e-05 3.5e-05"/>
        <joint class="left_wrist_y" name="lh_WRJ2"/>
        <geom class="left_plastic_visual" mesh="left_wrist" material="metallic"/>
        <!-- <geom size="0.013 0.015" quat="0.499998 0.5 0.5 -0.500002" type="cylinder" class="left_plastic_collision"/> -->
        <geom size="0.011 0.005" pos="0.026 0 0.034" quat="1 0 1 0" type="cylinder" class="left_plastic_collision"/>
        <geom size="0.011 0.005" pos="-0.031 0 0.034" quat="1 0 1 0" type="cylinder" class="left_plastic_collision"/>
        <geom size="0.0135 0.009 0.005" pos="0.021 0 0.011" quat="-0.923879 0 0.382684 0" type="box"
          class="left_plastic_collision"/>
        <geom size="0.0135 0.009 0.005" pos="-0.026 0 0.01" quat="-0.923879 0 -0.382684 0" type="box"
          class="left_plastic_collision"/>
        <body name="lh_palm" pos="0 0 0.034">
          <site name="lh_palm_touch" class="left_hand" pos="0 0 0.05" zaxis="0 1 0"/>
          <inertial mass="0.3" pos="0 0 0.035" quat="1 0 0 1" diaginertia="0.0005287 0.0003581 0.000191"/>
          <joint class="left_wrist_x" name="lh_WRJ1"/>
          <geom class="left_plastic_visual" mesh="left_palm"/>
          <include file="../shadow_hand_submodel/left_palm_collision_0.xml"/>
          <body name="lh_ffknuckle" pos="-0.033 0 0.095">
            <inertial mass="0.008" pos="0 0 0" quat="0.5 0.5 -0.5 0.5" diaginertia="3.2e-07 2.6e-07 2.6e-07"/>
            <joint name="lh_FFJ4" class="left_knuckle" axis="0 1 0"/>
            <geom pos="0 0 0.0005" class="left_plastic_visual" mesh="left_f_knuckle" material="metallic"/>
            <geom size="0.009 0.009" quat="1 0 1 0" type="cylinder" class="left_plastic_collision"/>
            <body name="lh_ffproximal">
              <site name="lh_ffproximal_touch" class="left_hand" pos="0 0 0.022" zaxis="0 1 0"/>
              <inertial mass="0.03" pos="0 0 0.0225" quat="1 0 0 1" diaginertia="1e-05 9.8e-06 1.8e-06"/>
              <joint name="lh_FFJ3" class="left_proximal"/>
              <geom class="left_plastic_visual" mesh="left_f_proximal"/>
              <include file="../shadow_hand_submodel/left_f_proximal_collision_0.xml"/>
              <body name="lh_ffmiddle" pos="0 0 0.045">
                <site name="lh_ffmiddle_touch" class="left_hand" pos="0 0 0.0125" zaxis="0 1 0"/>
                <inertial mass="0.017" pos="0 0 0.0125" quat="1 0 0 1" diaginertia="2.7e-06 2.6e-06 8.7e-07"/>
                <joint name="lh_FFJ2" class="left_middle_distal"/>
                <geom class="left_plastic_visual" mesh="left_f_middle"/>
                <include file="../shadow_hand_submodel/left_f_middle_collision_0.xml"/>
                <body name="lh_ffdistal" pos="0 0 0.025">
                  <site name="lh_ffdistal_touch" class="left_hand" pos="0 0 0.017" zaxis="0 1 0"/>
                  <inertial mass="0.013" pos="0 0 0.0130769" quat="1 0 0 1"
                    diaginertia="1.28092e-06 1.12092e-06 5.3e-07"/>
                  <joint name="lh_FFJ1" class="left_middle_distal"/>
                  <geom class="left_plastic_visual" mesh="left_f_distal_pst"/>
                  <include file="../shadow_hand_submodel/left_f_distal_pst_collision_0.xml"/>
                </body>
              </body>
            </body>
          </body>
          <body name="lh_mfknuckle" pos="-0.011 0 0.099">
            <inertial mass="0.008" pos="0 0 0" quat="0.5 0.5 -0.5 0.5" diaginertia="3.2e-07 2.6e-07 2.6e-07"/>
            <joint name="lh_MFJ4" class="left_knuckle" axis="0 1 0"/>
            <geom pos="0 0 0.0005" class="left_plastic_visual" mesh="left_f_knuckle" material="metallic"/>
            <geom size="0.009 0.009" quat="1 0 1 0" type="cylinder" class="left_plastic_collision"/>
            <body name="lh_mfproximal">
              <site name="lh_mfproximal_touch" class="left_hand" pos="0 0 0.022" zaxis="0 1 0"/>
              <inertial mass="0.03" pos="0 0 0.0225" quat="1 0 0 1" diaginertia="1e-05 9.8e-06 1.8e-06"/>
              <joint name="lh_MFJ3" class="left_proximal"/>
              <geom class="left_plastic_visual" mesh="left_f_proximal"/>
              <include file="../shadow_hand_submodel/left_f_proximal_collision_1.xml"/>
              <body name="lh_mfmiddle" pos="0 0 0.045">
                <site name="lh_mfmiddle_touch" class="left_hand" pos="0 0 0.0125" zaxis="0 1 0"/>
                <inertial mass="0.017" pos="0 0 0.0125" quat="1 0 0 1" diaginertia="2.7e-06 2.6e-06 8.7e-07"/>
                <joint name="lh_MFJ2" class="left_middle_distal"/>
                <geom class="left_plastic_visual" mesh="left_f_middle"/>
                <include file="../shadow_hand_submodel/left_f_middle_collision_1.xml"/>
                <body name="lh_mfdistal" pos="0 0 0.025">
                  <site name="lh_mfdistal_touch" class="left_hand" pos="0 0 0.017" zaxis="0 1 0"/>
                  <inertial mass="0.013" pos="0 0 0.0130769" quat="1 0 0 1"
                    diaginertia="1.28092e-06 1.12092e-06 5.3e-07"/>
                  <joint name="lh_MFJ1" class="left_middle_distal"/>
                  <geom class="left_plastic_visual" mesh="left_f_distal_pst"/>
                  <include file="../shadow_hand_submodel/left_f_distal_pst_collision_1.xml"/>
                </body>
              </body>
            </body>
          </body>
          <body name="lh_rfknuckle" pos="0.011 0 0.095">
            <inertial mass="0.008" pos="0 0 0" quat="0.5 0.5 -0.5 0.5" diaginertia="3.2e-07 2.6e-07 2.6e-07"/>
            <joint name="lh_RFJ4" class="left_knuckle"/>
            <geom pos="0 0 0.0005" class="left_plastic_visual" mesh="left_f_knuckle" material="metallic"/>
            <geom size="0.009 0.009" quat="1 0 1 0" type="cylinder" class="left_plastic_collision"/>
            <body name="lh_rfproximal">
              <site name="lh_rfproximal_touch" class="left_hand" pos="0 0 0.022" zaxis="0 1 0"/>
              <inertial mass="0.03" pos="0 0 0.0225" quat="1 0 0 1" diaginertia="1e-05 9.8e-06 1.8e-06"/>
              <joint name="lh_RFJ3" class="left_proximal"/>
              <geom class="left_plastic_visual" mesh="left_f_proximal"/>
              <include file="../shadow_hand_submodel/left_f_proximal_collision_2.xml"/>
              <body name="lh_rfmiddle" pos="0 0 0.045">
                <site name="lh_rfmiddle_touch" class="left_hand" pos="0 0 0.0125" zaxis="0 1 0"/>
                <inertial mass="0.017" pos="0 0 0.0125" quat="1 0 0 1" diaginertia="2.7e-06 2.6e-06 8.7e-07"/>
                <joint name="lh_RFJ2" class="left_middle_distal"/>
                <geom class="left_plastic_visual" mesh="left_f_middle"/>
                <include file="../shadow_hand_submodel/left_f_middle_collision_2.xml"/>
                <body name="lh_rfdistal" pos="0 0 0.025">
                  <site name="lh_rfdistal_touch" class="left_hand" pos="0 0 0.017" zaxis="0 1 0"/>
                  <inertial mass="0.013" pos="0 0 0.0130769" quat="1 0 0 1"
                    diaginertia="1.28092e-06 1.12092e-06 5.3e-07"/>
                  <joint name="lh_RFJ1" class="left_middle_distal"/>
                  <geom class="left_plastic_visual" mesh="left_f_distal_pst"/>
                  <include file="../shadow_hand_submodel/left_f_distal_pst_collision_2.xml"/>
                </body>
              </body>
            </body>
          </body>
          <body name="lh_lfmetacarpal" pos="0.033 0 0.02071">
            <site name="lh_lfmetacarpal_touch" class="left_hand" pos="0 0 0.035" zaxis="0 1 0"/>
            <inertial mass="0.03" pos="0 0 0.04" quat="1 0 0 1" diaginertia="1.638e-05 1.45e-05 4.272e-06"/>
            <joint name="lh_LFJ5" class="left_metacarpal" axis="0.573576 0 -0.819152"/>
            <geom class="left_plastic_visual" mesh="left_lf_metacarpal"/>
            <include file='../shadow_hand_submodel/left_lf_metacarpal_collision_0.xml'/>
            <body name="lh_lfknuckle" pos="0 0 0.06579">
              <inertial mass="0.008" pos="0 0 0" quat="0.5 0.5 -0.5 0.5" diaginertia="3.2e-07 2.6e-07 2.6e-07"/>
              <joint name="lh_LFJ4" class="left_knuckle"/>
              <geom pos="0 0 0.0005" class="left_plastic_visual" mesh="left_f_knuckle" material="metallic"/>
              <geom size="0.009 0.009" quat="1 0 1 0" type="cylinder" class="left_plastic_collision"/>
              <body name="lh_lfproximal">
                <site name="lh_lfproximal_touch" class="left_hand" pos="0 0 0.022" zaxis="0 1 0"/>
                <inertial mass="0.03" pos="0 0 0.0225" quat="1 0 0 1" diaginertia="1e-05 9.8e-06 1.8e-06"/>
                <joint name="lh_LFJ3" class="left_proximal"/>
                <geom class="left_plastic_visual" mesh="left_f_proximal"/>
                <include file="../shadow_hand_submodel/left_f_proximal_collision_3.xml"/>
                <body name="lh_lfmiddle" pos="0 0 0.045">
                  <site name="lh_lfmiddle_touch" class="left_hand" pos="0 0 0.0125" zaxis="0 1 0"/>
                  <inertial mass="0.017" pos="0 0 0.0125" quat="1 0 0 1" diaginertia="2.7e-06 2.6e-06 8.7e-07"/>
                  <joint name="lh_LFJ2" class="left_middle_distal"/>
                  <geom class="left_plastic_visual" mesh="left_f_middle"/>
                  <include file="../shadow_hand_submodel/left_f_middle_collision_3.xml"/>
                  <body name="lh_lfdistal" pos="0 0 0.025">
                    <site name="lh_lfdistal_touch" class="left_hand" pos="0 0 0.017" zaxis="0 1 0"/>
                    <inertial mass="0.013" pos="0 0 0.0130769" quat="1 0 0 1"
                      diaginertia="1.28092e-06 1.12092e-06 5.3e-07"/>
                    <joint name="lh_LFJ1" class="left_middle_distal"/>
                    <geom class="left_plastic_visual" mesh="left_f_distal_pst"/>
                    <include file="../shadow_hand_submodel/left_f_distal_pst_collision_3.xml"/>
                  </body>
                </body>
              </body>
            </body>
          </body>
          <body name="lh_thbase" pos="-0.034 -0.00858 0.029" quat="0 -0.382683 0 0.92388">
            <inertial mass="0.01" pos="0 0 0" diaginertia="1.6e-07 1.6e-07 1.6e-07"/>
            <joint name="lh_THJ5" class="left_thbase"/>
            <body name="lh_thproximal">
              <site name="lh_thproximal_touch" class="left_hand" pos="0 0 0.02" zaxis="1 0 0"/>
              <inertial mass="0.04" pos="0 0 0.019" diaginertia="1.36e-05 1.36e-05 3.13e-06"/>
              <joint name="lh_THJ4" class="left_thproximal"/>
              <geom class="left_plastic_visual" mesh="left_th_proximal"/>
              <include file='../shadow_hand_submodel/left_th_proximal_collision_0.xml'/>
              <body name="lh_thhub" pos="0 0 0.038">
                <inertial mass="0.005" pos="0 0 0" diaginertia="1e-06 1e-06 3e-07"/>
                <joint name="lh_THJ3" class="left_thhub"/>
                <body name="lh_thmiddle">
                  <site name="lh_thmiddle_touch" class="left_hand" pos="0 0 0.014" zaxis="1 0 0"/>
                  <inertial mass="0.02" pos="0 0 0.016" diaginertia="5.1e-06 5.1e-06 1.21e-06"/>
                  <joint name="lh_THJ2" class="left_thmiddle"/>
                  <geom class="left_plastic_visual" mesh="left_th_middle"/>
                  <include file='../shadow_hand_submodel/left_th_middle_collision_0.xml'/>
                  <body name="lh_thdistal" pos="0 0 0.032" quat="1 0 0 -1">
                    <site name="lh_thdistal_touch" class="left_hand" pos="0 0 0.02" zaxis="0 1 0"/>
                    <inertial mass="0.017" pos="0 0 0.0145588" quat="1 0 0 1"
                      diaginertia="2.37794e-06 2.27794e-06 1e-06"/>
                    <joint name="lh_THJ1" class="left_thdistal"/>
                    <geom class="left_plastic_visual" mesh="left_th_distal_pst"/>
                    <include file='../shadow_hand_submodel/left_th_distal_pst_collision_0.xml'/>
                  </body>
                </body>
              </body>
            </body>
          </body>
        </body>
      </body>
    <!-- </body> -->

 
</mujoco>
