<mujoco model="right_shadow_hand">

    <!-- <body name="rh_forearm" childclass="right_hand" quat="1 -1 1 -1"> -->
      <!-- <site name="rh_forearm_touch" class="right_hand" pos="0 0 0.08" zaxis="0 1 0"/> -->
      <!-- <inertial mass="3" pos="0 0 0.09" diaginertia="0.0138 0.0138 0.00744"/> -->
      <!-- <geom class="right_plastic_visual" mesh="right_forearm_0" material="gray"/> -->
      <!-- <geom class="right_plastic_visual" mesh="right_forearm_1"/> -->
      <!-- <include file="../shadow_hand_submodel/right_forearm_collision_collision_0.xml"/> -->
      <!-- <geom class="right_plastic_collision" type="mesh" mesh="right_forearm_collision"/> -->
      <!-- <geom class="right_plastic_collision" size="0.03 0.03 0.03" pos="0 -0.01 0.181" quat="0.924909 0 0.380188 0" -->
        <!-- type="box"/> -->
      <!-- <body name="rh_wrist" pos="0 -0.01 0.21301"> -->
      <body name="rh_wrist" pos="0 -0.01 0.15301" quat="1 0 0 1">
        <inertial mass="0.1" pos="0 0 0.029" quat="0.5 0.5 0.5 0.5" diaginertia="6.4e-05 4.38e-05 3.5e-05"/>
        <joint class="right_wrist_y" name="rh_WRJ2"/>
        <geom class="right_plastic_visual" mesh="right_wrist" material="metallic"/>
        <!-- <geom size="0.0135 0.015" quat="0.499998 0.5 0.5 -0.500002" type="cylinder" class="right_plastic_collision"/> -->
        <geom size="0.011 0.005" pos="-0.026 0 0.034" quat="1 0 1 0" type="cylinder" class="right_plastic_collision"/>
        <geom size="0.011 0.005" pos="0.031 0 0.034" quat="1 0 1 0" type="cylinder" class="right_plastic_collision"/>
        <geom size="0.0135 0.009 0.005" pos="-0.021 0 0.011" quat="0.923879 0 0.382684 0" type="box"
          class="right_plastic_collision"/>
        <geom size="0.0135 0.009 0.005" pos="0.026 0 0.01" quat="0.923879 0 -0.382684 0" type="box"
          class="right_plastic_collision"/>
        <body name="rh_palm" pos="0 0 0.034">
          <site name="rh_palm_touch" class="right_hand" pos="0 0 0.05" zaxis="0 1 0"/>
          <inertial mass="0.3" pos="0 0 0.035" quat="1 0 0 1" diaginertia="0.0005287 0.0003581 0.000191"/>
          <joint class="right_wrist_x" name="rh_WRJ1"/>
          <!-- <site name="grasp_site" pos="0 -.035 0.09" group="4"/> -->
          <geom class="right_plastic_visual" mesh="right_palm"/>
          <include file="../shadow_hand_submodel/right_palm_collision_0.xml"/>
          <!-- <geom size="0.031 0.0035 0.049" pos="0.011 0.0085 0.038" type="box" class="right_plastic_collision"/>
          <geom size="0.018 0.0085 0.049" pos="-0.002 -0.0035 0.038" type="box" class="right_plastic_collision"/>
          <geom size="0.013 0.0085 0.005" pos="0.029 -0.0035 0.082" type="box" class="right_plastic_collision"/>
          <geom size="0.013 0.007 0.009" pos="0.0265 -0.001 0.07" quat="0.987241 0.0990545 0.0124467 0.124052"
            type="box" class="right_plastic_collision"/>
          <geom size="0.0105 0.0135 0.012" pos="0.0315 -0.0085 0.001" type="box" class="right_plastic_collision"/>
          <geom size="0.011 0.0025 0.015" pos="0.0125 -0.015 0.004" quat="0.971338 0 0 -0.237703" type="box"
            class="right_plastic_collision"/>
          <geom size="0.009 0.012 0.002" pos="0.011 0 0.089" type="box" class="right_plastic_collision"/>
          <geom size="0.01 0.012 0.02" pos="-0.03 0 0.009" type="box" class="right_plastic_collision"/> -->
          <body name="rh_ffknuckle" pos="0.033 0 0.095">
            <inertial mass="0.008" pos="0 0 0" quat="0.5 0.5 -0.5 0.5" diaginertia="3.2e-07 2.6e-07 2.6e-07"/>
            <joint name="rh_FFJ4" class="right_knuckle"/>
            <geom pos="0 0 0.0005" class="right_plastic_visual" mesh="right_f_knuckle" material="metallic"/>
            <geom size="0.009 0.009" quat="1 0 1 0" type="cylinder" class="right_plastic_collision"/>
            <body name="rh_ffproximal">
              <site name="rh_ffproximal_touch" class="right_hand" pos="0 0 0.022" zaxis="0 1 0"/>
              <inertial mass="0.03" pos="0 0 0.0225" quat="1 0 0 1" diaginertia="1e-05 9.8e-06 1.8e-06"/>
              <joint name="rh_FFJ3" class="right_proximal"/>
              <geom class="right_plastic_visual" mesh="right_f_proximal"/>
              <include file="../shadow_hand_submodel/right_f_proximal_collision_0.xml"/>
              <!-- <geom size="0.009 0.02" pos="0 0 0.025" type="capsule" class="right_plastic_collision"/> -->
              <body name="rh_ffmiddle" pos="0 0 0.045">
                <site name="rh_ffmiddle_touch" class="right_hand" pos="0 0 0.0125" zaxis="0 1 0"/>
                <inertial mass="0.017" pos="0 0 0.0125" quat="1 0 0 1" diaginertia="2.7e-06 2.6e-06 8.7e-07"/>
                <joint name="rh_FFJ2" class="right_middle_distal"/>
                <geom class="right_plastic_visual" mesh="right_f_middle"/>
                <include file="../shadow_hand_submodel/right_f_middle_collision_0.xml"/>
                <!-- <geom size="0.009 0.0125" pos="0 0 0.0125" type="capsule" class="right_plastic_collision"/> -->
                <body name="rh_ffdistal" pos="0 0 0.025">
                  <site name="rh_ffdistal_touch" class="right_hand" pos="0 0 0.017" zaxis="0 1 0"/>
                  <inertial mass="0.013" pos="0 0 0.0130769" quat="1 0 0 1"
                    diaginertia="1.28092e-06 1.12092e-06 5.3e-07"/>
                  <joint name="rh_FFJ1" class="right_middle_distal"/>
                  <geom class="right_plastic_visual" mesh="right_f_distal_pst"/>
                  <include file="../shadow_hand_submodel/right_f_distal_pst_collision_0.xml"/>
                  <!-- <geom class="right_plastic_collision" type="mesh" mesh="right_f_distal_pst"/> -->
                </body>
              </body>
            </body>
          </body>
          <body name="rh_mfknuckle" pos="0.011 0 0.099">
            <inertial mass="0.008" pos="0 0 0" quat="0.5 0.5 -0.5 0.5" diaginertia="3.2e-07 2.6e-07 2.6e-07"/>
            <joint name="rh_MFJ4" class="right_knuckle"/>
            <geom pos="0 0 0.0005" class="right_plastic_visual" mesh="right_f_knuckle" material="metallic"/>
            <geom size="0.009 0.009" quat="1 0 1 0" type="cylinder" class="right_plastic_collision"/>
            <body name="rh_mfproximal">
              <site name="rh_mfproximal_touch" class="right_hand" pos="0 0 0.022" zaxis="0 1 0"/>
              <inertial mass="0.03" pos="0 0 0.0225" quat="1 0 0 1" diaginertia="1e-05 9.8e-06 1.8e-06"/>
              <joint name="rh_MFJ3" class="right_proximal"/>
              <geom class="right_plastic_visual" mesh="right_f_proximal"/>
              <include file="../shadow_hand_submodel/right_f_proximal_collision_1.xml"/>
              <!-- <geom size="0.009 0.02" pos="0 0 0.025" type="capsule" class="right_plastic_collision"/> -->
              <body name="rh_mfmiddle" pos="0 0 0.045">
                <site name="rh_mfmiddle_touch" class="right_hand" pos="0 0 0.0125" zaxis="0 1 0"/>
                <inertial mass="0.017" pos="0 0 0.0125" quat="1 0 0 1" diaginertia="2.7e-06 2.6e-06 8.7e-07"/>
                <joint name="rh_MFJ2" class="right_middle_distal"/>
                <geom class="right_plastic_visual" mesh="right_f_middle"/>
                <include file="../shadow_hand_submodel/right_f_middle_collision_1.xml"/>
                <!-- <geom size="0.009 0.0125" pos="0 0 0.0125" type="capsule" class="right_plastic_collision"/> -->
                <body name="rh_mfdistal" pos="0 0 0.025">
                  <site name="rh_mfdistal_touch" class="right_hand" pos="0 0 0.017" zaxis="0 1 0"/>
                  <inertial mass="0.013" pos="0 0 0.0130769" quat="1 0 0 1"
                    diaginertia="1.28092e-06 1.12092e-06 5.3e-07"/>
                  <joint name="rh_MFJ1" class="right_middle_distal"/>
                  <geom class="right_plastic_visual" mesh="right_f_distal_pst"/>
                  <include file="../shadow_hand_submodel/right_f_distal_pst_collision_1.xml"/>
                  <!-- <geom class="right_plastic_collision" type="mesh" mesh="right_f_distal_pst"/> -->
                </body>
              </body>
            </body>
          </body>
          <body name="rh_rfknuckle" pos="-0.011 0 0.095">
            <inertial mass="0.008" pos="0 0 0" quat="0.5 0.5 -0.5 0.5" diaginertia="3.2e-07 2.6e-07 2.6e-07"/>
            <joint name="rh_RFJ4" class="right_knuckle" axis="0 1 0"/>
            <geom pos="0 0 0.0005" class="right_plastic_visual" mesh="right_f_knuckle" material="metallic"/>
            <geom size="0.009 0.009" quat="1 0 1 0" type="cylinder" class="right_plastic_collision"/>
            <body name="rh_rfproximal">
              <site name="rh_rfproximal_touch" class="right_hand" pos="0 0 0.022" zaxis="0 1 0"/>
              <inertial mass="0.03" pos="0 0 0.0225" quat="1 0 0 1" diaginertia="1e-05 9.8e-06 1.8e-06"/>
              <joint name="rh_RFJ3" class="right_proximal"/>
              <geom class="right_plastic_visual" mesh="right_f_proximal"/>
              <include file="../shadow_hand_submodel/right_f_proximal_collision_2.xml"/>
              <!-- <geom size="0.009 0.02" pos="0 0 0.025" type="capsule" class="right_plastic_collision"/> -->
              <body name="rh_rfmiddle" pos="0 0 0.045">
                <site name="rh_rfmiddle_touch" class="right_hand" pos="0 0 0.0125" zaxis="0 1 0"/>
                <inertial mass="0.017" pos="0 0 0.0125" quat="1 0 0 1" diaginertia="2.7e-06 2.6e-06 8.7e-07"/>
                <joint name="rh_RFJ2" class="right_middle_distal"/>
                <geom class="right_plastic_visual" mesh="right_f_middle"/>
                <include file="../shadow_hand_submodel/right_f_middle_collision_2.xml"/>
                <!-- <geom size="0.009 0.0125" pos="0 0 0.0125" type="capsule" class="right_plastic_collision"/> -->
                <body name="rh_rfdistal" pos="0 0 0.025">
                  <site name="rh_rfdistal_touch" class="right_hand" pos="0 0 0.017" zaxis="0 1 0"/>
                  <inertial mass="0.013" pos="0 0 0.0130769" quat="1 0 0 1"
                    diaginertia="1.28092e-06 1.12092e-06 5.3e-07"/>
                  <joint name="rh_RFJ1" class="right_middle_distal"/>
                  <geom class="right_plastic_visual" mesh="right_f_distal_pst"/>
                  <include file="../shadow_hand_submodel/right_f_distal_pst_collision_2.xml"/>
                  <!-- <geom class="right_plastic_collision" type="mesh" mesh="right_f_distal_pst"/> -->
                </body>
              </body>
            </body>
          </body>
          <body name="rh_lfmetacarpal" pos="-0.033 0 0.02071">
            <site name="rh_lfmetacarpal_touch" class="right_hand" pos="0 0 0.035" zaxis="0 1 0"/>
            <inertial mass="0.03" pos="0 0 0.04" quat="1 0 0 1" diaginertia="1.638e-05 1.45e-05 4.272e-06"/>
            <joint name="rh_LFJ5" class="right_metacarpal"/>
            <geom class="right_plastic_visual" mesh="right_lf_metacarpal"/>
            <include file='../shadow_hand_submodel/right_lf_metacarpal_collision_0.xml'/>
            <!-- <geom size="0.011 0.012 0.025" pos="0.002 0 0.033" type="box" class="right_plastic_collision"/> -->
            <body name="rh_lfknuckle" pos="0 0 0.06579">
              <inertial mass="0.008" pos="0 0 0" quat="0.5 0.5 -0.5 0.5" diaginertia="3.2e-07 2.6e-07 2.6e-07"/>
              <joint name="rh_LFJ4" class="right_knuckle" axis="0 1 0"/>
              <geom pos="0 0 0.0005" class="right_plastic_visual" mesh="right_f_knuckle" material="metallic"/>
              <geom size="0.009 0.009" quat="1 0 1 0" type="cylinder" class="right_plastic_collision"/>
              <body name="rh_lfproximal">
                <site name="rh_lfproximal_touch" class="right_hand" pos="0 0 0.022" zaxis="0 1 0"/>
                <inertial mass="0.03" pos="0 0 0.0225" quat="1 0 0 1" diaginertia="1e-05 9.8e-06 1.8e-06"/>
                <joint name="rh_LFJ3" class="right_proximal"/>
                <geom class="right_plastic_visual" mesh="right_f_proximal"/>
                <include file="../shadow_hand_submodel/right_f_proximal_collision_3.xml"/>
                <!-- <geom size="0.009 0.02" pos="0 0 0.025" type="capsule" class="right_plastic_collision"/> -->
                <body name="rh_lfmiddle" pos="0 0 0.045">
                  <site name="rh_lfmiddle_touch" class="right_hand" pos="0 0 0.0125" zaxis="0 1 0"/>
                  <inertial mass="0.017" pos="0 0 0.0125" quat="1 0 0 1" diaginertia="2.7e-06 2.6e-06 8.7e-07"/>
                  <joint name="rh_LFJ2" class="right_middle_distal"/>
                  <geom class="right_plastic_visual" mesh="right_f_middle"/>
                  <include file="../shadow_hand_submodel/right_f_middle_collision_3.xml"/>
                  <!-- <geom size="0.009 0.0125" pos="0 0 0.0125" type="capsule" class="right_plastic_collision"/> -->
                  <body name="rh_lfdistal" pos="0 0 0.025">
                    <site name="rh_lfdistal_touch" class="right_hand" pos="0 0 0.017" zaxis="0 1 0"/>
                    <inertial mass="0.013" pos="0 0 0.0130769" quat="1 0 0 1"
                      diaginertia="1.28092e-06 1.12092e-06 5.3e-07"/>
                    <joint name="rh_LFJ1" class="right_middle_distal"/>
                    <geom class="right_plastic_visual" mesh="right_f_distal_pst"/>
                    <include file="../shadow_hand_submodel/right_f_distal_pst_collision_3.xml"/>
                    <!-- <geom class="right_plastic_collision" type="mesh" mesh="right_f_distal_pst"/> -->
                  </body>
                </body>
              </body>
            </body>
          </body>
          <body name="rh_thbase" pos="0.034 -0.00858 0.029" quat="0.92388 0 0.382683 0">
            <inertial mass="0.01" pos="0 0 0" diaginertia="1.6e-07 1.6e-07 1.6e-07"/>
            <joint name="rh_THJ5" class="right_thbase"/>
            <!-- <geom class="right_plastic_collision" size="0.013"/> -->
            <body name="rh_thproximal">
              <site name="rh_thproximal_touch" class="right_hand" pos="0 0 0.02" zaxis="1 0 0"/>
              <inertial mass="0.04" pos="0 0 0.019" diaginertia="1.36e-05 1.36e-05 3.13e-06"/>
              <joint name="rh_THJ4" class="right_thproximal"/>
              <geom class="right_plastic_visual" mesh="right_th_proximal"/>
              <include file='../shadow_hand_submodel/right_th_proximal_collision_0.xml'/>
              <!-- <geom class="right_plastic_collision" size="0.0105 0.009" pos="0 0 0.02" type="capsule"/> -->
              <body name="rh_thhub" pos="0 0 0.038">
                <inertial mass="0.005" pos="0 0 0" diaginertia="1e-06 1e-06 3e-07"/>
                <joint name="rh_THJ3" class="right_thhub"/>
                <!-- <geom size="0.011" class="right_plastic_collision"/> -->
                <body name="rh_thmiddle">
                  <site name="rh_thmiddle_touch" class="right_hand" pos="0 0 0.014" zaxis="1 0 0"/>
                  <inertial mass="0.02" pos="0 0 0.016" diaginertia="5.1e-06 5.1e-06 1.21e-06"/>
                  <joint name="rh_THJ2" class="right_thmiddle"/>
                  <geom class="right_plastic_visual" mesh="right_th_middle"/>
                  <include file='../shadow_hand_submodel/right_th_middle_collision_0.xml'/>
                  <!-- <geom size="0.009 0.009" pos="0 0 0.012" type="capsule" class="right_plastic_collision"/> -->
                  <!-- <geom size="0.01" pos="0 0 0.03" class="right_plastic_collision"/> -->
                  <body name="rh_thdistal" pos="0 0 0.032" quat="1 0 0 -1">
                    <site name="rh_thdistal_touch" class="right_hand" pos="0 0 0.02" zaxis="0 1 0"/>
                    <inertial mass="0.017" pos="0 0 0.0145588" quat="1 0 0 1"
                      diaginertia="2.37794e-06 2.27794e-06 1e-06"/>
                    <joint name="rh_THJ1" class="right_thdistal"/>
                    <geom class="right_plastic_visual" mesh="right_th_distal_pst"/>
                    <include file='../shadow_hand_submodel/right_th_distal_pst_collision_0.xml'/>
                    <!-- <geom class="right_plastic_collision" type="mesh" mesh="right_th_distal_pst"/> -->
                  </body>
                </body>
              </body>
            </body>
          </body>
        </body>
      </body>
    <!-- </body> -->

</mujoco>
